Workbook

Sheet Sheet1
A1: 唯一ID | B1: 副本类型 | C1: 战力限制 | D1: 等级限制 | E1: 章节 | F1: 闯关层数 | G1: 刷怪配置 | H1: 挑战时间 | I1: 结算奖励 | J1: 产出预览 | K1: 展示怪形象 | L1: 章节奖励 | M1: 星级奖励 | N1: 地图ID | O1: 章节标记
A2: int32 | B2: int32 | C2: int32 | D2: int32 | E2: int32 | F2: int32 | G2: json | H2: int32 | I2: json | J2: json | K2: int32 | L2: json | M2: json | N2: int32 | O2: int32
A3: UID | B3: Copytype | C3: Powerlimit | D3: Levellimit | E3: Chapter | F3: Layers | G3: Monster | H3: Timelimit | I3: Settlement | J3: Preview | K3: MonsterShow | L3: ChapterAward | M3: StarAward | N3: MapID | O3: MapMark
A4: =B4*100000+E4*1000+F4 -> 1401001 | B4: 14 | C4: 0 | D4: 1 | E4: 1 | F4: 1 | G4: [{"id":1,"num":2,"point":{"x":24,"y":37}}, {"id":2001, "num":2,"point":{"x":15,"y":35}}, {"id":1, "num":2,"point":{"x":33,"y":33}}] | H4: 90 | I4: =VLOOKUP(A4,战役结算奖励!$A$1:$O$301,15,0) -> [{"id":14,"num":12},{"id":2,"num":20000},{"id":1,"num":20000}] | J4: [14,2,1] | K4: 61 | N4: 1
A5: =B5*100000+E5*1000+F5 -> 1401002 | B5: 14 | C5: 0 | D5: 1 | E5: 1 | F5: 2 | G5: [{"id":1,"num":3,"point":{"x":24,"y":37}}, {"id":2001, "num":2,"point":{"x":15,"y":35}}, {"id":1, "num":2,"point":{"x":33,"y":33}}] | H5: 90 | I5: =VLOOKUP(A5,战役结算奖励!$A$1:$O$301,15,0) -> [{"id":14,"num":12},{"id":2,"num":20000},{"id":1,"num":20000}] | J5: [14,2,1] | K5: 61 | N5: 1
A6: =B6*100000+E6*1000+F6 -> 1401003 | B6: 14 | C6: 0 | D6: 1 | E6: 1 | F6: 3 | G6: [{"id":1,"num":3,"point":{"x":16,"y":38}}, {"id":2001, "num":3,"point":{"x":35,"y":35}}, {"id":1, "num":3,"point":{"x":23,"y":12}}] | H6: 90 | I6: =VLOOKUP(A6,战役结算奖励!$A$1:$O$301,15,0) -> [{"id":14,"num":12},{"id":2,"num":20000},{"id":1,"num":20000}] | J6: [14,2,1] | K6: 61 | N6: 1
A7: =B7*100000+E7*1000+F7 -> 1401004 | B7: 14 | C7: 0 | D7: 1 | E7: 1 | F7: 4 | G7: [{"id":1,"num":4,"point":{"x":16,"y":38}}, {"id":2001, "num":3,"point":{"x":35,"y":35}}, {"id":1, "num":3,"point":{"x":23,"y":12}}] | H7: 90 | I7: =VLOOKUP(A7,战役结算奖励!$A$1:$O$301,15,0) -> [{"id":14,"num":12},{"id":2,"num":20000},{"id":1,"num":20000}] | J7: [14,2,1] | K7: 61 | N7: 1
A8: =B8*100000+E8*1000+F8 -> 1401005 | B8: 14 | C8: 0 | D8: 1 | E8: 1 | F8: 5 | G8: [{"id":1,"num":4,"point":{"x":16,"y":20}}, {"id":2001, "num":4,"point":{"x":25,"y":37}}, {"id":1, "num":4,"point":{"x":33,"y":16}}] | H8: 90 | I8: =VLOOKUP(A8,战役结算奖励!$A$1:$O$301,15,0) -> [{"id":14,"num":12},{"id":2,"num":20000},{"id":1,"num":20000}] | J8: [14,2,1] | K8: 61 | N8: 1
A9: =B9*100000+E9*1000+F9 -> 1401006 | B9: 14 | C9: 0 | D9: 1 | E9: 1 | F9: 6 | G9: [{"id":1,"num":5,"point":{"x":16,"y":20}}, {"id":2001, "num":4,"point":{"x":25,"y":37}}, {"id":1, "num":4,"point":{"x":33,"y":16}}] | H9: 90 | I9: =VLOOKUP(A9,战役结算奖励!$A$1:$O$301,15,0) -> [{"id":14,"num":12},{"id":2,"num":20000},{"id":1,"num":20000}] | J9: [14,2,1] | K9: 61 | N9: 1
A10: =B10*100000+E10*1000+F10 -> 1401007 | B10: 14 | C10: 0 | D10: 1 | E10: 1 | F10: 7 | G10: [{"id":1,"num":5,"point":{"x":25,"y":35}}, {"id":2001, "num":5,"point":{"x":33,"y":33}}, {"id":1, "num":5,"point":{"x":20,"y":18}}] | H10: 90 | I10: =VLOOKUP(A10,战役结算奖励!$A$1:$O$301,15,0) -> [{"id":14,"num":12},{"id":2,"num":20000},{"id":1,"num":20000}] | J10: [14,2,1] | K10: 61 | N10: 1
A11: =B11*100000+E11*1000+F11 -> 1401008 | B11: 14 | C11: 0 | D11: 1 | E11: 1 | F11: 8 | G11: [{"id":1,"num":6,"point":{"x":25,"y":35}}, {"id":2001, "num":5,"point":{"x":33,"y":33}}, {"id":1, "num":5,"point":{"x":20,"y":18}}] | H11: 90 | I11: =VLOOKUP(A11,战役结算奖励!$A$1:$O$301,15,0) -> [{"id":14,"num":12},{"id":2,"num":20000},{"id":1,"num":20000}] | J11: [14,2,1] | K11: 61 | N11: 1
A12: =B12*100000+E12*1000+F12 -> 1401009 | B12: 14 | C12: 0 | D12: 1 | E12: 1 | F12: 9 | G12: [{"id":1,"num":6,"point":{"x":15,"y":35}}, {"id":2001, "num":6,"point":{"x":26,"y":39}}, {"id":1, "num":5,"point":{"x":36,"y":37}}] | H12: 90 | I12: =VLOOKUP(A12,战役结算奖励!$A$1:$O$301,15,0) -> [{"id":14,"num":12},{"id":2,"num":20000},{"id":1,"num":20000}] | J12: [14,2,1] | K12: 61 | N12: 1
A13: =B13*100000+E13*1000+F13 -> 1401010 | B13: 14 | C13: 0 | D13: 1 | E13: 1 | F13: 10 | G13: [{"id":1,"num":6,"point":{"x":15,"y":35}}, {"id":2001, "num":6,"point":{"x":26,"y":39}}, {"id":1, "num":5,"point":{"x":36,"y":37}}, {"id":31, "num":1,"point":{"x":25,"y":42}}] | H13: 90 | I13: =VLOOKUP(A13,战役结算奖励!$A$1:$O$301,15,0) -> [{"id":14,"num":12},{"id":2,"num":20000},{"id":1,"num":20000}] | J13: [14,2,1] | K13: 61 | N13: 1
A14: =B14*100000+E14*1000+F14 -> 1401011 | B14: 14 | C14: 0 | D14: 1 | E14: 1 | F14: 11 | G14: [{"id":2,"num":2,"point":{"x":24,"y":37}}, {"id":2002, "num":2,"point":{"x":15,"y":35}}, {"id":2, "num":2,"point":{"x":33,"y":33}}] | H14: 90 | I14: =VLOOKUP(A14,战役结算奖励!$A$1:$O$301,15,0) -> [{"id":14,"num":12},{"id":2,"num":20000},{"id":1,"num":20000}] | J14: [14,2,1] | K14: 61 | N14: 1
A15: =B15*100000+E15*1000+F15 -> 1401012 | B15: 14 | C15: 0 | D15: 1 | E15: 1 | F15: 12 | G15: [{"id":2,"num":3,"point":{"x":24,"y":37}}, {"id":2002, "num":2,"point":{"x":15,"y":35}}, {"id":2, "num":2,"point":{"x":33,"y":33}}] | H15: 90 | I15: =VLOOKUP(A15,战役结算奖励!$A$1:$O$301,15,0) -> [{"id":14,"num":12},{"id":2,"num":20000},{"id":1,"num":20000}] | J15: [14,2,1] | K15: 61 | N15: 1
... A42: =B42*100000+E42*1000+F42 -> 1401039 | B42: 14 | C42: 0 | D42: 1 | E42: 1 | F42: 39 | G42: [{"id":4,"num":6,"point":{"x":15,"y":35}}, {"id":2004, "num":6,"point":{"x":26,"y":39}}, {"id":4, "num":5,"point":{"x":36,"y":37}}] | H42: 90 | I42: =VLOOKUP(A42,战役结算奖励!$A$1:$O$301,15,0) -> [{"id":14,"num":16},{"id":2,"num":20000},{"id":1,"num":20000}] | J42: [14,2,1] | K42: 61 | N42: 1
A43: =B43*100000+E43*1000+F43 -> 1401040 | B43: 14 | C43: 0 | D43: 1 | E43: 1 | F43: 40 | G43: [{"id":4,"num":6,"point":{"x":15,"y":35}}, {"id":2004, "num":6,"point":{"x":26,"y":39}}, {"id":4, "num":5,"point":{"x":36,"y":37}}, {"id":34, "num":1,"point":{"x":25,"y":42}}] | H43: 90 | I43: =VLOOKUP(A43,战役结算奖励!$A$1:$O$301,15,0) -> [{"id":14,"num":16},{"id":2,"num":20000},{"id":1,"num":20000}] | J43: [14,2,1] | K43: 61 | L43: [{"id":5,"num":3000},{"id":14,"num":100},{"id":99,"num":10}] | N43: 1 | O43: 1
A44: =B44*100000+E44*1000+F44 -> 1402001 | B44: 14 | C44: 0 | D44: 1 | E44: 2 | F44: 1 | G44: [{"id":5,"num":2,"point":{"x":24,"y":37}}, {"id":2005, "num":2,"point":{"x":15,"y":35}}, {"id":5, "num":2,"point":{"x":33,"y":33}}] | H44: 90 | I44: =VLOOKUP(A44,战役结算奖励!$A$1:$O$301,15,0) -> [{"id":14,"num":16},{"id":2,"num":20000},{"id":1,"num":20000}] | J44: [14,2,1] | K44: 62 | N44: 2
A45: =B45*100000+E45*1000+F45 -> 1402002 | B45: 14 | C45: 0 | D45: 1 | E45: 2 | F45: 2 | G45: [{"id":5,"num":3,"point":{"x":24,"y":37}}, {"id":2005, "num":2,"point":{"x":15,"y":35}}, {"id":5, "num":2,"point":{"x":33,"y":33}}] | H45: 90 | I45: =VLOOKUP(A45,战役结算奖励!$A$1:$O$301,15,0) -> [{"id":14,"num":16},{"id":2,"num":20000},{"id":1,"num":20000}] | J45: [14,2,1] | K45: 62 | N45: 2
A46: =B46*100000+E46*1000+F46 -> 1402003 | B46: 14 | C46: 0 | D46: 1 | E46: 2 | F46: 3 | G46: [{"id":5,"num":3,"point":{"x":16,"y":38}}, {"id":2005, "num":3,"point":{"x":35,"y":35}}, {"id":5, "num":3,"point":{"x":23,"y":12}}] | H46: 90 | I46: =VLOOKUP(A46,战役结算奖励!$A$1:$O$301,15,0) -> [{"id":14,"num":16},{"id":2,"num":20000},{"id":1,"num":20000}] | J46: [14,2,1] | K46: 62 | N46: 2
A47: =B47*100000+E47*1000+F47 -> 1402004 | B47: 14 | C47: 0 | D47: 1 | E47: 2 | F47: 4 | G47: [{"id":5,"num":4,"point":{"x":16,"y":38}}, {"id":2005, "num":3,"point":{"x":35,"y":35}}, {"id":5, "num":3,"point":{"x":23,"y":12}}] | H47: 90 | I47: =VLOOKUP(A47,战役结算奖励!$A$1:$O$301,15,0) -> [{"id":14,"num":16},{"id":2,"num":20000},{"id":1,"num":20000}] | J47: [14,2,1] | K47: 62 | N47: 2
A48: =B48*100000+E48*1000+F48 -> 1402005 | B48: 14 | C48: 0 | D48: 1 | E48: 2 | F48: 5 | G48: [{"id":5,"num":4,"point":{"x":16,"y":20}}, {"id":2005, "num":4,"point":{"x":25,"y":37}}, {"id":5, "num":4,"point":{"x":33,"y":16}}] | H48: 90 | I48: =VLOOKUP(A48,战役结算奖励!$A$1:$O$301,15,0) -> [{"id":14,"num":16},{"id":2,"num":20000},{"id":1,"num":20000}] | J48: [14,2,1] | K48: 62 | N48: 2
A49: =B49*100000+E49*1000+F49 -> 1402006 | B49: 14 | C49: 0 | D49: 1 | E49: 2 | F49: 6 | G49: [{"id":5,"num":5,"point":{"x":16,"y":20}}, {"id":2005, "num":4,"point":{"x":25,"y":37}}, {"id":5, "num":4,"point":{"x":33,"y":16}}] | H49: 90 | I49: =VLOOKUP(A49,战役结算奖励!$A$1:$O$301,15,0) -> [{"id":14,"num":16},{"id":2,"num":20000},{"id":1,"num":20000}] | J49: [14,2,1] | K49: 62 | N49: 2
A50: =B50*100000+E50*1000+F50 -> 1402007 | B50: 14 | C50: 0 | D50: 1 | E50: 2 | F50: 7 | G50: [{"id":5,"num":5,"point":{"x":25,"y":35}}, {"id":2005, "num":5,"point":{"x":33,"y":33}}, {"id":5, "num":5,"point":{"x":20,"y":18}}] | H50: 90 | I50: =VLOOKUP(A50,战役结算奖励!$A$1:$O$301,15,0) -> [{"id":14,"num":16},{"id":2,"num":20000},{"id":1,"num":20000}] | J50: [14,2,1] | K50: 62 | N50: 2
A51: =B51*100000+E51*1000+F51 -> 1402008 | B51: 14 | C51: 0 | D51: 1 | E51: 2 | F51: 8 | G51: [{"id":5,"num":6,"point":{"x":25,"y":35}}, {"id":2005, "num":5,"point":{"x":33,"y":33}}, {"id":5, "num":5,"point":{"x":20,"y":18}}] | H51: 90 | I51: =VLOOKUP(A51,战役结算奖励!$A$1:$O$301,15,0) -> [{"id":14,"num":16},{"id":2,"num":20000},{"id":1,"num":20000}] | J51: [14,2,1] | K51: 62 | N51: 2
A52: =B52*100000+E52*1000+F52 -> 1402009 | B52: 14 | C52: 0 | D52: 1 | E52: 2 | F52: 9 | G52: [{"id":5,"num":6,"point":{"x":15,"y":35}}, {"id":2005, "num":6,"point":{"x":26,"y":39}}, {"id":5, "num":5,"point":{"x":36,"y":37}}] | H52: 90 | I52: =VLOOKUP(A52,战役结算奖励!$A$1:$O$301,15,0) -> [{"id":14,"num":16},{"id":2,"num":20000},{"id":1,"num":20000}] | J52: [14,2,1] | K52: 62 | N52: 2
A53: =B53*100000+E53*1000+F53 -> 1402010 | B53: 14 | C53: 0 | D53: 1 | E53: 2 | F53: 10 | G53: [{"id":5,"num":6,"point":{"x":15,"y":35}}, {"id":2005, "num":6,"point":{"x":26,"y":39}}, {"id":5, "num":5,"point":{"x":36,"y":37}}, {"id":35, "num":1,"point":{"x":25,"y":42}}] | H53: 90 | I53: =VLOOKUP(A53,战役结算奖励!$A$1:$O$301,15,0) -> [{"id":14,"num":16},{"id":2,"num":20000},{"id":1,"num":20000}] | J53: [14,2,1] | K53: 62 | N53: 2
A54: =B54*100000+E54*1000+F54 -> 1402011 | B54: 14 | C54: 0 | D54: 1 | E54: 2 | F54: 11 | G54: [{"id":6,"num":2,"point":{"x":24,"y":37}}, {"id":2006, "num":2,"point":{"x":15,"y":35}}, {"id":6, "num":2,"point":{"x":33,"y":33}}] | H54: 90 | I54: =VLOOKUP(A54,战役结算奖励!$A$1:$O$301,15,0) -> [{"id":14,"num":16},{"id":2,"num":20000},{"id":1,"num":20000}] | J54: [14,2,1] | K54: 62 | N54: 2
A55: =B55*100000+E55*1000+F55 -> 1402012 | B55: 14 | C55: 0 | D55: 1 | E55: 2 | F55: 12 | G55: [{"id":6,"num":3,"point":{"x":24,"y":37}}, {"id":2006, "num":2,"point":{"x":15,"y":35}}, {"id":6, "num":2,"point":{"x":33,"y":33}}] | H55: 90 | I55: =VLOOKUP(A55,战役结算奖励!$A$1:$O$301,15,0) -> [{"id":14,"num":16},{"id":2,"num":20000},{"id":1,"num":20000}] | J55: [14,2,1] | K55: 62 | N55: 2
... A82: =B82*100000+E82*1000+F82 -> 1402039 | B82: 14 | C82: 0 | D82: 1 | E82: 2 | F82: 39 | G82: [{"id":8,"num":6,"point":{"x":15,"y":35}}, {"id":8, "num":6,"point":{"x":26,"y":39}}, {"id":8, "num":5,"point":{"x":36,"y":37}}] | H82: 90 | I82: =VLOOKUP(A82,战役结算奖励!$A$1:$O$301,15,0) -> [{"id":14,"num":20},{"id":2,"num":220000},{"id":1,"num":220000}] | J82: [14,2,1] | K82: 62 | N82: 2
A83: =B83*100000+E83*1000+F83 -> 1402040 | B83: 14 | C83: 0 | D83: 1 | E83: 2 | F83: 40 | G83: [{"id":8,"num":6,"point":{"x":15,"y":35}}, {"id":8, "num":6,"point":{"x":26,"y":39}}, {"id":8, "num":5,"point":{"x":36,"y":37}}, {"id":38, "num":1,"point":{"x":25,"y":42}}] | H83: 90 | I83: =VLOOKUP(A83,战役结算奖励!$A$1:$O$301,15,0) -> [{"id":14,"num":20},{"id":2,"num":220000},{"id":1,"num":220000}] | J83: [14,2,1] | K83: 62 | L83: [{"id":5,"num":3500},{"id":14,"num":200},{"id":99,"num":10}] | N83: 2 | O83: 1
A84: =B84*100000+E84*1000+F84 -> 1403001 | B84: 14 | C84: 0 | D84: 1 | E84: =E44+1 -> 3 | F84: =F44 -> 1 | G84: [{"id":9,"num":2,"point":{"x":24,"y":37}}, {"id":9, "num":2,"point":{"x":15,"y":35}}, {"id":9, "num":2,"point":{"x":33,"y":33}}] | H84: 90 | I84: =VLOOKUP(A84,战役结算奖励!$A$1:$O$301,15,0) -> [{"id":14,"num":20},{"id":2,"num":230000},{"id":1,"num":230000}] | J84: [14,2,1] | K84: 63 | N84: 3
A85: =B85*100000+E85*1000+F85 -> 1403002 | B85: 14 | C85: 0 | D85: 1 | E85: =E45+1 -> 3 | F85: =F45 -> 2 | G85: [{"id":9,"num":3,"point":{"x":24,"y":37}}, {"id":9, "num":2,"point":{"x":15,"y":35}}, {"id":9, "num":2,"point":{"x":33,"y":33}}] | H85: 90 | I85: =VLOOKUP(A85,战役结算奖励!$A$1:$O$301,15,0) -> [{"id":14,"num":20},{"id":2,"num":230000},{"id":1,"num":230000}] | J85: [14,2,1] | K85: 63 | N85: 3
A86: =B86*100000+E86*1000+F86 -> 1403003 | B86: 14 | C86: 0 | D86: 1 | E86: =E46+1 -> 3 | F86: =F46 -> 3 | G86: [{"id":9,"num":3,"point":{"x":16,"y":38}}, {"id":9, "num":3,"point":{"x":35,"y":35}}, {"id":9, "num":3,"point":{"x":23,"y":12}}] | H86: 90 | I86: =VLOOKUP(A86,战役结算奖励!$A$1:$O$301,15,0) -> [{"id":14,"num":20},{"id":2,"num":230000},{"id":1,"num":230000}] | J86: [14,2,1] | K86: 63 | N86: 3
A87: =B87*100000+E87*1000+F87 -> 1403004 | B87: 14 | C87: 0 | D87: 1 | E87: =E47+1 -> 3 | F87: =F47 -> 4 | G87: [{"id":9,"num":4,"point":{"x":16,"y":38}}, {"id":9, "num":3,"point":{"x":35,"y":35}}, {"id":9, "num":3,"point":{"x":23,"y":12}}] | H87: 90 | I87: =VLOOKUP(A87,战役结算奖励!$A$1:$O$301,15,0) -> [{"id":14,"num":20},{"id":2,"num":230000},{"id":1,"num":230000}] | J87: [14,2,1] | K87: 63 | N87: 3
A88: =B88*100000+E88*1000+F88 -> 1403005 | B88: 14 | C88: 0 | D88: 1 | E88: =E48+1 -> 3 | F88: =F48 -> 5 | G88: [{"id":9,"num":4,"point":{"x":16,"y":20}}, {"id":9, "num":4,"point":{"x":25,"y":37}}, {"id":9, "num":4,"point":{"x":33,"y":16}}] | H88: 90 | I88: =VLOOKUP(A88,战役结算奖励!$A$1:$O$301,15,0) -> [{"id":14,"num":20},{"id":2,"num":230000},{"id":1,"num":230000}] | J88: [14,2,1] | K88: 63 | N88: 3
A89: =B89*100000+E89*1000+F89 -> 1403006 | B89: 14 | C89: 0 | D89: 1 | E89: =E49+1 -> 3 | F89: =F49 -> 6 | G89: [{"id":9,"num":5,"point":{"x":16,"y":20}}, {"id":9, "num":4,"point":{"x":25,"y":37}}, {"id":9, "num":4,"point":{"x":33,"y":16}}] | H89: 90 | I89: =VLOOKUP(A89,战役结算奖励!$A$1:$O$301,15,0) -> [{"id":14,"num":20},{"id":2,"num":230000},{"id":1,"num":230000}] | J89: [14,2,1] | K89: 63 | N89: 3
A90: =B90*100000+E90*1000+F90 -> 1403007 | B90: 14 | C90: 0 | D90: 1 | E90: =E50+1 -> 3 | F90: =F50 -> 7 | G90: [{"id":9,"num":5,"point":{"x":25,"y":35}}, {"id":9, "num":5,"point":{"x":33,"y":33}}, {"id":9, "num":5,"point":{"x":20,"y":18}}] | H90: 90 | I90: =VLOOKUP(A90,战役结算奖励!$A$1:$O$301,15,0) -> [{"id":14,"num":20},{"id":2,"num":230000},{"id":1,"num":230000}] | J90: [14,2,1] | K90: 63 | N90: 3
A91: =B91*100000+E91*1000+F91 -> 1403008 | B91: 14 | C91: 0 | D91: 1 | E91: =E51+1 -> 3 | F91: =F51 -> 8 | G91: [{"id":9,"num":6,"point":{"x":25,"y":35}}, {"id":9, "num":5,"point":{"x":33,"y":33}}, {"id":9, "num":5,"point":{"x":20,"y":18}}] | H91: 90 | I91: =VLOOKUP(A91,战役结算奖励!$A$1:$O$301,15,0) -> [{"id":14,"num":20},{"id":2,"num":230000},{"id":1,"num":230000}] | J91: [14,2,1] | K91: 63 | N91: 3
A92: =B92*100000+E92*1000+F92 -> 1403009 | B92: 14 | C92: 0 | D92: 1 | E92: =E52+1 -> 3 | F92: =F52 -> 9 | G92: [{"id":9,"num":6,"point":{"x":15,"y":35}}, {"id":9, "num":6,"point":{"x":26,"y":39}}, {"id":9, "num":5,"point":{"x":36,"y":37}}] | H92: 90 | I92: =VLOOKUP(A92,战役结算奖励!$A$1:$O$301,15,0) -> [{"id":14,"num":20},{"id":2,"num":230000},{"id":1,"num":230000}] | J92: [14,2,1] | K92: 63 | N92: 3
...

Sheet 战役结算奖励
A1: 索引 | C1: 道具ID | E1: 道具数量 | G1: 道具ID | I1: 道具数量 | K1: 道具ID | M1: 道具数量 | O1: 生成
A2: =Sheet1!A4 -> 1401001 | B2: [{"id": | C2: 14 | D2: ,"num": | E2: 12 | F2: },{"id": | G2: 2 | H2: ,"num": | I2: 20000 | J2: },{"id": | K2: 1 | L2: ,"num": | M2: 20000 | N2: }] | O2: =_xlfn.TEXTJOIN(,TRUE,B2:N2) -> [{"id":14,"num":12},{"id":2,"num":20000},{"id":1,"num":20000}] | U2: =INT(E2*0.4) -> 4
A3: =Sheet1!A5 -> 1401002 | B3: [{"id": | C3: 14 | D3: ,"num": | E3: 12 | F3: },{"id": | G3: 2 | H3: ,"num": | I3: 20000 | J3: },{"id": | K3: 1 | L3: ,"num": | M3: 20000 | N3: }] | O3: =_xlfn.TEXTJOIN(,TRUE,B3:N3) -> [{"id":14,"num":12},{"id":2,"num":20000},{"id":1,"num":20000}] | U3: =INT(E3*0.4) -> 4
A4: =Sheet1!A6 -> 1401003 | B4: [{"id": | C4: 14 | D4: ,"num": | E4: 12 | F4: },{"id": | G4: 2 | H4: ,"num": | I4: 20000 | J4: },{"id": | K4: 1 | L4: ,"num": | M4: 20000 | N4: }] | O4: =_xlfn.TEXTJOIN(,TRUE,B4:N4) -> [{"id":14,"num":12},{"id":2,"num":20000},{"id":1,"num":20000}] | U4: =INT(E4*0.4) -> 4
A5: =Sheet1!A7 -> 1401004 | B5: [{"id": | C5: 14 | D5: ,"num": | E5: 12 | F5: },{"id": | G5: 2 | H5: ,"num": | I5: 20000 | J5: },{"id": | K5: 1 | L5: ,"num": | M5: 20000 | N5: }] | O5: =_xlfn.TEXTJOIN(,TRUE,B5:N5) -> [{"id":14,"num":12},{"id":2,"num":20000},{"id":1,"num":20000}] | U5: =INT(E5*0.4) -> 4
A6: =Sheet1!A8 -> 1401005 | B6: [{"id": | C6: 14 | D6: ,"num": | E6: 12 | F6: },{"id": | G6: 2 | H6: ,"num": | I6: 20000 | J6: },{"id": | K6: 1 | L6: ,"num": | M6: 20000 | N6: }] | O6: =_xlfn.TEXTJOIN(,TRUE,B6:N6) -> [{"id":14,"num":12},{"id":2,"num":20000},{"id":1,"num":20000}] | U6: =INT(E6*0.4) -> 4
A7: =Sheet1!A9 -> 1401006 | B7: [{"id": | C7: 14 | D7: ,"num": | E7: 12 | F7: },{"id": | G7: 2 | H7: ,"num": | I7: 20000 | J7: },{"id": | K7: 1 | L7: ,"num": | M7: 20000 | N7: }] | O7: =_xlfn.TEXTJOIN(,TRUE,B7:N7) -> [{"id":14,"num":12},{"id":2,"num":20000},{"id":1,"num":20000}] | U7: =INT(E7*0.4) -> 4
A8: =Sheet1!A10 -> 1401007 | B8: [{"id": | C8: 14 | D8: ,"num": | E8: 12 | F8: },{"id": | G8: 2 | H8: ,"num": | I8: 20000 | J8: },{"id": | K8: 1 | L8: ,"num": | M8: 20000 | N8: }] | O8: =_xlfn.TEXTJOIN(,TRUE,B8:N8) -> [{"id":14,"num":12},{"id":2,"num":20000},{"id":1,"num":20000}] | U8: =INT(E8*0.4) -> 4
A9: =Sheet1!A11 -> 1401008 | B9: [{"id": | C9: 14 | D9: ,"num": | E9: 12 | F9: },{"id": | G9: 2 | H9: ,"num": | I9: 20000 | J9: },{"id": | K9: 1 | L9: ,"num": | M9: 20000 | N9: }] | O9: =_xlfn.TEXTJOIN(,TRUE,B9:N9) -> [{"id":14,"num":12},{"id":2,"num":20000},{"id":1,"num":20000}] | U9: =INT(E9*0.4) -> 4
A10: =Sheet1!A12 -> 1401009 | B10: [{"id": | C10: 14 | D10: ,"num": | E10: 12 | F10: },{"id": | G10: 2 | H10: ,"num": | I10: 20000 | J10: },{"id": | K10: 1 | L10: ,"num": | M10: 20000 | N10: }] | O10: =_xlfn.TEXTJOIN(,TRUE,B10:N10) -> [{"id":14,"num":12},{"id":2,"num":20000},{"id":1,"num":20000}] | U10: =INT(E10*0.4) -> 4
A11: =Sheet1!A13 -> 1401010 | B11: [{"id": | C11: 14 | D11: ,"num": | E11: 12 | F11: },{"id": | G11: 2 | H11: ,"num": | I11: 20000 | J11: },{"id": | K11: 1 | L11: ,"num": | M11: 20000 | N11: }] | O11: =_xlfn.TEXTJOIN(,TRUE,B11:N11) -> [{"id":14,"num":12},{"id":2,"num":20000},{"id":1,"num":20000}] | U11: =INT(E11*0.4) -> 4
A12: =Sheet1!A14 -> 1401011 | B12: [{"id": | C12: 14 | D12: ,"num": | E12: 12 | F12: },{"id": | G12: 2 | H12: ,"num": | I12: 20000 | J12: },{"id": | K12: 1 | L12: ,"num": | M12: 20000 | N12: }] | O12: =_xlfn.TEXTJOIN(,TRUE,B12:N12) -> [{"id":14,"num":12},{"id":2,"num":20000},{"id":1,"num":20000}] | U12: =INT(E12*0.4) -> 4
A13: =Sheet1!A15 -> 1401012 | B13: [{"id": | C13: 14 | D13: ,"num": | E13: 12 | F13: },{"id": | G13: 2 | H13: ,"num": | I13: 20000 | J13: },{"id": | K13: 1 | L13: ,"num": | M13: 20000 | N13: }] | O13: =_xlfn.TEXTJOIN(,TRUE,B13:N13) -> [{"id":14,"num":12},{"id":2,"num":20000},{"id":1,"num":20000}] | U13: =INT(E13*0.4) -> 4
... A161: =Sheet1!A163 -> 1404040 | B161: [{"id": | C161: 14 | D161: ,"num": | E161: 28 | F161: },{"id": | G161: 2 | H161: ,"num": | I161: 1202000 | J161: },{"id": | K161: 1 | L161: ,"num": | M161: 1200000 | N161: }] | O161: =_xlfn.TEXTJOIN(,TRUE,B161:N161) -> [{"id":14,"num":28},{"id":2,"num":1202000},{"id":1,"num":1200000}] | U161: =INT(E161*0.4) -> 11
A162: =Sheet1!A164 -> 1405001 | B162: [{"id": | C162: 14 | D162: ,"num": | E162: 28 | F162: },{"id": | G162: 2 | H162: ,"num": | I162: 1210000 | J162: },{"id": | K162: 1 | L162: ,"num": | M162: =I162 -> 1210000 | N162: }] | O162: =_xlfn.TEXTJOIN(,TRUE,B162:N162) -> [{"id":14,"num":28},{"id":2,"num":1210000},{"id":1,"num":1210000}] | U162: =INT(E162*0.4) -> 11
A163: =Sheet1!A165 -> 1405002 | B163: [{"id": | C163: 14 | D163: ,"num": | E163: 28 | F163: },{"id": | G163: 2 | H163: ,"num": | I163: 1210000 | J163: },{"id": | K163: 1 | L163: ,"num": | M163: =I163 -> 1210000 | N163: }] | O163: =_xlfn.TEXTJOIN(,TRUE,B163:N163) -> [{"id":14,"num":28},{"id":2,"num":1210000},{"id":1,"num":1210000}] | U163: =INT(E163*0.4) -> 11
A164: =Sheet1!A166 -> 1405003 | B164: [{"id": | C164: 14 | D164: ,"num": | E164: 28 | F164: },{"id": | G164: 2 | H164: ,"num": | I164: 1210000 | J164: },{"id": | K164: 1 | L164: ,"num": | M164: =I164 -> 1210000 | N164: }] | O164: =_xlfn.TEXTJOIN(,TRUE,B164:N164) -> [{"id":14,"num":28},{"id":2,"num":1210000},{"id":1,"num":1210000}] | U164: =INT(E164*0.4) -> 11
A165: =Sheet1!A167 -> 1405004 | B165: [{"id": | C165: 14 | D165: ,"num": | E165: 28 | F165: },{"id": | G165: 2 | H165: ,"num": | I165: 1210000 | J165: },{"id": | K165: 1 | L165: ,"num": | M165: =I165 -> 1210000 | N165: }] | O165: =_xlfn.TEXTJOIN(,TRUE,B165:N165) -> [{"id":14,"num":28},{"id":2,"num":1210000},{"id":1,"num":1210000}] | U165: =INT(E165*0.4) -> 11
A166: =Sheet1!A168 -> 1405005 | B166: [{"id": | C166: 14 | D166: ,"num": | E166: 28 | F166: },{"id": | G166: 2 | H166: ,"num": | I166: 1210000 | J166: },{"id": | K166: 1 | L166: ,"num": | M166: =I166 -> 1210000 | N166: }] | O166: =_xlfn.TEXTJOIN(,TRUE,B166:N166) -> [{"id":14,"num":28},{"id":2,"num":1210000},{"id":1,"num":1210000}] | U166: =INT(E166*0.4) -> 11
A167: =Sheet1!A169 -> 1405006 | B167: [{"id": | C167: 14 | D167: ,"num": | E167: 28 | F167: },{"id": | G167: 2 | H167: ,"num": | I167: 1210000 | J167: },{"id": | K167: 1 | L167: ,"num": | M167: =I167 -> 1210000 | N167: }] | O167: =_xlfn.TEXTJOIN(,TRUE,B167:N167) -> [{"id":14,"num":28},{"id":2,"num":1210000},{"id":1,"num":1210000}] | U167: =INT(E167*0.4) -> 11
A168: =Sheet1!A170 -> 1405007 | B168: [{"id": | C168: 14 | D168: ,"num": | E168: 28 | F168: },{"id": | G168: 2 | H168: ,"num": | I168: 1210000 | J168: },{"id": | K168: 1 | L168: ,"num": | M168: =I168 -> 1210000 | N168: }] | O168: =_xlfn.TEXTJOIN(,TRUE,B168:N168) -> [{"id":14,"num":28},{"id":2,"num":1210000},{"id":1,"num":1210000}] | U168: =INT(E168*0.4) -> 11
A169: =Sheet1!A171 -> 1405008 | B169: [{"id": | C169: 14 | D169: ,"num": | E169: 28 | F169: },{"id": | G169: 2 | H169: ,"num": | I169: 1210000 | J169: },{"id": | K169: 1 | L169: ,"num": | M169: =I169 -> 1210000 | N169: }] | O169: =_xlfn.TEXTJOIN(,TRUE,B169:N169) -> [{"id":14,"num":28},{"id":2,"num":1210000},{"id":1,"num":1210000}] | U169: =INT(E169*0.4) -> 11
A170: =Sheet1!A172 -> 1405009 | B170: [{"id": | C170: 14 | D170: ,"num": | E170: 28 | F170: },{"id": | G170: 2 | H170: ,"num": | I170: 1210000 | J170: },{"id": | K170: 1 | L170: ,"num": | M170: =I170 -> 1210000 | N170: }] | O170: =_xlfn.TEXTJOIN(,TRUE,B170:N170) -> [{"id":14,"num":28},{"id":2,"num":1210000},{"id":1,"num":1210000}] | U170: =INT(E170*0.4) -> 11
A171: =Sheet1!A173 -> 1405010 | B171: [{"id": | C171: 14 | D171: ,"num": | E171: 28 | F171: },{"id": | G171: 2 | H171: ,"num": | I171: 1210000 | J171: },{"id": | K171: 1 | L171: ,"num": | M171: =I171 -> 1210000 | N171: }] | O171: =_xlfn.TEXTJOIN(,TRUE,B171:N171) -> [{"id":14,"num":28},{"id":2,"num":1210000},{"id":1,"num":1210000}] | U171: =INT(E171*0.4) -> 11
A172: =Sheet1!A174 -> 1405011 | B172: [{"id": | C172: 14 | D172: ,"num": | E172: 28 | F172: },{"id": | G172: 2 | H172: ,"num": | I172: 1210000 | J172: },{"id": | K172: 1 | L172: ,"num": | M172: =I172 -> 1210000 | N172: }] | O172: =_xlfn.TEXTJOIN(,TRUE,B172:N172) -> [{"id":14,"num":28},{"id":2,"num":1210000},{"id":1,"num":1210000}] | U172: =INT(E172*0.4) -> 11
A173: =Sheet1!A175 -> 1405012 | B173: [{"id": | C173: 14 | D173: ,"num": | E173: 28 | F173: },{"id": | G173: 2 | H173: ,"num": | I173: 1210000 | J173: },{"id": | K173: 1 | L173: ,"num": | M173: =I173 -> 1210000 | N173: }] | O173: =_xlfn.TEXTJOIN(,TRUE,B173:N173) -> [{"id":14,"num":28},{"id":2,"num":1210000},{"id":1,"num":1210000}] | U173: =INT(E173*0.4) -> 11
... A221: =Sheet1!A223 -> 1406020 | B221: [{"id": | C221: 14 | D221: ,"num": | E221: 32 | F221: },{"id": | G221: 2 | H221: ,"num": | I221: 1230000 | J221: },{"id": | K221: 1 | L221: ,"num": | M221: =I221 -> 1230000 | N221: }] | O221: =_xlfn.TEXTJOIN(,TRUE,B221:N221) -> [{"id":14,"num":32},{"id":2,"num":1230000},{"id":1,"num":1230000}] | U221: =INT(E221*0.4) -> 12
A222: =Sheet1!A224 -> 1406021 | B222: [{"id": | C222: 14 | D222: ,"num": | E222: 36 | F222: },{"id": | G222: 2 | H222: ,"num": | I222: 1264000 | J222: },{"id": | K222: 1 | L222: ,"num": | M222: 1260000 | N222: }] | O222: =_xlfn.TEXTJOIN(,TRUE,B222:N222) -> [{"id":14,"num":36},{"id":2,"num":1264000},{"id":1,"num":1260000}] | U222: =INT(E222*0.4) -> 14
A223: =Sheet1!A225 -> 1406022 | B223: [{"id": | C223: 14 | D223: ,"num": | E223: 36 | F223: },{"id": | G223: 2 | H223: ,"num": | I223: 1264000 | J223: },{"id": | K223: 1 | L223: ,"num": | M223: 1260000 | N223: }] | O223: =_xlfn.TEXTJOIN(,TRUE,B223:N223) -> [{"id":14,"num":36},{"id":2,"num":1264000},{"id":1,"num":1260000}] | U223: =INT(E223*0.4) -> 14
A224: =Sheet1!A226 -> 1406023 | B224: [{"id": | C224: 14 | D224: ,"num": | E224: 36 | F224: },{"id": | G224: 2 | H224: ,"num": | I224: 1264000 | J224: },{"id": | K224: 1 | L224: ,"num": | M224: 1260000 | N224: }] | O224: =_xlfn.TEXTJOIN(,TRUE,B224:N224) -> [{"id":14,"num":36},{"id":2,"num":1264000},{"id":1,"num":1260000}] | U224: =INT(E224*0.4) -> 14
A225: =Sheet1!A227 -> 1406024 | B225: [{"id": | C225: 14 | D225: ,"num": | E225: 36 | F225: },{"id": | G225: 2 | H225: ,"num": | I225: 1264000 | J225: },{"id": | K225: 1 | L225: ,"num": | M225: 1260000 | N225: }] | O225: =_xlfn.TEXTJOIN(,TRUE,B225:N225) -> [{"id":14,"num":36},{"id":2,"num":1264000},{"id":1,"num":1260000}] | U225: =INT(E225*0.4) -> 14
A226: =Sheet1!A228 -> 1406025 | B226: [{"id": | C226: 14 | D226: ,"num": | E226: 36 | F226: },{"id": | G226: 2 | H226: ,"num": | I226: 1264000 | J226: },{"id": | K226: 1 | L226: ,"num": | M226: 1260000 | N226: }] | O226: =_xlfn.TEXTJOIN(,TRUE,B226:N226) -> [{"id":14,"num":36},{"id":2,"num":1264000},{"id":1,"num":1260000}] | U226: =INT(E226*0.4) -> 14
A227: =Sheet1!A229 -> 1406026 | B227: [{"id": | C227: 14 | D227: ,"num": | E227: 36 | F227: },{"id": | G227: 2 | H227: ,"num": | I227: 1264000 | J227: },{"id": | K227: 1 | L227: ,"num": | M227: 1260000 | N227: }] | O227: =_xlfn.TEXTJOIN(,TRUE,B227:N227) -> [{"id":14,"num":36},{"id":2,"num":1264000},{"id":1,"num":1260000}] | U227: =INT(E227*0.4) -> 14
A228: =Sheet1!A230 -> 1406027 | B228: [{"id": | C228: 14 | D228: ,"num": | E228: 36 | F228: },{"id": | G228: 2 | H228: ,"num": | I228: 1264000 | J228: },{"id": | K228: 1 | L228: ,"num": | M228: 1260000 | N228: }] | O228: =_xlfn.TEXTJOIN(,TRUE,B228:N228) -> [{"id":14,"num":36},{"id":2,"num":1264000},{"id":1,"num":1260000}] | U228: =INT(E228*0.4) -> 14
A229: =Sheet1!A231 -> 1406028 | B229: [{"id": | C229: 14 | D229: ,"num": | E229: 36 | F229: },{"id": | G229: 2 | H229: ,"num": | I229: 1264000 | J229: },{"id": | K229: 1 | L229: ,"num": | M229: 1260000 | N229: }] | O229: =_xlfn.TEXTJOIN(,TRUE,B229:N229) -> [{"id":14,"num":36},{"id":2,"num":1264000},{"id":1,"num":1260000}] | U229: =INT(E229*0.4) -> 14
A230: =Sheet1!A232 -> 1406029 | B230: [{"id": | C230: 14 | D230: ,"num": | E230: 36 | F230: },{"id": | G230: 2 | H230: ,"num": | I230: 1264000 | J230: },{"id": | K230: 1 | L230: ,"num": | M230: 1260000 | N230: }] | O230: =_xlfn.TEXTJOIN(,TRUE,B230:N230) -> [{"id":14,"num":36},{"id":2,"num":1264000},{"id":1,"num":1260000}] | U230: =INT(E230*0.4) -> 14
A231: =Sheet1!A233 -> 1406030 | B231: [{"id": | C231: 14 | D231: ,"num": | E231: 36 | F231: },{"id": | G231: 2 | H231: ,"num": | I231: 1264000 | J231: },{"id": | K231: 1 | L231: ,"num": | M231: 1260000 | N231: }] | O231: =_xlfn.TEXTJOIN(,TRUE,B231:N231) -> [{"id":14,"num":36},{"id":2,"num":1264000},{"id":1,"num":1260000}] | U231: =INT(E231*0.4) -> 14
A232: =Sheet1!A234 -> 1406031 | B232: [{"id": | C232: 14 | D232: ,"num": | E232: 36 | F232: },{"id": | G232: 2 | H232: ,"num": | I232: 1264000 | J232: },{"id": | K232: 1 | L232: ,"num": | M232: 1260000 | N232: }] | O232: =_xlfn.TEXTJOIN(,TRUE,B232:N232) -> [{"id":14,"num":36},{"id":2,"num":1264000},{"id":1,"num":1260000}] | U232: =INT(E232*0.4) -> 14
A233: =Sheet1!A235 -> 1406032 | B233: [{"id": | C233: 14 | D233: ,"num": | E233: 36 | F233: },{"id": | G233: 2 | H233: ,"num": | I233: 1264000 | J233: },{"id": | K233: 1 | L233: ,"num": | M233: 1260000 | N233: }] | O233: =_xlfn.TEXTJOIN(,TRUE,B233:N233) -> [{"id":14,"num":36},{"id":2,"num":1264000},{"id":1,"num":1260000}] | U233: =INT(E233*0.4) -> 14
... A321: =Sheet1!A323 -> 1408040 | B321: [{"id": | C321: 14 | D321: ,"num": | E321: 40 | F321: },{"id": | G321: 2 | H321: ,"num": | I321: 1878000 | J321: },{"id": | K321: 1 | L321: ,"num": | M321: 1870000 | N321: }] | O321: =_xlfn.TEXTJOIN(,TRUE,B321:N321) -> [{"id":14,"num":40},{"id":2,"num":1878000},{"id":1,"num":1870000}] | U321: =INT(E321*0.4) -> 16
...

Sheet 首领结算奖励
A1: 索引 | C1: 道具ID | E1: 道具数量 | G1: 道具ID | I1: 道具数量 | K1: 道具ID | M1: 道具数量 | O1: 生成
A2: =Sheet1!A804 -> 1501001 | B2: [{"id": | C2: 14 | D2: ,"num": | E2: 50 | F2: },{"id": | G2: 5 | H2: ,"num": | I2: 100 | J2: },{"id": | K2: 60 | L2: ,"num": | M2: 1 | N2: }] | O2: =_xlfn.TEXTJOIN(,TRUE,B2:N2) -> [{"id":14,"num":50},{"id":5,"num":100},{"id":60,"num":1}]
A3: =Sheet1!A805 -> 1501002 | B3: [{"id": | C3: 14 | D3: ,"num": | E3: 50 | F3: },{"id": | G3: 5 | H3: ,"num": | I3: 125 | J3: },{"id": | K3: 60 | L3: ,"num": | M3: 1 | N3: }] | O3: =_xlfn.TEXTJOIN(,TRUE,B3:N3) -> [{"id":14,"num":50},{"id":5,"num":125},{"id":60,"num":1}]
A4: =Sheet1!A806 -> 1501003 | B4: [{"id": | C4: 14 | D4: ,"num": | E4: 50 | F4: },{"id": | G4: 5 | H4: ,"num": | I4: 150 | J4: },{"id": | K4: 60 | L4: ,"num": | M4: 1 | N4: }] | O4: =_xlfn.TEXTJOIN(,TRUE,B4:N4) -> [{"id":14,"num":50},{"id":5,"num":150},{"id":60,"num":1}]
A5: =Sheet1!A807 -> 1501004 | B5: [{"id": | C5: 14 | D5: ,"num": | E5: 50 | F5: },{"id": | G5: 5 | H5: ,"num": | I5: 175 | J5: },{"id": | K5: 60 | L5: ,"num": | M5: 1 | N5: }] | O5: =_xlfn.TEXTJOIN(,TRUE,B5:N5) -> [{"id":14,"num":50},{"id":5,"num":175},{"id":60,"num":1}]
A6: =Sheet1!A808 -> 1501005 | B6: [{"id": | C6: 14 | D6: ,"num": | E6: 50 | F6: },{"id": | G6: 5 | H6: ,"num": | I6: 200 | J6: },{"id": | K6: 60 | L6: ,"num": | M6: 1 | N6: }] | O6: =_xlfn.TEXTJOIN(,TRUE,B6:N6) -> [{"id":14,"num":50},{"id":5,"num":200},{"id":60,"num":1}]
A7: =Sheet1!A809 -> 1501006 | B7: [{"id": | C7: 14 | D7: ,"num": | E7: 50 | F7: },{"id": | G7: 5 | H7: ,"num": | I7: 225 | J7: },{"id": | K7: 61 | L7: ,"num": | M7: 1 | N7: }] | O7: =_xlfn.TEXTJOIN(,TRUE,B7:N7) -> [{"id":14,"num":50},{"id":5,"num":225},{"id":61,"num":1}]
A8: =Sheet1!A810 -> 1501007 | B8: [{"id": | C8: 14 | D8: ,"num": | E8: 50 | F8: },{"id": | G8: 5 | H8: ,"num": | I8: 250 | J8: },{"id": | K8: 61 | L8: ,"num": | M8: 1 | N8: }] | O8: =_xlfn.TEXTJOIN(,TRUE,B8:N8) -> [{"id":14,"num":50},{"id":5,"num":250},{"id":61,"num":1}]
A9: =Sheet1!A811 -> 1501008 | B9: [{"id": | C9: 14 | D9: ,"num": | E9: 50 | F9: },{"id": | G9: 5 | H9: ,"num": | I9: 265 | J9: },{"id": | K9: 61 | L9: ,"num": | M9: 1 | N9: }] | O9: =_xlfn.TEXTJOIN(,TRUE,B9:N9) -> [{"id":14,"num":50},{"id":5,"num":265},{"id":61,"num":1}]
A10: =Sheet1!A812 -> 1501009 | B10: [{"id": | C10: 14 | D10: ,"num": | E10: 50 | F10: },{"id": | G10: 5 | H10: ,"num": | I10: 280 | J10: },{"id": | K10: 61 | L10: ,"num": | M10: 1 | N10: }] | O10: =_xlfn.TEXTJOIN(,TRUE,B10:N10) -> [{"id":14,"num":50},{"id":5,"num":280},{"id":61,"num":1}]
A11: =Sheet1!A813 -> 1501010 | B11: [{"id": | C11: 14 | D11: ,"num": | E11: 50 | F11: },{"id": | G11: 5 | H11: ,"num": | I11: 295 | J11: },{"id": | K11: 61 | L11: ,"num": | M11: 1 | N11: }] | O11: =_xlfn.TEXTJOIN(,TRUE,B11:N11) -> [{"id":14,"num":50},{"id":5,"num":295},{"id":61,"num":1}]
A12: =Sheet1!A814 -> 1501011 | B12: [{"id": | C12: 14 | D12: ,"num": | E12: 50 | F12: },{"id": | G12: 5 | H12: ,"num": | I12: 310 | J12: },{"id": | K12: 61 | L12: ,"num": | M12: 2 | N12: }] | O12: =_xlfn.TEXTJOIN(,TRUE,B12:N12) -> [{"id":14,"num":50},{"id":5,"num":310},{"id":61,"num":2}]
A13: =Sheet1!A815 -> 1501012 | B13: [{"id": | C13: 14 | D13: ,"num": | E13: 50 | F13: },{"id": | G13: 5 | H13: ,"num": | I13: 325 | J13: },{"id": | K13: 61 | L13: ,"num": | M13: 2 | N13: }] | O13: =_xlfn.TEXTJOIN(,TRUE,B13:N13) -> [{"id":14,"num":50},{"id":5,"num":325},{"id":61,"num":2}]
... A121: =Sheet1!A923 -> 1501120 | B121: [{"id": | C121: 14 | D121: ,"num": | E121: 100 | F121: },{"id": | G121: 5 | H121: ,"num": | I121: 890 | J121: },{"id": | K121: 63 | L121: ,"num": | M121: 10 | N121: }] | O121: =_xlfn.TEXTJOIN(,TRUE,B121:N121) -> [{"id":14,"num":100},{"id":5,"num":890},{"id":63,"num":10}]

Sheet 试炼塔结算奖励
A1: 索引 | C1: 道具ID | E1: 道具数量 | G1: 道具ID | I1: 道具数量 | K1: 道具ID | M1: 道具数量 | O1: 生成
A2: =Sheet1!A924 -> 1601001 | B2: [{"id": | C2: 8 | D2: ,"num": | E2: 150 | F2: },{"id": | G2: 1 | H2: ,"num": | I2: 75000 | J2: },{"id": | K2: 11 | L2: ,"num": | M2: 1 | N2: }] | O2: =_xlfn.TEXTJOIN(,TRUE,B2:N2) -> [{"id":8,"num":150},{"id":1,"num":75000},{"id":11,"num":1}]
A3: =Sheet1!A925 -> 1601002 | B3: [{"id": | C3: 8 | D3: ,"num": | E3: 160 | F3: },{"id": | G3: 1 | H3: ,"num": | I3: 80000 | J3: },{"id": | K3: 11 | L3: ,"num": | M3: 2 | N3: }] | O3: =_xlfn.TEXTJOIN(,TRUE,B3:N3) -> [{"id":8,"num":160},{"id":1,"num":80000},{"id":11,"num":2}]
A4: =Sheet1!A926 -> 1601003 | B4: [{"id": | C4: 8 | D4: ,"num": | E4: 170 | F4: },{"id": | G4: 1 | H4: ,"num": | I4: 85000 | J4: },{"id": | K4: 11 | L4: ,"num": | M4: 3 | N4: }] | O4: =_xlfn.TEXTJOIN(,TRUE,B4:N4) -> [{"id":8,"num":170},{"id":1,"num":85000},{"id":11,"num":3}]
A5: =Sheet1!A927 -> 1601004 | B5: [{"id": | C5: 8 | D5: ,"num": | E5: 180 | F5: },{"id": | G5: 1 | H5: ,"num": | I5: 90000 | J5: },{"id": | K5: 11 | L5: ,"num": | M5: 4 | N5: }] | O5: =_xlfn.TEXTJOIN(,TRUE,B5:N5) -> [{"id":8,"num":180},{"id":1,"num":90000},{"id":11,"num":4}]
A6: =Sheet1!A928 -> 1601005 | B6: [{"id": | C6: 8 | D6: ,"num": | E6: 190 | F6: },{"id": | G6: 1 | H6: ,"num": | I6: 95000 | J6: },{"id": | K6: 11 | L6: ,"num": | M6: 5 | N6: }] | O6: =_xlfn.TEXTJOIN(,TRUE,B6:N6) -> [{"id":8,"num":190},{"id":1,"num":95000},{"id":11,"num":5}]
A7: =Sheet1!A929 -> 1601006 | B7: [{"id": | C7: 8 | D7: ,"num": | E7: 200 | F7: },{"id": | G7: 1 | H7: ,"num": | I7: 100000 | J7: },{"id": | K7: 11 | L7: ,"num": | M7: 6 | N7: }] | O7: =_xlfn.TEXTJOIN(,TRUE,B7:N7) -> [{"id":8,"num":200},{"id":1,"num":100000},{"id":11,"num":6}]
A8: =Sheet1!A930 -> 1601007 | B8: [{"id": | C8: 8 | D8: ,"num": | E8: 210 | F8: },{"id": | G8: 1 | H8: ,"num": | I8: 105000 | J8: },{"id": | K8: 11 | L8: ,"num": | M8: 7 | N8: }] | O8: =_xlfn.TEXTJOIN(,TRUE,B8:N8) -> [{"id":8,"num":210},{"id":1,"num":105000},{"id":11,"num":7}]
A9: =Sheet1!A931 -> 1601008 | B9: [{"id": | C9: 8 | D9: ,"num": | E9: 220 | F9: },{"id": | G9: 1 | H9: ,"num": | I9: 110000 | J9: },{"id": | K9: 11 | L9: ,"num": | M9: 8 | N9: }] | O9: =_xlfn.TEXTJOIN(,TRUE,B9:N9) -> [{"id":8,"num":220},{"id":1,"num":110000},{"id":11,"num":8}]
A10: =Sheet1!A932 -> 1601009 | B10: [{"id": | C10: 8 | D10: ,"num": | E10: 230 | F10: },{"id": | G10: 1 | H10: ,"num": | I10: 115000 | J10: },{"id": | K10: 11 | L10: ,"num": | M10: 9 | N10: }] | O10: =_xlfn.TEXTJOIN(,TRUE,B10:N10) -> [{"id":8,"num":230},{"id":1,"num":115000},{"id":11,"num":9}]
A11: =Sheet1!A933 -> 1601010 | B11: [{"id": | C11: 8 | D11: ,"num": | E11: 240 | F11: },{"id": | G11: 1 | H11: ,"num": | I11: 120000 | J11: },{"id": | K11: 11 | L11: ,"num": | M11: 10 | N11: }] | O11: =_xlfn.TEXTJOIN(,TRUE,B11:N11) -> [{"id":8,"num":240},{"id":1,"num":120000},{"id":11,"num":10}]
A12: =Sheet1!A934 -> 1601011 | B12: [{"id": | C12: 8 | D12: ,"num": | E12: 250 | F12: },{"id": | G12: 1 | H12: ,"num": | I12: 125000 | J12: },{"id": | K12: 11 | L12: ,"num": | M12: 11 | N12: }] | O12: =_xlfn.TEXTJOIN(,TRUE,B12:N12) -> [{"id":8,"num":250},{"id":1,"num":125000},{"id":11,"num":11}]
A13: =Sheet1!A935 -> 1601012 | B13: [{"id": | C13: 8 | D13: ,"num": | E13: 260 | F13: },{"id": | G13: 1 | H13: ,"num": | I13: 130000 | J13: },{"id": | K13: 11 | L13: ,"num": | M13: 12 | N13: }] | O13: =_xlfn.TEXTJOIN(,TRUE,B13:N13) -> [{"id":8,"num":260},{"id":1,"num":130000},{"id":11,"num":12}]
... A62: =Sheet1!A984 -> 1601061 | B62: [{"id": | C62: 8 | D62: ,"num": | E62: 750 | F62: },{"id": | G62: 1 | H62: ,"num": | I62: 375000 | J62: },{"id": | K62: 22 | L62: ,"num": | M62: 1900 | N62: }] | O62: =_xlfn.TEXTJOIN(,TRUE,B62:N62) -> [{"id":8,"num":750},{"id":1,"num":375000},{"id":22,"num":1900}]

Sheet 遗迹结算奖励
A1: 索引 | C1: 道具ID | E1: 道具数量 | G1: 道具ID | I1: 道具数量 | K1: 道具ID | M1: 道具数量 | O1: 生成
A2: =Sheet1!A985 -> 1701001 | B2: [{"id": | C2: 2 | D2: ,"num": | E2: 10600 | F2: },{"id": | G2: 1 | H2: ,"num": | I2: 10000 | J2: },{"id": | K2: 84 | L2: ,"num": | M2: 1 | N2: }] | O2: =_xlfn.TEXTJOIN(,TRUE,B2:N2) -> [{"id":2,"num":10600},{"id":1,"num":10000},{"id":84,"num":1}]
A3: =Sheet1!A986 -> 1701002 | B3: [{"id": | C3: 2 | D3: ,"num": | E3: 10600 | F3: },{"id": | G3: 1 | H3: ,"num": | I3: 10000 | J3: },{"id": | K3: 84 | L3: ,"num": | M3: 1 | N3: }] | O3: =_xlfn.TEXTJOIN(,TRUE,B3:N3) -> [{"id":2,"num":10600},{"id":1,"num":10000},{"id":84,"num":1}]
A4: =Sheet1!A987 -> 1701003 | B4: [{"id": | C4: 2 | D4: ,"num": | E4: 10600 | F4: },{"id": | G4: 1 | H4: ,"num": | I4: 10000 | J4: },{"id": | K4: 84 | L4: ,"num": | M4: 1 | N4: }] | O4: =_xlfn.TEXTJOIN(,TRUE,B4:N4) -> [{"id":2,"num":10600},{"id":1,"num":10000},{"id":84,"num":1}]
A5: =Sheet1!A988 -> 1701004 | B5: [{"id": | C5: 2 | D5: ,"num": | E5: 10600 | F5: },{"id": | G5: 1 | H5: ,"num": | I5: 10000 | J5: },{"id": | K5: 84 | L5: ,"num": | M5: 1 | N5: }] | O5: =_xlfn.TEXTJOIN(,TRUE,B5:N5) -> [{"id":2,"num":10600},{"id":1,"num":10000},{"id":84,"num":1}]
A6: =Sheet1!A989 -> 1701005 | B6: [{"id": | C6: 2 | D6: ,"num": | E6: 10600 | F6: },{"id": | G6: 1 | H6: ,"num": | I6: 10000 | J6: },{"id": | K6: 84 | L6: ,"num": | M6: 1 | N6: }] | O6: =_xlfn.TEXTJOIN(,TRUE,B6:N6) -> [{"id":2,"num":10600},{"id":1,"num":10000},{"id":84,"num":1}]
A7: =Sheet1!A990 -> 1701006 | B7: [{"id": | C7: 2 | D7: ,"num": | E7: 10600 | F7: },{"id": | G7: 1 | H7: ,"num": | I7: 10000 | J7: },{"id": | K7: 84 | L7: ,"num": | M7: 1 | N7: }] | O7: =_xlfn.TEXTJOIN(,TRUE,B7:N7) -> [{"id":2,"num":10600},{"id":1,"num":10000},{"id":84,"num":1}]
A8: =Sheet1!A991 -> 1701007 | B8: [{"id": | C8: 2 | D8: ,"num": | E8: 10600 | F8: },{"id": | G8: 1 | H8: ,"num": | I8: 10000 | J8: },{"id": | K8: 84 | L8: ,"num": | M8: 1 | N8: }] | O8: =_xlfn.TEXTJOIN(,TRUE,B8:N8) -> [{"id":2,"num":10600},{"id":1,"num":10000},{"id":84,"num":1}]
A9: =Sheet1!A992 -> 1701008 | B9: [{"id": | C9: 2 | D9: ,"num": | E9: 10600 | F9: },{"id": | G9: 1 | H9: ,"num": | I9: 10000 | J9: },{"id": | K9: 84 | L9: ,"num": | M9: 1 | N9: }] | O9: =_xlfn.TEXTJOIN(,TRUE,B9:N9) -> [{"id":2,"num":10600},{"id":1,"num":10000},{"id":84,"num":1}]
A10: =Sheet1!A993 -> 1701009 | B10: [{"id": | C10: 2 | D10: ,"num": | E10: 10600 | F10: },{"id": | G10: 1 | H10: ,"num": | I10: 10000 | J10: },{"id": | K10: 84 | L10: ,"num": | M10: 1 | N10: }] | O10: =_xlfn.TEXTJOIN(,TRUE,B10:N10) -> [{"id":2,"num":10600},{"id":1,"num":10000},{"id":84,"num":1}]
A11: =Sheet1!A994 -> 1701010 | B11: [{"id": | C11: 2 | D11: ,"num": | E11: 10600 | F11: },{"id": | G11: 1 | H11: ,"num": | I11: 10000 | J11: },{"id": | K11: 84 | L11: ,"num": | M11: 1 | N11: }] | O11: =_xlfn.TEXTJOIN(,TRUE,B11:N11) -> [{"id":2,"num":10600},{"id":1,"num":10000},{"id":84,"num":1}]
A12: =Sheet1!A995 -> 1702001 | B12: [{"id": | C12: 2 | D12: ,"num": | E12: 22400 | F12: },{"id": | G12: 1 | H12: ,"num": | I12: 20000 | J12: },{"id": | K12: 85 | L12: ,"num": | M12: 1 | N12: }] | O12: =_xlfn.TEXTJOIN(,TRUE,B12:N12) -> [{"id":2,"num":22400},{"id":1,"num":20000},{"id":85,"num":1}]
A13: =Sheet1!A996 -> 1702002 | B13: [{"id": | C13: 2 | D13: ,"num": | E13: 22400 | F13: },{"id": | G13: 1 | H13: ,"num": | I13: 20000 | J13: },{"id": | K13: 85 | L13: ,"num": | M13: 1 | N13: }] | O13: =_xlfn.TEXTJOIN(,TRUE,B13:N13) -> [{"id":2,"num":22400},{"id":1,"num":20000},{"id":85,"num":1}]
... A61: =Sheet1!A1044 -> 1706010 | B61: [{"id": | C61: 2 | D61: ,"num": | E61: 1698800 | F61: },{"id": | G61: 1 | H61: ,"num": | I61: 1690000 | J61: },{"id": | K61: 86 | L61: ,"num": | M61: 1 | N61: }] | O61: =_xlfn.TEXTJOIN(,TRUE,B61:N61) -> [{"id":2,"num":1698800},{"id":1,"num":1690000},{"id":86,"num":1}]
A62: =Sheet1!A1045 -> 1707001 | B62: [{"id": | C62: 2 | D62: ,"num": | E62: 1698800 | F62: },{"id": | G62: 1 | H62: ,"num": | I62: 1690000 | J62: },{"id": | K62: 86 | L62: ,"num": | M62: =M52+1 -> 2 | N62: }] | O62: =_xlfn.TEXTJOIN(,TRUE,B62:N62) -> [{"id":2,"num":1698800},{"id":1,"num":1690000},{"id":86,"num":2}]
A63: =Sheet1!A1046 -> 1707002 | B63: [{"id": | C63: 2 | D63: ,"num": | E63: 1698800 | F63: },{"id": | G63: 1 | H63: ,"num": | I63: 1690000 | J63: },{"id": | K63: 86 | L63: ,"num": | M63: =M53+1 -> 2 | N63: }] | O63: =_xlfn.TEXTJOIN(,TRUE,B63:N63) -> [{"id":2,"num":1698800},{"id":1,"num":1690000},{"id":86,"num":2}]
A64: =Sheet1!A1047 -> 1707003 | B64: [{"id": | C64: 2 | D64: ,"num": | E64: 1698800 | F64: },{"id": | G64: 1 | H64: ,"num": | I64: 1690000 | J64: },{"id": | K64: 86 | L64: ,"num": | M64: =M54+1 -> 2 | N64: }] | O64: =_xlfn.TEXTJOIN(,TRUE,B64:N64) -> [{"id":2,"num":1698800},{"id":1,"num":1690000},{"id":86,"num":2}]
A65: =Sheet1!A1048 -> 1707004 | B65: [{"id": | C65: 2 | D65: ,"num": | E65: 1698800 | F65: },{"id": | G65: 1 | H65: ,"num": | I65: 1690000 | J65: },{"id": | K65: 86 | L65: ,"num": | M65: =M55+1 -> 2 | N65: }] | O65: =_xlfn.TEXTJOIN(,TRUE,B65:N65) -> [{"id":2,"num":1698800},{"id":1,"num":1690000},{"id":86,"num":2}]
A66: =Sheet1!A1049 -> 1707005 | B66: [{"id": | C66: 2 | D66: ,"num": | E66: 1698800 | F66: },{"id": | G66: 1 | H66: ,"num": | I66: 1690000 | J66: },{"id": | K66: 86 | L66: ,"num": | M66: =M56+1 -> 2 | N66: }] | O66: =_xlfn.TEXTJOIN(,TRUE,B66:N66) -> [{"id":2,"num":1698800},{"id":1,"num":1690000},{"id":86,"num":2}]
A67: =Sheet1!A1050 -> 1707006 | B67: [{"id": | C67: 2 | D67: ,"num": | E67: 1698800 | F67: },{"id": | G67: 1 | H67: ,"num": | I67: 1690000 | J67: },{"id": | K67: 86 | L67: ,"num": | M67: =M57+1 -> 2 | N67: }] | O67: =_xlfn.TEXTJOIN(,TRUE,B67:N67) -> [{"id":2,"num":1698800},{"id":1,"num":1690000},{"id":86,"num":2}]
A68: =Sheet1!A1051 -> 1707007 | B68: [{"id": | C68: 2 | D68: ,"num": | E68: 1698800 | F68: },{"id": | G68: 1 | H68: ,"num": | I68: 1690000 | J68: },{"id": | K68: 86 | L68: ,"num": | M68: =M58+1 -> 2 | N68: }] | O68: =_xlfn.TEXTJOIN(,TRUE,B68:N68) -> [{"id":2,"num":1698800},{"id":1,"num":1690000},{"id":86,"num":2}]
A69: =Sheet1!A1052 -> 1707008 | B69: [{"id": | C69: 2 | D69: ,"num": | E69: 1698800 | F69: },{"id": | G69: 1 | H69: ,"num": | I69: 1690000 | J69: },{"id": | K69: 86 | L69: ,"num": | M69: =M59+1 -> 2 | N69: }] | O69: =_xlfn.TEXTJOIN(,TRUE,B69:N69) -> [{"id":2,"num":1698800},{"id":1,"num":1690000},{"id":86,"num":2}]
A70: =Sheet1!A1053 -> 1707009 | B70: [{"id": | C70: 2 | D70: ,"num": | E70: 1698800 | F70: },{"id": | G70: 1 | H70: ,"num": | I70: 1690000 | J70: },{"id": | K70: 86 | L70: ,"num": | M70: =M60+1 -> 2 | N70: }] | O70: =_xlfn.TEXTJOIN(,TRUE,B70:N70) -> [{"id":2,"num":1698800},{"id":1,"num":1690000},{"id":86,"num":2}]
A71: =Sheet1!A1054 -> 1707010 | B71: [{"id": | C71: 2 | D71: ,"num": | E71: 1698800 | F71: },{"id": | G71: 1 | H71: ,"num": | I71: 1690000 | J71: },{"id": | K71: 86 | L71: ,"num": | M71: =M61+1 -> 2 | N71: }] | O71: =_xlfn.TEXTJOIN(,TRUE,B71:N71) -> [{"id":2,"num":1698800},{"id":1,"num":1690000},{"id":86,"num":2}]
A72: =Sheet1!A1055 -> 1708001 | B72: [{"id": | C72: 2 | D72: ,"num": | E72: 1698800 | F72: },{"id": | G72: 1 | H72: ,"num": | I72: 1690000 | J72: },{"id": | K72: 86 | L72: ,"num": | M72: =M62+1 -> 3 | N72: }] | O72: =_xlfn.TEXTJOIN(,TRUE,B72:N72) -> [{"id":2,"num":1698800},{"id":1,"num":1690000},{"id":86,"num":3}]
A73: =Sheet1!A1056 -> 1708002 | B73: [{"id": | C73: 2 | D73: ,"num": | E73: 1698800 | F73: },{"id": | G73: 1 | H73: ,"num": | I73: 1690000 | J73: },{"id": | K73: 86 | L73: ,"num": | M73: =M63+1 -> 3 | N73: }] | O73: =_xlfn.TEXTJOIN(,TRUE,B73:N73) -> [{"id":2,"num":1698800},{"id":1,"num":1690000},{"id":86,"num":3}]
... A201: =Sheet1!A1184 -> 1720010 | B201: [{"id": | C201: 2 | D201: ,"num": | E201: 1698800 | F201: },{"id": | G201: 1 | H201: ,"num": | I201: 1690000 | J201: },{"id": | K201: 86 | L201: ,"num": | M201: =M191+1 -> 15 | N201: }] | O201: =_xlfn.TEXTJOIN(,TRUE,B201:N201) -> [{"id":2,"num":1698800},{"id":1,"num":1690000},{"id":86,"num":15}]

Sheet Sheet2
A1: 1408020 | B1: ,"point":{"x":15,"y":35}}, {"id":30, "num":6,"point":{"x":26,"y":39}}, {"id":30, "num":5,"point":{"x":36,"y":37}}, {"id":60, "num":1,"point":{"x":25,"y":42}}]
A2: 1408021 | B2: [{"id":231,"num":2,"point":{"x":24,"y":37}}, {"id":231, "num":2,"point":{"x":15,"y":35}}, {"id":231, "num":2,"point":{"x":33,"y":33}}]
A3: 1408022 | B3: [{"id":231,"num":3,"point":{"x":24,"y":37}}, {"id":231, "num":2,"point":{"x":15,"y":35}}, {"id":231, "num":2,"point":{"x":33,"y":33}}]
A4: 1408023 | B4: [{"id":231,"num":3,"point":{"x":16,"y":38}}, {"id":231, "num":3,"point":{"x":35,"y":35}}, {"id":231, "num":3,"point":{"x":23,"y":12}}]
A5: 1408024 | B5: [{"id":231,"num":4,"point":{"x":16,"y":38}}, {"id":231, "num":3,"point":{"x":35,"y":35}}, {"id":231, "num":3,"point":{"x":23,"y":12}}]
A6: 1408025 | B6: [{"id":231,"num":4,"point":{"x":16,"y":20}}, {"id":231, "num":4,"point":{"x":25,"y":37}}, {"id":231, "num":4,"point":{"x":33,"y":16}}]
A7: 1408026 | B7: [{"id":231,"num":5,"point":{"x":16,"y":20}}, {"id":231, "num":4,"point":{"x":25,"y":37}}, {"id":231, "num":4,"point":{"x":33,"y":16}}]
A8: 1408027 | B8: [{"id":231,"num":5,"point":{"x":25,"y":35}}, {"id":231, "num":5,"point":{"x":33,"y":33}}, {"id":231, "num":5,"point":{"x":20,"y":18}}]
A9: 1408028 | B9: [{"id":231,"num":6,"point":{"x":25,"y":35}}, {"id":231, "num":5,"point":{"x":33,"y":33}}, {"id":231, "num":5,"point":{"x":20,"y":18}}]
A10: 1408029 | B10: [{"id":231,"num":6,"point":{"x":15,"y":35}}, {"id":231, "num":6,"point":{"x":26,"y":39}}, {"id":231, "num":5,"point":{"x":36,"y":37}}]
A11: 1408030 | B11: [{"id":231,"num":6,"point":{"x":15,"y":35}}, {"id":231, "num":6,"point":{"x":26,"y":39}}, {"id":231, "num":5,"point":{"x":36,"y":37}}, {"id":261, "num":1,"point":{"x":25,"y":42}}]
A14: 1408020 | B14: =CONCATENATE(C14,D14,E14,F14,G14,H14,I14,J14,K14,L14,M14,N14,O14,P14,Q14,R14,S14) -> [{"id":30,"num":6,"point":{"x":15,"y":35}}, {"id":30, "num":6,"point":{"x":26,"y":39}}, {"id":30, "num":5,"point":{"x":36,"y":37}}, {"id":60, "num":1,"point":{"x":25,"y":42}}] | C14: [{"id": | D14: 30 | E14: ,"num": | F14: 6 | G14: ,"point":{"x":15,"y":35}}, {"id": | H14: 30 | I14: , "num": | J14: 6 | K14: ,"point":{"x":26,"y":39}}, {"id": | L14: 30 | M14: , "num": | N14: 5 | O14: ,"point":{"x":36,"y":37}}, {"id": | P14: 60 | Q14: , "num": | R14: 1 | S14: ,"point":{"x":25,"y":42}}]
A15: 1408021 | B15: =CONCATENATE(C15,D15,E15,F15,G15,H15,I15,J15,K15,L15,M15,N15,O15,P15,Q15,R15,S15) -> [{"id":201,"num":2,"point":{"x":24,"y":37}}, {"id":201, "num":2,"point":{"x":15,"y":35}}, {"id":231, "num":3,"point":{"x":33,"y":33}}] | C15: [{"id": | D15: 201 | E15: ,"num": | F15: 2 | G15: ,"point":{"x":24,"y":37}}, {"id": | H15: =D15 -> 201 | I15: , "num": | J15: 2 | K15: ,"point":{"x":15,"y":35}}, {"id": | L15: 231 | M15: , "num": | N15: 3 | O15: ,"point":{"x":33,"y":33}}]
A16: 1408022 | B16: =CONCATENATE(C16,D16,E16,F16,G16,H16,I16,J16,K16,L16,M16,N16,O16,P16,Q16,R16,S16) -> [{"id":201,"num":3,"point":{"x":24,"y":37}}, {"id":201, "num":2,"point":{"x":15,"y":35}}, {"id":231, "num":3,"point":{"x":33,"y":33}}] | C16: [{"id": | D16: 201 | E16: ,"num": | F16: 3 | G16: ,"point":{"x":24,"y":37}}, {"id": | H16: =D16 -> 201 | I16: , "num": | J16: 2 | K16: ,"point":{"x":15,"y":35}}, {"id": | L16: 231 | M16: , "num": | N16: 3 | O16: ,"point":{"x":33,"y":33}}]
A17: 1408023 | B17: =CONCATENATE(C17,D17,E17,F17,G17,H17,I17,J17,K17,L17,M17,N17,O17,P17,Q17,R17,S17) -> [{"id":202,"num":3,"point":{"x":16,"y":38}}, {"id":202, "num":3,"point":{"x":35,"y":35}}, {"id":231, "num":4,"point":{"x":23,"y":12}}] | C17: [{"id": | D17: 202 | E17: ,"num": | F17: 3 | G17: ,"point":{"x":16,"y":38}}, {"id": | H17: =D17 -> 202 | I17: , "num": | J17: 3 | K17: ,"point":{"x":35,"y":35}}, {"id": | L17: 231 | M17: , "num": | N17: 4 | O17: ,"point":{"x":23,"y":12}}]
A18: 1408024 | B18: =CONCATENATE(C18,D18,E18,F18,G18,H18,I18,J18,K18,L18,M18,N18,O18,P18,Q18,R18,S18) -> [{"id":202,"num":4,"point":{"x":16,"y":38}}, {"id":202, "num":3,"point":{"x":35,"y":35}}, {"id":231, "num":4,"point":{"x":23,"y":12}}] | C18: [{"id": | D18: 202 | E18: ,"num": | F18: 4 | G18: ,"point":{"x":16,"y":38}}, {"id": | H18: =D18 -> 202 | I18: , "num": | J18: 3 | K18: ,"point":{"x":35,"y":35}}, {"id": | L18: 231 | M18: , "num": | N18: 4 | O18: ,"point":{"x":23,"y":12}}]
A19: 1408025 | B19: =CONCATENATE(C19,D19,E19,F19,G19,H19,I19,J19,K19,L19,M19,N19,O19,P19,Q19,R19,S19) -> [{"id":203,"num":4,"point":{"x":16,"y":20}}, {"id":203, "num":4,"point":{"x":25,"y":37}}, {"id":231, "num":5,"point":{"x":33,"y":16}}] | C19: [{"id": | D19: 203 | E19: ,"num": | F19: 4 | G19: ,"point":{"x":16,"y":20}}, {"id": | H19: =D19 -> 203 | I19: , "num": | J19: 4 | K19: ,"point":{"x":25,"y":37}}, {"id": | L19: 231 | M19: , "num": | N19: 5 | O19: ,"point":{"x":33,"y":16}}]
A20: 1408026 | B20: =CONCATENATE(C20,D20,E20,F20,G20,H20,I20,J20,K20,L20,M20,N20,O20,P20,Q20,R20,S20) -> [{"id":203,"num":5,"point":{"x":16,"y":20}}, {"id":203, "num":4,"point":{"x":25,"y":37}}, {"id":231, "num":5,"point":{"x":33,"y":16}}] | C20: [{"id": | D20: 203 | E20: ,"num": | F20: 5 | G20: ,"point":{"x":16,"y":20}}, {"id": | H20: =D20 -> 203 | I20: , "num": | J20: 4 | K20: ,"point":{"x":25,"y":37}}, {"id": | L20: 231 | M20: , "num": | N20: 5 | O20: ,"point":{"x":33,"y":16}}]
A21: 1408027 | B21: =CONCATENATE(C21,D21,E21,F21,G21,H21,I21,J21,K21,L21,M21,N21,O21,P21,Q21,R21,S21) -> [{"id":204,"num":5,"point":{"x":25,"y":35}}, {"id":204, "num":5,"point":{"x":33,"y":33}}, {"id":231, "num":5,"point":{"x":20,"y":18}}] | C21: [{"id": | D21: 204 | E21: ,"num": | F21: 5 | G21: ,"point":{"x":25,"y":35}}, {"id": | H21: =D21 -> 204 | I21: , "num": | J21: 5 | K21: ,"point":{"x":33,"y":33}}, {"id": | L21: 231 | M21: , "num": | N21: 5 | O21: ,"point":{"x":20,"y":18}}]
A22: 1408028 | B22: =CONCATENATE(C22,D22,E22,F22,G22,H22,I22,J22,K22,L22,M22,N22,O22,P22,Q22,R22,S22) -> [{"id":204,"num":6,"point":{"x":25,"y":35}}, {"id":204, "num":5,"point":{"x":33,"y":33}}, {"id":231, "num":6,"point":{"x":20,"y":18}}] | C22: [{"id": | D22: 204 | E22: ,"num": | F22: 6 | G22: ,"point":{"x":25,"y":35}}, {"id": | H22: =D22 -> 204 | I22: , "num": | J22: 5 | K22: ,"point":{"x":33,"y":33}}, {"id": | L22: 231 | M22: , "num": | N22: 6 | O22: ,"point":{"x":20,"y":18}}]
A23: 1408029 | B23: =CONCATENATE(C23,D23,E23,F23,G23,H23,I23,J23,K23,L23,M23,N23,O23,P23,Q23,R23,S23) -> [{"id":205,"num":6,"point":{"x":15,"y":35}}, {"id":205, "num":6,"point":{"x":26,"y":39}}, {"id":231, "num":6,"point":{"x":36,"y":37}}] | C23: [{"id": | D23: 205 | E23: ,"num": | F23: 6 | G23: ,"point":{"x":15,"y":35}}, {"id": | H23: =D23 -> 205 | I23: , "num": | J23: 6 | K23: ,"point":{"x":26,"y":39}}, {"id": | L23: 231 | M23: , "num": | N23: 6 | O23: ,"point":{"x":36,"y":37}}]
A24: 1408030 | B24: =CONCATENATE(C24,D24,E24,F24,G24,H24,I24,J24,K24,L24,M24,N24,O24,P24,Q24,R24,S24) -> [{"id":206,"num":6,"point":{"x":15,"y":35}}, {"id":206, "num":6,"point":{"x":26,"y":39}}, {"id":231, "num":7,"point":{"x":36,"y":37}}, {"id":261, "num":1,"point":{"x":25,"y":42}}] | C24: [{"id": | D24: 206 | E24: ,"num": | F24: 6 | G24: ,"point":{"x":15,"y":35}}, {"id": | H24: =D24 -> 206 | I24: , "num": | J24: 6 | K24: ,"point":{"x":26,"y":39}}, {"id": | L24: 231 | M24: , "num": | N24: 7 | O24: ,"point":{"x":36,"y":37}}, {"id": | P24: 261 | Q24: , "num": | R24: =IF(R14=0,"",R14) -> 1 | S24: ,"point":{"x":25,"y":42}}]
A25: 1408031 | B25: =CONCATENATE(C25,D25,E25,F25,G25,H25,I25,J25,K25,L25,M25,N25,O25,P25,Q25,R25,S25) -> [{"id":204,"num":2,"point":{"x":24,"y":37}}, {"id":204, "num":2,"point":{"x":15,"y":35}}, {"id":232, "num":3,"point":{"x":33,"y":33}}] | C25: [{"id": | D25: 204 | E25: ,"num": | F25: =F15 -> 2 | G25: =G15 -> ,"point":{"x":24,"y":37}}, {"id": | H25: =D25 -> 204 | I25: , "num": | J25: =J15 -> 2 | K25: =K15 -> ,"point":{"x":15,"y":35}}, {"id": | L25: =L15+1 -> 232 | M25: , "num": | N25: =N15 -> 3 | O25: =O15 -> ,"point":{"x":33,"y":33}}] | P25: =IF(P15=0,"",P15) | Q25: =IF(Q15=0,"",Q15) | R25: =IF(R15=0,"",R15) | S25: =IF(S15=0,"",S15)
A26: 1408032 | B26: =CONCATENATE(C26,D26,E26,F26,G26,H26,I26,J26,K26,L26,M26,N26,O26,P26,Q26,R26,S26) -> [{"id":204,"num":3,"point":{"x":24,"y":37}}, {"id":204, "num":2,"point":{"x":15,"y":35}}, {"id":232, "num":3,"point":{"x":33,"y":33}}] | C26: [{"id": | D26: 204 | E26: ,"num": | F26: =F16 -> 3 | G26: =G16 -> ,"point":{"x":24,"y":37}}, {"id": | H26: =D26 -> 204 | I26: , "num": | J26: =J16 -> 2 | K26: =K16 -> ,"point":{"x":15,"y":35}}, {"id": | L26: =L16+1 -> 232 | M26: , "num": | N26: =N16 -> 3 | O26: =O16 -> ,"point":{"x":33,"y":33}}] | Q26: =IF(Q16=0,"",Q16) | R26: =IF(R16=0,"",R16) | S26: =IF(S16=0,"",S16)
A27: 1408033 | B27: =CONCATENATE(C27,D27,E27,F27,G27,H27,I27,J27,K27,L27,M27,N27,O27,P27,Q27,R27,S27) -> [{"id":205,"num":3,"point":{"x":16,"y":38}}, {"id":205, "num":3,"point":{"x":35,"y":35}}, {"id":232, "num":4,"point":{"x":23,"y":12}}] | C27: [{"id": | D27: 205 | E27: ,"num": | F27: =F17 -> 3 | G27: =G17 -> ,"point":{"x":16,"y":38}}, {"id": | H27: =D27 -> 205 | I27: , "num": | J27: =J17 -> 3 | K27: =K17 -> ,"point":{"x":35,"y":35}}, {"id": | L27: =L17+1 -> 232 | M27: , "num": | N27: =N17 -> 4 | O27: =O17 -> ,"point":{"x":23,"y":12}}] | Q27: =IF(Q17=0,"",Q17) | R27: =IF(R17=0,"",R17) | S27: =IF(S17=0,"",S17)
A28: 1408034 | B28: =CONCATENATE(C28,D28,E28,F28,G28,H28,I28,J28,K28,L28,M28,N28,O28,P28,Q28,R28,S28) -> [{"id":205,"num":4,"point":{"x":16,"y":38}}, {"id":205, "num":3,"point":{"x":35,"y":35}}, {"id":232, "num":4,"point":{"x":23,"y":12}}] | C28: [{"id": | D28: 205 | E28: ,"num": | F28: =F18 -> 4 | G28: =G18 -> ,"point":{"x":16,"y":38}}, {"id": | H28: =D28 -> 205 | I28: , "num": | J28: =J18 -> 3 | K28: =K18 -> ,"point":{"x":35,"y":35}}, {"id": | L28: =L18+1 -> 232 | M28: , "num": | N28: =N18 -> 4 | O28: =O18 -> ,"point":{"x":23,"y":12}}] | Q28: =IF(Q18=0,"",Q18) | R28: =IF(R18=0,"",R18) | S28: =IF(S18=0,"",S18)
A29: 1408035 | B29: =CONCATENATE(C29,D29,E29,F29,G29,H29,I29,J29,K29,L29,M29,N29,O29,P29,Q29,R29,S29) -> [{"id":206,"num":4,"point":{"x":16,"y":20}}, {"id":206, "num":4,"point":{"x":25,"y":37}}, {"id":232, "num":5,"point":{"x":33,"y":16}}] | C29: [{"id": | D29: 206 | E29: ,"num": | F29: =F19 -> 4 | G29: =G19 -> ,"point":{"x":16,"y":20}}, {"id": | H29: =D29 -> 206 | I29: , "num": | J29: =J19 -> 4 | K29: =K19 -> ,"point":{"x":25,"y":37}}, {"id": | L29: =L19+1 -> 232 | M29: , "num": | N29: =N19 -> 5 | O29: =O19 -> ,"point":{"x":33,"y":16}}] | Q29: =IF(Q19=0,"",Q19) | R29: =IF(R19=0,"",R19) | S29: =IF(S19=0,"",S19)
A30: 1408036 | B30: =CONCATENATE(C30,D30,E30,F30,G30,H30,I30,J30,K30,L30,M30,N30,O30,P30,Q30,R30,S30) -> [{"id":206,"num":5,"point":{"x":16,"y":20}}, {"id":206, "num":4,"point":{"x":25,"y":37}}, {"id":232, "num":5,"point":{"x":33,"y":16}}] | C30: [{"id": | D30: 206 | E30: ,"num": | F30: =F20 -> 5 | G30: =G20 -> ,"point":{"x":16,"y":20}}, {"id": | H30: =D30 -> 206 | I30: , "num": | J30: =J20 -> 4 | K30: =K20 -> ,"point":{"x":25,"y":37}}, {"id": | L30: =L20+1 -> 232 | M30: , "num": | N30: =N20 -> 5 | O30: =O20 -> ,"point":{"x":33,"y":16}}] | Q30: =IF(Q20=0,"",Q20) | R30: =IF(R20=0,"",R20) | S30: =IF(S20=0,"",S20)
A31: 1408037 | B31: =CONCATENATE(C31,D31,E31,F31,G31,H31,I31,J31,K31,L31,M31,N31,O31,P31,Q31,R31,S31) -> [{"id":207,"num":5,"point":{"x":25,"y":35}}, {"id":207, "num":5,"point":{"x":33,"y":33}}, {"id":232, "num":6,"point":{"x":20,"y":18}}] | C31: [{"id": | D31: 207 | E31: ,"num": | F31: =F21 -> 5 | G31: =G21 -> ,"point":{"x":25,"y":35}}, {"id": | H31: =D31 -> 207 | I31: , "num": | J31: =J21 -> 5 | K31: =K21 -> ,"point":{"x":33,"y":33}}, {"id": | L31: =L21+1 -> 232 | M31: , "num": | N31: 6 | O31: =O21 -> ,"point":{"x":20,"y":18}}] | Q31: =IF(Q21=0,"",Q21) | R31: =IF(R21=0,"",R21) | S31: =IF(S21=0,"",S21)
A32: 1408038 | B32: =CONCATENATE(C32,D32,E32,F32,G32,H32,I32,J32,K32,L32,M32,N32,O32,P32,Q32,R32,S32) -> [{"id":207,"num":6,"point":{"x":25,"y":35}}, {"id":207, "num":5,"point":{"x":33,"y":33}}, {"id":232, "num":6,"point":{"x":20,"y":18}}] | C32: [{"id": | D32: 207 | E32: ,"num": | F32: =F22 -> 6 | G32: =G22 -> ,"point":{"x":25,"y":35}}, {"id": | H32: =D32 -> 207 | I32: , "num": | J32: =J22 -> 5 | K32: =K22 -> ,"point":{"x":33,"y":33}}, {"id": | L32: =L22+1 -> 232 | M32: , "num": | N32: =N22 -> 6 | O32: =O22 -> ,"point":{"x":20,"y":18}}] | Q32: =IF(Q22=0,"",Q22) | R32: =IF(R22=0,"",R22) | S32: =IF(S22=0,"",S22)
A33: 1408039 | B33: =CONCATENATE(C33,D33,E33,F33,G33,H33,I33,J33,K33,L33,M33,N33,O33,P33,Q33,R33,S33) -> [{"id":208,"num":6,"point":{"x":15,"y":35}}, {"id":208, "num":6,"point":{"x":26,"y":39}}, {"id":232, "num":7,"point":{"x":36,"y":37}}] | C33: [{"id": | D33: 208 | E33: ,"num": | F33: =F23 -> 6 | G33: =G23 -> ,"point":{"x":15,"y":35}}, {"id": | H33: =D33 -> 208 | I33: , "num": | J33: =J23 -> 6 | K33: =K23 -> ,"point":{"x":26,"y":39}}, {"id": | L33: =L23+1 -> 232 | M33: , "num": | N33: 7 | O33: =O23 -> ,"point":{"x":36,"y":37}}] | Q33: =IF(Q23=0,"",Q23) | R33: =IF(R23=0,"",R23) | S33: =IF(S23=0,"",S23)
A34: 1408040 | B34: =CONCATENATE(C34,D34,E34,F34,G34,H34,I34,J34,K34,L34,M34,N34,O34,P34,Q34,R34,S34) -> [{"id":209,"num":6,"point":{"x":15,"y":35}}, {"id":209, "num":6,"point":{"x":26,"y":39}}, {"id":232, "num":7,"point":{"x":36,"y":37}}, {"id":262, "num":1,"point":{"x":25,"y":42}}] | C34: [{"id": | D34: 209 | E34: ,"num": | F34: =F24 -> 6 | G34: =G24 -> ,"point":{"x":15,"y":35}}, {"id": | H34: =D34 -> 209 | I34: , "num": | J34: =J24 -> 6 | K34: =K24 -> ,"point":{"x":26,"y":39}}, {"id": | L34: =L24+1 -> 232 | M34: , "num": | N34: =N24 -> 7 | O34: =O24 -> ,"point":{"x":36,"y":37}}, {"id": | P34: 262 | Q34: =IF(Q24=0,"",Q24) -> , "num": | R34: =IF(R24=0,"",R24) -> 1 | S34: =IF(S24=0,"",S24) -> ,"point":{"x":25,"y":42}}]
A35: 1409001 | B35: =CONCATENATE(C35,D35,E35,F35,G35,H35,I35,J35,K35,L35,M35,N35,O35,P35,Q35,R35,S35) -> [{"id":207,"num":2,"point":{"x":24,"y":37}}, {"id":207, "num":2,"point":{"x":15,"y":35}}, {"id":233, "num":3,"point":{"x":33,"y":33}}] | C35: [{"id": | D35: =D34-2 -> 207 | E35: ,"num": | F35: =F25 -> 2 | G35: =G25 -> ,"point":{"x":24,"y":37}}, {"id": | H35: =D35 -> 207 | I35: , "num": | J35: =J25 -> 2 | K35: =K25 -> ,"point":{"x":15,"y":35}}, {"id": | L35: =L25+1 -> 233 | M35: , "num": | N35: =N25 -> 3 | O35: =O25 -> ,"point":{"x":33,"y":33}}] | Q35: =IF(Q25=0,"",Q25) | R35: =IF(R25=0,"",R25) | S35: =IF(S25=0,"",S25)
A36: 1409002 | B36: =CONCATENATE(C36,D36,E36,F36,G36,H36,I36,J36,K36,L36,M36,N36,O36,P36,Q36,R36,S36) -> [{"id":207,"num":3,"point":{"x":24,"y":37}}, {"id":207, "num":2,"point":{"x":15,"y":35}}, {"id":233, "num":3,"point":{"x":33,"y":33}}] | C36: [{"id": | D36: =D34-2 -> 207 | E36: ,"num": | F36: =F26 -> 3 | G36: =G26 -> ,"point":{"x":24,"y":37}}, {"id": | H36: =D36 -> 207 | I36: , "num": | J36: =J26 -> 2 | K36: =K26 -> ,"point":{"x":15,"y":35}}, {"id": | L36: =L26+1 -> 233 | M36: , "num": | N36: =N26 -> 3 | O36: =O26 -> ,"point":{"x":33,"y":33}}] | Q36: =IF(Q26=0,"",Q26) | R36: =IF(R26=0,"",R26) | S36: =IF(S26=0,"",S26)
A37: 1409003 | B37: =CONCATENATE(C37,D37,E37,F37,G37,H37,I37,J37,K37,L37,M37,N37,O37,P37,Q37,R37,S37) -> [{"id":208,"num":3,"point":{"x":16,"y":38}}, {"id":208, "num":3,"point":{"x":35,"y":35}}, {"id":233, "num":4,"point":{"x":23,"y":12}}] | C37: [{"id": | D37: =D34-1 -> 208 | E37: ,"num": | F37: =F27 -> 3 | G37: =G27 -> ,"point":{"x":16,"y":38}}, {"id": | H37: =D37 -> 208 | I37: , "num": | J37: =J27 -> 3 | K37: =K27 -> ,"point":{"x":35,"y":35}}, {"id": | L37: =L27+1 -> 233 | M37: , "num": | N37: =N27 -> 4 | O37: =O27 -> ,"point":{"x":23,"y":12}}] | Q37: =IF(Q27=0,"",Q27) | R37: =IF(R27=0,"",R27) | S37: =IF(S27=0,"",S27)
