Workbook

Sheet Sheet1
A1: 唯一ID | B1: 职业 | C1: 强化等级 | D1: 道具消耗 | E1: 属性加成
A2: int32 | B2: int32 | C2: int32 | D2: json | E2: json
A3: UUID | B3: Job | C3: Strengthenlevel | D3: Consume | E3: Attribute
A4: =B4*1000+C4 -> 1000 | B4: 1 | C4: 0 | D4: =消耗配置!G2 -> [{"id":21,"num":10},{"id":1,"num":1000}]
A5: =B5*1000+C5 -> 1001 | B5: 1 | C5: 1 | D5: =消耗配置!G3 -> [{"id":21,"num":20},{"id":1,"num":2000}] | E5: =属性配置!G2&属性配置!L2&属性配置!Q2&属性配置!V2&属性配置!AA2&属性配置!AF2&属性配置!AK2&属性配置!AP2&属性配置!AU2&属性配置!AZ2&属性配置!BE2&属性配置!BJ2 -> [{"slot":1,"attribute":1,"value":2},{"slot":2,"attribute":4,"value":3},{"slot":3,"attribute":5,"value":2},{"slot":4,"attribute":1,"value":1},{"slot":5,"attribute":1,"value":1},{"slot":6,"attribute":1,"value":1},{"slot":7,"attribute":1,"value":1},{"slot":8,"attribute":1,"value":1},{"slot":9,"attribute":4,"value":1},{"slot":10,"attribute":5,"value":3},{"slot":11,"attribute":12,"value":44},{"slot":12,"attribute":12,"value":44}]
A6: =B6*1000+C6 -> 1002 | B6: 1 | C6: 2 | D6: =消耗配置!G4 -> [{"id":21,"num":30},{"id":1,"num":3000}] | E6: =属性配置!G3&属性配置!L3&属性配置!Q3&属性配置!V3&属性配置!AA3&属性配置!AF3&属性配置!AK3&属性配置!AP3&属性配置!AU3&属性配置!AZ3&属性配置!BE3&属性配置!BJ3 -> [{"slot":1,"attribute":1,"value":4},{"slot":2,"attribute":4,"value":7},{"slot":3,"attribute":5,"value":4},{"slot":4,"attribute":1,"value":3},{"slot":5,"attribute":1,"value":2},{"slot":6,"attribute":1,"value":2},{"slot":7,"attribute":1,"value":2},{"slot":8,"attribute":1,"value":2},{"slot":9,"attribute":4,"value":3},{"slot":10,"attribute":5,"value":6},{"slot":11,"attribute":12,"value":89},{"slot":12,"attribute":12,"value":89}]
A7: =B7*1000+C7 -> 1003 | B7: 1 | C7: 3 | D7: =消耗配置!G5 -> [{"id":21,"num":40},{"id":1,"num":4000}] | E7: =属性配置!G4&属性配置!L4&属性配置!Q4&属性配置!V4&属性配置!AA4&属性配置!AF4&属性配置!AK4&属性配置!AP4&属性配置!AU4&属性配置!AZ4&属性配置!BE4&属性配置!BJ4 -> [{"slot":1,"attribute":1,"value":6},{"slot":2,"attribute":4,"value":10},{"slot":3,"attribute":5,"value":6},{"slot":4,"attribute":1,"value":4},{"slot":5,"attribute":1,"value":3},{"slot":6,"attribute":1,"value":3},{"slot":7,"attribute":1,"value":3},{"slot":8,"attribute":1,"value":3},{"slot":9,"attribute":4,"value":4},{"slot":10,"attribute":5,"value":9},{"slot":11,"attribute":12,"value":133},{"slot":12,"attribute":12,"value":133}]
A8: =B8*1000+C8 -> 1004 | B8: 1 | C8: 4 | D8: =消耗配置!G6 -> [{"id":21,"num":50},{"id":1,"num":5000}] | E8: =属性配置!G5&属性配置!L5&属性配置!Q5&属性配置!V5&属性配置!AA5&属性配置!AF5&属性配置!AK5&属性配置!AP5&属性配置!AU5&属性配置!AZ5&属性配置!BE5&属性配置!BJ5 -> [{"slot":1,"attribute":1,"value":8},{"slot":2,"attribute":4,"value":14},{"slot":3,"attribute":5,"value":8},{"slot":4,"attribute":1,"value":6},{"slot":5,"attribute":1,"value":4},{"slot":6,"attribute":1,"value":4},{"slot":7,"attribute":1,"value":4},{"slot":8,"attribute":1,"value":4},{"slot":9,"attribute":4,"value":6},{"slot":10,"attribute":5,"value":12},{"slot":11,"attribute":12,"value":178},{"slot":12,"attribute":12,"value":178}]
A9: =B9*1000+C9 -> 1005 | B9: 1 | C9: 5 | D9: =消耗配置!G7 -> [{"id":21,"num":60},{"id":1,"num":6000}] | E9: =属性配置!G6&属性配置!L6&属性配置!Q6&属性配置!V6&属性配置!AA6&属性配置!AF6&属性配置!AK6&属性配置!AP6&属性配置!AU6&属性配置!AZ6&属性配置!BE6&属性配置!BJ6 -> [{"slot":1,"attribute":1,"value":10},{"slot":2,"attribute":4,"value":17},{"slot":3,"attribute":5,"value":10},{"slot":4,"attribute":1,"value":7},{"slot":5,"attribute":1,"value":5},{"slot":6,"attribute":1,"value":5},{"slot":7,"attribute":1,"value":5},{"slot":8,"attribute":1,"value":5},{"slot":9,"attribute":4,"value":7},{"slot":10,"attribute":5,"value":15},{"slot":11,"attribute":12,"value":222},{"slot":12,"attribute":12,"value":222}]
A10: =B10*1000+C10 -> 1006 | B10: 1 | C10: 6 | D10: =消耗配置!G8 -> [{"id":21,"num":70},{"id":1,"num":7000}] | E10: =属性配置!G7&属性配置!L7&属性配置!Q7&属性配置!V7&属性配置!AA7&属性配置!AF7&属性配置!AK7&属性配置!AP7&属性配置!AU7&属性配置!AZ7&属性配置!BE7&属性配置!BJ7 -> [{"slot":1,"attribute":1,"value":12},{"slot":2,"attribute":4,"value":21},{"slot":3,"attribute":5,"value":12},{"slot":4,"attribute":1,"value":8},{"slot":5,"attribute":1,"value":6},{"slot":6,"attribute":1,"value":6},{"slot":7,"attribute":1,"value":6},{"slot":8,"attribute":1,"value":6},{"slot":9,"attribute":4,"value":9},{"slot":10,"attribute":5,"value":18},{"slot":11,"attribute":12,"value":266},{"slot":12,"attribute":12,"value":266}]
A11: =B11*1000+C11 -> 1007 | B11: 1 | C11: 7 | D11: =消耗配置!G9 -> [{"id":21,"num":80},{"id":1,"num":8000}] | E11: =属性配置!G8&属性配置!L8&属性配置!Q8&属性配置!V8&属性配置!AA8&属性配置!AF8&属性配置!AK8&属性配置!AP8&属性配置!AU8&属性配置!AZ8&属性配置!BE8&属性配置!BJ8 -> [{"slot":1,"attribute":1,"value":14},{"slot":2,"attribute":4,"value":24},{"slot":3,"attribute":5,"value":14},{"slot":4,"attribute":1,"value":10},{"slot":5,"attribute":1,"value":7},{"slot":6,"attribute":1,"value":7},{"slot":7,"attribute":1,"value":7},{"slot":8,"attribute":1,"value":7},{"slot":9,"attribute":4,"value":10},{"slot":10,"attribute":5,"value":21},{"slot":11,"attribute":12,"value":311},{"slot":12,"attribute":12,"value":311}]
A12: =B12*1000+C12 -> 1008 | B12: 1 | C12: 8 | D12: =消耗配置!G10 -> [{"id":21,"num":90},{"id":1,"num":9000}] | E12: =属性配置!G9&属性配置!L9&属性配置!Q9&属性配置!V9&属性配置!AA9&属性配置!AF9&属性配置!AK9&属性配置!AP9&属性配置!AU9&属性配置!AZ9&属性配置!BE9&属性配置!BJ9 -> [{"slot":1,"attribute":1,"value":16},{"slot":2,"attribute":4,"value":28},{"slot":3,"attribute":5,"value":16},{"slot":4,"attribute":1,"value":11},{"slot":5,"attribute":1,"value":8},{"slot":6,"attribute":1,"value":8},{"slot":7,"attribute":1,"value":8},{"slot":8,"attribute":1,"value":8},{"slot":9,"attribute":4,"value":12},{"slot":10,"attribute":5,"value":24},{"slot":11,"attribute":12,"value":355},{"slot":12,"attribute":12,"value":355}]
A13: =B13*1000+C13 -> 1009 | B13: 1 | C13: 9 | D13: =消耗配置!G11 -> [{"id":21,"num":100},{"id":1,"num":10000}] | E13: =属性配置!G10&属性配置!L10&属性配置!Q10&属性配置!V10&属性配置!AA10&属性配置!AF10&属性配置!AK10&属性配置!AP10&属性配置!AU10&属性配置!AZ10&属性配置!BE10&属性配置!BJ10 -> [{"slot":1,"attribute":1,"value":18},{"slot":2,"attribute":4,"value":31},{"slot":3,"attribute":5,"value":18},{"slot":4,"attribute":1,"value":13},{"slot":5,"attribute":1,"value":9},{"slot":6,"attribute":1,"value":9},{"slot":7,"attribute":1,"value":9},{"slot":8,"attribute":1,"value":9},{"slot":9,"attribute":4,"value":13},{"slot":10,"attribute":5,"value":27},{"slot":11,"attribute":12,"value":400},{"slot":12,"attribute":12,"value":400}]
A14: =B14*1000+C14 -> 1010 | B14: 1 | C14: 10 | D14: =消耗配置!G12 -> [{"id":21,"num":110},{"id":1,"num":11000}] | E14: =属性配置!G11&属性配置!L11&属性配置!Q11&属性配置!V11&属性配置!AA11&属性配置!AF11&属性配置!AK11&属性配置!AP11&属性配置!AU11&属性配置!AZ11&属性配置!BE11&属性配置!BJ11 -> [{"slot":1,"attribute":1,"value":20},{"slot":2,"attribute":4,"value":35},{"slot":3,"attribute":5,"value":20},{"slot":4,"attribute":1,"value":14},{"slot":5,"attribute":1,"value":10},{"slot":6,"attribute":1,"value":10},{"slot":7,"attribute":1,"value":10},{"slot":8,"attribute":1,"value":10},{"slot":9,"attribute":4,"value":15},{"slot":10,"attribute":5,"value":30},{"slot":11,"attribute":12,"value":444},{"slot":12,"attribute":12,"value":444}]
A15: =B15*1000+C15 -> 1011 | B15: 1 | C15: 11 | D15: =消耗配置!G13 -> [{"id":21,"num":120},{"id":1,"num":12000}] | E15: =属性配置!G12&属性配置!L12&属性配置!Q12&属性配置!V12&属性配置!AA12&属性配置!AF12&属性配置!AK12&属性配置!AP12&属性配置!AU12&属性配置!AZ12&属性配置!BE12&属性配置!BJ12 -> [{"slot":1,"attribute":1,"value":22},{"slot":2,"attribute":4,"value":38},{"slot":3,"attribute":5,"value":22},{"slot":4,"attribute":1,"value":15},{"slot":5,"attribute":1,"value":11},{"slot":6,"attribute":1,"value":11},{"slot":7,"attribute":1,"value":11},{"slot":8,"attribute":1,"value":11},{"slot":9,"attribute":4,"value":16},{"slot":10,"attribute":5,"value":33},{"slot":11,"attribute":12,"value":488},{"slot":12,"attribute":12,"value":488}]
A16: =B16*1000+C16 -> 1012 | B16: 1 | C16: 12 | D16: =消耗配置!G14 -> [{"id":21,"num":130},{"id":1,"num":13000}] | E16: =属性配置!G13&属性配置!L13&属性配置!Q13&属性配置!V13&属性配置!AA13&属性配置!AF13&属性配置!AK13&属性配置!AP13&属性配置!AU13&属性配置!AZ13&属性配置!BE13&属性配置!BJ13 -> [{"slot":1,"attribute":1,"value":24},{"slot":2,"attribute":4,"value":41},{"slot":3,"attribute":5,"value":24},{"slot":4,"attribute":1,"value":17},{"slot":5,"attribute":1,"value":12},{"slot":6,"attribute":1,"value":12},{"slot":7,"attribute":1,"value":12},{"slot":8,"attribute":1,"value":12},{"slot":9,"attribute":4,"value":18},{"slot":10,"attribute":5,"value":36},{"slot":11,"attribute":12,"value":533},{"slot":12,"attribute":12,"value":533}]
... A305: =B305*1000+C305 -> 1301 | B305: 1 | C305: 301 | D305: =消耗配置!G303 -> [{"id":21,"num":3020},{"id":1,"num":302000}] | E305: =属性配置!G302&属性配置!L302&属性配置!Q302&属性配置!V302&属性配置!AA302&属性配置!AF302&属性配置!AK302&属性配置!AP302&属性配置!AU302&属性配置!AZ302&属性配置!BE302&属性配置!BJ302 -> [{"slot":1,"attribute":1,"value":602},{"slot":2,"attribute":4,"value":1039},{"slot":3,"attribute":5,"value":594},{"slot":4,"attribute":1,"value":421},{"slot":5,"attribute":1,"value":301},{"slot":6,"attribute":1,"value":301},{"slot":7,"attribute":1,"value":301},{"slot":8,"attribute":1,"value":301},{"slot":9,"attribute":4,"value":445},{"slot":10,"attribute":5,"value":891},{"slot":11,"attribute":12,"value":13364},{"slot":12,"attribute":12,"value":13364}]
A306: =B306*1000+C306 -> 2000 | B306: 2 | C306: 0 | D306: =消耗配置!G2 -> [{"id":21,"num":10},{"id":1,"num":1000}]
A307: =B307*1000+C307 -> 2001 | B307: 2 | C307: 1 | D307: =消耗配置!G3 -> [{"id":21,"num":20},{"id":1,"num":2000}] | E307: =属性配置!G303&属性配置!L303&属性配置!Q303&属性配置!V303&属性配置!AA303&属性配置!AF303&属性配置!AK303&属性配置!AP303&属性配置!AU303&属性配置!AZ303&属性配置!BE303&属性配置!BJ303 -> [{"slot":1,"attribute":2,"value":2},{"slot":2,"attribute":4,"value":3},{"slot":3,"attribute":5,"value":2},{"slot":4,"attribute":2,"value":1},{"slot":5,"attribute":2,"value":1},{"slot":6,"attribute":2,"value":1},{"slot":7,"attribute":2,"value":1},{"slot":8,"attribute":2,"value":1},{"slot":9,"attribute":4,"value":1},{"slot":10,"attribute":5,"value":3},{"slot":11,"attribute":12,"value":15},{"slot":12,"attribute":12,"value":15}]
A308: =B308*1000+C308 -> 2002 | B308: 2 | C308: 2 | D308: =消耗配置!G4 -> [{"id":21,"num":30},{"id":1,"num":3000}] | E308: =属性配置!G304&属性配置!L304&属性配置!Q304&属性配置!V304&属性配置!AA304&属性配置!AF304&属性配置!AK304&属性配置!AP304&属性配置!AU304&属性配置!AZ304&属性配置!BE304&属性配置!BJ304 -> [{"slot":1,"attribute":2,"value":3},{"slot":2,"attribute":4,"value":7},{"slot":3,"attribute":5,"value":4},{"slot":4,"attribute":2,"value":2},{"slot":5,"attribute":2,"value":2},{"slot":6,"attribute":2,"value":2},{"slot":7,"attribute":2,"value":2},{"slot":8,"attribute":2,"value":2},{"slot":9,"attribute":4,"value":3},{"slot":10,"attribute":5,"value":6},{"slot":11,"attribute":12,"value":30},{"slot":12,"attribute":12,"value":30}]
A309: =B309*1000+C309 -> 2003 | B309: 2 | C309: 3 | D309: =消耗配置!G5 -> [{"id":21,"num":40},{"id":1,"num":4000}] | E309: =属性配置!G305&属性配置!L305&属性配置!Q305&属性配置!V305&属性配置!AA305&属性配置!AF305&属性配置!AK305&属性配置!AP305&属性配置!AU305&属性配置!AZ305&属性配置!BE305&属性配置!BJ305 -> [{"slot":1,"attribute":2,"value":5},{"slot":2,"attribute":4,"value":10},{"slot":3,"attribute":5,"value":6},{"slot":4,"attribute":2,"value":3},{"slot":5,"attribute":2,"value":2},{"slot":6,"attribute":2,"value":2},{"slot":7,"attribute":2,"value":2},{"slot":8,"attribute":2,"value":2},{"slot":9,"attribute":4,"value":4},{"slot":10,"attribute":5,"value":9},{"slot":11,"attribute":12,"value":44},{"slot":12,"attribute":12,"value":44}]
A310: =B310*1000+C310 -> 2004 | B310: 2 | C310: 4 | D310: =消耗配置!G6 -> [{"id":21,"num":50},{"id":1,"num":5000}] | E310: =属性配置!G306&属性配置!L306&属性配置!Q306&属性配置!V306&属性配置!AA306&属性配置!AF306&属性配置!AK306&属性配置!AP306&属性配置!AU306&属性配置!AZ306&属性配置!BE306&属性配置!BJ306 -> [{"slot":1,"attribute":2,"value":7},{"slot":2,"attribute":4,"value":14},{"slot":3,"attribute":5,"value":8},{"slot":4,"attribute":2,"value":5},{"slot":5,"attribute":2,"value":3},{"slot":6,"attribute":2,"value":3},{"slot":7,"attribute":2,"value":3},{"slot":8,"attribute":2,"value":3},{"slot":9,"attribute":4,"value":6},{"slot":10,"attribute":5,"value":12},{"slot":11,"attribute":12,"value":59},{"slot":12,"attribute":12,"value":59}]
A311: =B311*1000+C311 -> 2005 | B311: 2 | C311: 5 | D311: =消耗配置!G7 -> [{"id":21,"num":60},{"id":1,"num":6000}] | E311: =属性配置!G307&属性配置!L307&属性配置!Q307&属性配置!V307&属性配置!AA307&属性配置!AF307&属性配置!AK307&属性配置!AP307&属性配置!AU307&属性配置!AZ307&属性配置!BE307&属性配置!BJ307 -> [{"slot":1,"attribute":2,"value":8},{"slot":2,"attribute":4,"value":17},{"slot":3,"attribute":5,"value":10},{"slot":4,"attribute":2,"value":6},{"slot":5,"attribute":2,"value":4},{"slot":6,"attribute":2,"value":4},{"slot":7,"attribute":2,"value":4},{"slot":8,"attribute":2,"value":4},{"slot":9,"attribute":4,"value":7},{"slot":10,"attribute":5,"value":15},{"slot":11,"attribute":12,"value":74},{"slot":12,"attribute":12,"value":74}]
A312: =B312*1000+C312 -> 2006 | B312: 2 | C312: 6 | D312: =消耗配置!G8 -> [{"id":21,"num":70},{"id":1,"num":7000}] | E312: =属性配置!G308&属性配置!L308&属性配置!Q308&属性配置!V308&属性配置!AA308&属性配置!AF308&属性配置!AK308&属性配置!AP308&属性配置!AU308&属性配置!AZ308&属性配置!BE308&属性配置!BJ308 -> [{"slot":1,"attribute":2,"value":10},{"slot":2,"attribute":4,"value":21},{"slot":3,"attribute":5,"value":12},{"slot":4,"attribute":2,"value":7},{"slot":5,"attribute":2,"value":5},{"slot":6,"attribute":2,"value":5},{"slot":7,"attribute":2,"value":5},{"slot":8,"attribute":2,"value":5},{"slot":9,"attribute":4,"value":9},{"slot":10,"attribute":5,"value":18},{"slot":11,"attribute":12,"value":89},{"slot":12,"attribute":12,"value":89}]
A313: =B313*1000+C313 -> 2007 | B313: 2 | C313: 7 | D313: =消耗配置!G9 -> [{"id":21,"num":80},{"id":1,"num":8000}] | E313: =属性配置!G309&属性配置!L309&属性配置!Q309&属性配置!V309&属性配置!AA309&属性配置!AF309&属性配置!AK309&属性配置!AP309&属性配置!AU309&属性配置!AZ309&属性配置!BE309&属性配置!BJ309 -> [{"slot":1,"attribute":2,"value":11},{"slot":2,"attribute":4,"value":24},{"slot":3,"attribute":5,"value":14},{"slot":4,"attribute":2,"value":8},{"slot":5,"attribute":2,"value":6},{"slot":6,"attribute":2,"value":6},{"slot":7,"attribute":2,"value":6},{"slot":8,"attribute":2,"value":6},{"slot":9,"attribute":4,"value":10},{"slot":10,"attribute":5,"value":21},{"slot":11,"attribute":12,"value":104},{"slot":12,"attribute":12,"value":104}]
A314: =B314*1000+C314 -> 2008 | B314: 2 | C314: 8 | D314: =消耗配置!G10 -> [{"id":21,"num":90},{"id":1,"num":9000}] | E314: =属性配置!G310&属性配置!L310&属性配置!Q310&属性配置!V310&属性配置!AA310&属性配置!AF310&属性配置!AK310&属性配置!AP310&属性配置!AU310&属性配置!AZ310&属性配置!BE310&属性配置!BJ310 -> [{"slot":1,"attribute":2,"value":13},{"slot":2,"attribute":4,"value":28},{"slot":3,"attribute":5,"value":16},{"slot":4,"attribute":2,"value":9},{"slot":5,"attribute":2,"value":7},{"slot":6,"attribute":2,"value":7},{"slot":7,"attribute":2,"value":7},{"slot":8,"attribute":2,"value":7},{"slot":9,"attribute":4,"value":12},{"slot":10,"attribute":5,"value":24},{"slot":11,"attribute":12,"value":118},{"slot":12,"attribute":12,"value":118}]
A315: =B315*1000+C315 -> 2009 | B315: 2 | C315: 9 | D315: =消耗配置!G11 -> [{"id":21,"num":100},{"id":1,"num":10000}] | E315: =属性配置!G311&属性配置!L311&属性配置!Q311&属性配置!V311&属性配置!AA311&属性配置!AF311&属性配置!AK311&属性配置!AP311&属性配置!AU311&属性配置!AZ311&属性配置!BE311&属性配置!BJ311 -> [{"slot":1,"attribute":2,"value":15},{"slot":2,"attribute":4,"value":31},{"slot":3,"attribute":5,"value":18},{"slot":4,"attribute":2,"value":11},{"slot":5,"attribute":2,"value":7},{"slot":6,"attribute":2,"value":7},{"slot":7,"attribute":2,"value":7},{"slot":8,"attribute":2,"value":7},{"slot":9,"attribute":4,"value":13},{"slot":10,"attribute":5,"value":27},{"slot":11,"attribute":12,"value":133},{"slot":12,"attribute":12,"value":133}]
A316: =B316*1000+C316 -> 2010 | B316: 2 | C316: 10 | D316: =消耗配置!G12 -> [{"id":21,"num":110},{"id":1,"num":11000}] | E316: =属性配置!G312&属性配置!L312&属性配置!Q312&属性配置!V312&属性配置!AA312&属性配置!AF312&属性配置!AK312&属性配置!AP312&属性配置!AU312&属性配置!AZ312&属性配置!BE312&属性配置!BJ312 -> [{"slot":1,"attribute":2,"value":16},{"slot":2,"attribute":4,"value":35},{"slot":3,"attribute":5,"value":20},{"slot":4,"attribute":2,"value":11},{"slot":5,"attribute":2,"value":8},{"slot":6,"attribute":2,"value":8},{"slot":7,"attribute":2,"value":8},{"slot":8,"attribute":2,"value":8},{"slot":9,"attribute":4,"value":15},{"slot":10,"attribute":5,"value":30},{"slot":11,"attribute":12,"value":148},{"slot":12,"attribute":12,"value":148}]
A317: =B317*1000+C317 -> 2011 | B317: 2 | C317: 11 | D317: =消耗配置!G13 -> [{"id":21,"num":120},{"id":1,"num":12000}] | E317: =属性配置!G313&属性配置!L313&属性配置!Q313&属性配置!V313&属性配置!AA313&属性配置!AF313&属性配置!AK313&属性配置!AP313&属性配置!AU313&属性配置!AZ313&属性配置!BE313&属性配置!BJ313 -> [{"slot":1,"attribute":2,"value":18},{"slot":2,"attribute":4,"value":38},{"slot":3,"attribute":5,"value":22},{"slot":4,"attribute":2,"value":12},{"slot":5,"attribute":2,"value":9},{"slot":6,"attribute":2,"value":9},{"slot":7,"attribute":2,"value":9},{"slot":8,"attribute":2,"value":9},{"slot":9,"attribute":4,"value":16},{"slot":10,"attribute":5,"value":33},{"slot":11,"attribute":12,"value":163},{"slot":12,"attribute":12,"value":163}]
A318: =B318*1000+C318 -> 2012 | B318: 2 | C318: 12 | D318: =消耗配置!G14 -> [{"id":21,"num":130},{"id":1,"num":13000}] | E318: =属性配置!G314&属性配置!L314&属性配置!Q314&属性配置!V314&属性配置!AA314&属性配置!AF314&属性配置!AK314&属性配置!AP314&属性配置!AU314&属性配置!AZ314&属性配置!BE314&属性配置!BJ314 -> [{"slot":1,"attribute":2,"value":20},{"slot":2,"attribute":4,"value":41},{"slot":3,"attribute":5,"value":24},{"slot":4,"attribute":2,"value":14},{"slot":5,"attribute":2,"value":10},{"slot":6,"attribute":2,"value":10},{"slot":7,"attribute":2,"value":10},{"slot":8,"attribute":2,"value":10},{"slot":9,"attribute":4,"value":18},{"slot":10,"attribute":5,"value":36},{"slot":11,"attribute":12,"value":178},{"slot":12,"attribute":12,"value":178}]
... A607: =B607*1000+C607 -> 2301 | B607: 2 | C607: 301 | D607: =消耗配置!G303 -> [{"id":21,"num":3020},{"id":1,"num":302000}] | E607: =属性配置!G603&属性配置!L603&属性配置!Q603&属性配置!V603&属性配置!AA603&属性配置!AF603&属性配置!AK603&属性配置!AP603&属性配置!AU603&属性配置!AZ603&属性配置!BE603&属性配置!BJ603 -> [{"slot":1,"attribute":2,"value":494},{"slot":2,"attribute":4,"value":1039},{"slot":3,"attribute":5,"value":594},{"slot":4,"attribute":2,"value":345},{"slot":5,"attribute":2,"value":247},{"slot":6,"attribute":2,"value":247},{"slot":7,"attribute":2,"value":247},{"slot":8,"attribute":2,"value":247},{"slot":9,"attribute":4,"value":445},{"slot":10,"attribute":5,"value":891},{"slot":11,"attribute":12,"value":4455},{"slot":12,"attribute":12,"value":4455}]
A608: =B608*1000+C608 -> 3000 | B608: =B306+1 -> 3 | C608: =C306 -> 0 | D608: =消耗配置!G2 -> [{"id":21,"num":10},{"id":1,"num":1000}]
A609: =B609*1000+C609 -> 3001 | B609: =B307+1 -> 3 | C609: =C307 -> 1 | D609: =消耗配置!G3 -> [{"id":21,"num":20},{"id":1,"num":2000}] | E609: =属性配置!G604&属性配置!L604&属性配置!Q604&属性配置!V604&属性配置!AA604&属性配置!AF604&属性配置!AK604&属性配置!AP604&属性配置!AU604&属性配置!AZ604&属性配置!BE604&属性配置!BJ604 -> [{"slot":1,"attribute":2,"value":2},{"slot":2,"attribute":4,"value":3},{"slot":3,"attribute":5,"value":2},{"slot":4,"attribute":2,"value":1},{"slot":5,"attribute":2,"value":1},{"slot":6,"attribute":2,"value":1},{"slot":7,"attribute":2,"value":1},{"slot":8,"attribute":2,"value":1},{"slot":9,"attribute":4,"value":1},{"slot":10,"attribute":5,"value":3},{"slot":11,"attribute":12,"value":29},{"slot":12,"attribute":12,"value":29}]
A610: =B610*1000+C610 -> 3002 | B610: =B308+1 -> 3 | C610: =C308 -> 2 | D610: =消耗配置!G4 -> [{"id":21,"num":30},{"id":1,"num":3000}] | E610: =属性配置!G605&属性配置!L605&属性配置!Q605&属性配置!V605&属性配置!AA605&属性配置!AF605&属性配置!AK605&属性配置!AP605&属性配置!AU605&属性配置!AZ605&属性配置!BE605&属性配置!BJ605 -> [{"slot":1,"attribute":2,"value":2},{"slot":2,"attribute":4,"value":7},{"slot":3,"attribute":5,"value":4},{"slot":4,"attribute":2,"value":2},{"slot":5,"attribute":2,"value":2},{"slot":6,"attribute":2,"value":2},{"slot":7,"attribute":2,"value":2},{"slot":8,"attribute":2,"value":2},{"slot":9,"attribute":4,"value":3},{"slot":10,"attribute":5,"value":6},{"slot":11,"attribute":12,"value":59},{"slot":12,"attribute":12,"value":59}]
A611: =B611*1000+C611 -> 3003 | B611: =B309+1 -> 3 | C611: =C309 -> 3 | D611: =消耗配置!G5 -> [{"id":21,"num":40},{"id":1,"num":4000}] | E611: =属性配置!G606&属性配置!L606&属性配置!Q606&属性配置!V606&属性配置!AA606&属性配置!AF606&属性配置!AK606&属性配置!AP606&属性配置!AU606&属性配置!AZ606&属性配置!BE606&属性配置!BJ606 -> [{"slot":1,"attribute":2,"value":4},{"slot":2,"attribute":4,"value":10},{"slot":3,"attribute":5,"value":6},{"slot":4,"attribute":2,"value":2},{"slot":5,"attribute":2,"value":2},{"slot":6,"attribute":2,"value":2},{"slot":7,"attribute":2,"value":2},{"slot":8,"attribute":2,"value":2},{"slot":9,"attribute":4,"value":4},{"slot":10,"attribute":5,"value":9},{"slot":11,"attribute":12,"value":89},{"slot":12,"attribute":12,"value":89}]
A612: =B612*1000+C612 -> 3004 | B612: =B310+1 -> 3 | C612: =C310 -> 4 | D612: =消耗配置!G6 -> [{"id":21,"num":50},{"id":1,"num":5000}] | E612: =属性配置!G607&属性配置!L607&属性配置!Q607&属性配置!V607&属性配置!AA607&属性配置!AF607&属性配置!AK607&属性配置!AP607&属性配置!AU607&属性配置!AZ607&属性配置!BE607&属性配置!BJ607 -> [{"slot":1,"attribute":2,"value":6},{"slot":2,"attribute":4,"value":14},{"slot":3,"attribute":5,"value":8},{"slot":4,"attribute":2,"value":4},{"slot":5,"attribute":2,"value":2},{"slot":6,"attribute":2,"value":2},{"slot":7,"attribute":2,"value":2},{"slot":8,"attribute":2,"value":2},{"slot":9,"attribute":4,"value":6},{"slot":10,"attribute":5,"value":12},{"slot":11,"attribute":12,"value":119},{"slot":12,"attribute":12,"value":119}]
A613: =B613*1000+C613 -> 3005 | B613: =B311+1 -> 3 | C613: =C311 -> 5 | D613: =消耗配置!G7 -> [{"id":21,"num":60},{"id":1,"num":6000}] | E613: =属性配置!G608&属性配置!L608&属性配置!Q608&属性配置!V608&属性配置!AA608&属性配置!AF608&属性配置!AK608&属性配置!AP608&属性配置!AU608&属性配置!AZ608&属性配置!BE608&属性配置!BJ608 -> [{"slot":1,"attribute":2,"value":7},{"slot":2,"attribute":4,"value":17},{"slot":3,"attribute":5,"value":10},{"slot":4,"attribute":2,"value":5},{"slot":5,"attribute":2,"value":3},{"slot":6,"attribute":2,"value":3},{"slot":7,"attribute":2,"value":3},{"slot":8,"attribute":2,"value":3},{"slot":9,"attribute":4,"value":7},{"slot":10,"attribute":5,"value":15},{"slot":11,"attribute":12,"value":148},{"slot":12,"attribute":12,"value":148}]
A614: =B614*1000+C614 -> 3006 | B614: =B312+1 -> 3 | C614: =C312 -> 6 | D614: =消耗配置!G8 -> [{"id":21,"num":70},{"id":1,"num":7000}] | E614: =属性配置!G609&属性配置!L609&属性配置!Q609&属性配置!V609&属性配置!AA609&属性配置!AF609&属性配置!AK609&属性配置!AP609&属性配置!AU609&属性配置!AZ609&属性配置!BE609&属性配置!BJ609 -> [{"slot":1,"attribute":2,"value":8},{"slot":2,"attribute":4,"value":21},{"slot":3,"attribute":5,"value":12},{"slot":4,"attribute":2,"value":6},{"slot":5,"attribute":2,"value":4},{"slot":6,"attribute":2,"value":4},{"slot":7,"attribute":2,"value":4},{"slot":8,"attribute":2,"value":4},{"slot":9,"attribute":4,"value":9},{"slot":10,"attribute":5,"value":18},{"slot":11,"attribute":12,"value":177},{"slot":12,"attribute":12,"value":177}]
A615: =B615*1000+C615 -> 3007 | B615: =B313+1 -> 3 | C615: =C313 -> 7 | D615: =消耗配置!G9 -> [{"id":21,"num":80},{"id":1,"num":8000}] | E615: =属性配置!G610&属性配置!L610&属性配置!Q610&属性配置!V610&属性配置!AA610&属性配置!AF610&属性配置!AK610&属性配置!AP610&属性配置!AU610&属性配置!AZ610&属性配置!BE610&属性配置!BJ610 -> [{"slot":1,"attribute":2,"value":9},{"slot":2,"attribute":4,"value":24},{"slot":3,"attribute":5,"value":14},{"slot":4,"attribute":2,"value":7},{"slot":5,"attribute":2,"value":5},{"slot":6,"attribute":2,"value":5},{"slot":7,"attribute":2,"value":5},{"slot":8,"attribute":2,"value":5},{"slot":9,"attribute":4,"value":10},{"slot":10,"attribute":5,"value":21},{"slot":11,"attribute":12,"value":207},{"slot":12,"attribute":12,"value":207}]
A616: =B616*1000+C616 -> 3008 | B616: =B314+1 -> 3 | C616: =C314 -> 8 | D616: =消耗配置!G10 -> [{"id":21,"num":90},{"id":1,"num":9000}] | E616: =属性配置!G611&属性配置!L611&属性配置!Q611&属性配置!V611&属性配置!AA611&属性配置!AF611&属性配置!AK611&属性配置!AP611&属性配置!AU611&属性配置!AZ611&属性配置!BE611&属性配置!BJ611 -> [{"slot":1,"attribute":2,"value":11},{"slot":2,"attribute":4,"value":28},{"slot":3,"attribute":5,"value":16},{"slot":4,"attribute":2,"value":7},{"slot":5,"attribute":2,"value":6},{"slot":6,"attribute":2,"value":6},{"slot":7,"attribute":2,"value":6},{"slot":8,"attribute":2,"value":6},{"slot":9,"attribute":4,"value":12},{"slot":10,"attribute":5,"value":24},{"slot":11,"attribute":12,"value":237},{"slot":12,"attribute":12,"value":237}]
...

Sheet 属性配置
A1: 职业 | B1: 强化等级 | C1: [{"slot": | D1: ,"attribute": | E1: ,"value": | F1: }, | G1: 武器 | H1: {"slot": | I1: ,"attribute": | J1: ,"value": | K1: }, | L1: 衣服 | M1: {"slot": | N1: ,"attribute": | O1: ,"value": | P1: }, | Q1: 头盔 | R1: {"slot": | S1: ,"attribute": | T1: ,"value": | U1: }, | V1: 项链 | W1: {"slot": | X1: ,"attribute": | Y1: ,"value": | Z1: }, | AA1: 左戒指 | AB1: {"slot": | AC1: ,"attribute": | AD1: ,"value": | AE1: }, | AF1: 右戒指 | AG1: {"slot": | AH1: ,"attribute": | AI1: ,"value": | AJ1: }, | AK1: 左手镯 | AL1: {"slot": | AM1: ,"attribute": | AN1: ,"value": | AO1: }, | AP1: 右手镯 | AQ1: {"slot": | AR1: ,"attribute": | AS1: ,"value": | AT1: }, | AU1: 腰带 | AV1: {"slot": | AW1: ,"attribute": | AX1: ,"value": | AY1: }, | AZ1: 靴子 | BA1: {"slot": | BB1: ,"attribute": | BC1: ,"value": | BD1: }, | BE1: 护腿 | BF1: {"slot": | BG1: ,"attribute": | BH1: ,"value": | BI1: }] | BJ1: 饰品
A2: 1 | B2: 1 | C2: 1 | D2: 1 | E2: 2 | G2: =$C$1&C2&$D$1&D2&$E$1&E2&$F$1 -> [{"slot":1,"attribute":1,"value":2}, | H2: 2 | I2: 4 | J2: 3 | L2: =$H$1&H2&$I$1&I2&$J$1&J2&$K$1 -> {"slot":2,"attribute":4,"value":3}, | M2: 3 | N2: 5 | O2: 2 | Q2: =$M$1&M2&$N$1&N2&$O$1&O2&$P$1 -> {"slot":3,"attribute":5,"value":2}, | R2: 4 | S2: 1 | T2: 1 | V2: =$R$1&R2&$S$1&S2&$T$1&T2&$U$1 -> {"slot":4,"attribute":1,"value":1}, | W2: 5 | X2: 1 | Y2: 1 | AA2: =$W$1&W2&$X$1&X2&$Y$1&Y2&$Z$1 -> {"slot":5,"attribute":1,"value":1}, | AB2: 6 | AC2: 1 | AD2: 1 | AF2: =$AB$1&AB2&$AC$1&AC2&$AD$1&AD2&$AE$1 -> {"slot":6,"attribute":1,"value":1}, | AG2: 7 | AH2: 1 | AI2: 1 | AK2: =$AG$1&AG2&$AH$1&AH2&$AI$1&AI2&$AJ$1 -> {"slot":7,"attribute":1,"value":1}, | AL2: 8 | AM2: 1 | AN2: 1 | AP2: =$AL$1&AL2&$AM$1&AM2&$AN$1&AN2&$AO$1 -> {"slot":8,"attribute":1,"value":1}, | AQ2: 9 | AR2: 4 | AS2: 1 | AU2: =$AQ$1&AQ2&$AR$1&AR2&$AS$1&AS2&$AT$1 -> {"slot":9,"attribute":4,"value":1}, | AV2: 10 | AW2: 5 | AX2: 3 | AZ2: =$AV$1&AV2&$AW$1&AW2&$AX$1&AX2&$AY$1 -> {"slot":10,"attribute":5,"value":3}, | BA2: 11 | BB2: 12 | BC2: 44 | BE2: =$AV$1&BA2&$AW$1&BB2&$AX$1&BC2&$AY$1 -> {"slot":11,"attribute":12,"value":44}, | BF2: 12 | BG2: 12 | BH2: 44 | BJ2: =$AV$1&BF2&$AW$1&BG2&$AX$1&BH2&$BI$1 -> {"slot":12,"attribute":12,"value":44}]
A3: 1 | B3: 2 | C3: 1 | D3: 1 | E3: 4 | G3: =$C$1&C3&$D$1&D3&$E$1&E3&$F$1 -> [{"slot":1,"attribute":1,"value":4}, | H3: 2 | I3: 4 | J3: 7 | L3: =$H$1&H3&$I$1&I3&$J$1&J3&$K$1 -> {"slot":2,"attribute":4,"value":7}, | M3: 3 | N3: 5 | O3: 4 | Q3: =$M$1&M3&$N$1&N3&$O$1&O3&$P$1 -> {"slot":3,"attribute":5,"value":4}, | R3: 4 | S3: 1 | T3: 3 | V3: =$R$1&R3&$S$1&S3&$T$1&T3&$U$1 -> {"slot":4,"attribute":1,"value":3}, | W3: 5 | X3: 1 | Y3: 2 | AA3: =$W$1&W3&$X$1&X3&$Y$1&Y3&$Z$1 -> {"slot":5,"attribute":1,"value":2}, | AB3: 6 | AC3: 1 | AD3: 2 | AF3: =$AB$1&AB3&$AC$1&AC3&$AD$1&AD3&$AE$1 -> {"slot":6,"attribute":1,"value":2}, | AG3: 7 | AH3: 1 | AI3: 2 | AK3: =$AG$1&AG3&$AH$1&AH3&$AI$1&AI3&$AJ$1 -> {"slot":7,"attribute":1,"value":2}, | AL3: 8 | AM3: 1 | AN3: 2 | AP3: =$AL$1&AL3&$AM$1&AM3&$AN$1&AN3&$AO$1 -> {"slot":8,"attribute":1,"value":2}, | AQ3: 9 | AR3: 4 | AS3: 3 | AU3: =$AQ$1&AQ3&$AR$1&AR3&$AS$1&AS3&$AT$1 -> {"slot":9,"attribute":4,"value":3}, | AV3: 10 | AW3: 5 | AX3: 6 | AZ3: =$AV$1&AV3&$AW$1&AW3&$AX$1&AX3&$AY$1 -> {"slot":10,"attribute":5,"value":6}, | BA3: 11 | BB3: 12 | BC3: 89 | BE3: =$AV$1&BA3&$AW$1&BB3&$AX$1&BC3&$AY$1 -> {"slot":11,"attribute":12,"value":89}, | BF3: 12 | BG3: 12 | BH3: 89 | BJ3: =$AV$1&BF3&$AW$1&BG3&$AX$1&BH3&$BI$1 -> {"slot":12,"attribute":12,"value":89}]
A4: 1 | B4: 3 | C4: 1 | D4: 1 | E4: 6 | G4: =$C$1&C4&$D$1&D4&$E$1&E4&$F$1 -> [{"slot":1,"attribute":1,"value":6}, | H4: 2 | I4: 4 | J4: 10 | L4: =$H$1&H4&$I$1&I4&$J$1&J4&$K$1 -> {"slot":2,"attribute":4,"value":10}, | M4: 3 | N4: 5 | O4: 6 | Q4: =$M$1&M4&$N$1&N4&$O$1&O4&$P$1 -> {"slot":3,"attribute":5,"value":6}, | R4: 4 | S4: 1 | T4: 4 | V4: =$R$1&R4&$S$1&S4&$T$1&T4&$U$1 -> {"slot":4,"attribute":1,"value":4}, | W4: 5 | X4: 1 | Y4: 3 | AA4: =$W$1&W4&$X$1&X4&$Y$1&Y4&$Z$1 -> {"slot":5,"attribute":1,"value":3}, | AB4: 6 | AC4: 1 | AD4: 3 | AF4: =$AB$1&AB4&$AC$1&AC4&$AD$1&AD4&$AE$1 -> {"slot":6,"attribute":1,"value":3}, | AG4: 7 | AH4: 1 | AI4: 3 | AK4: =$AG$1&AG4&$AH$1&AH4&$AI$1&AI4&$AJ$1 -> {"slot":7,"attribute":1,"value":3}, | AL4: 8 | AM4: 1 | AN4: 3 | AP4: =$AL$1&AL4&$AM$1&AM4&$AN$1&AN4&$AO$1 -> {"slot":8,"attribute":1,"value":3}, | AQ4: 9 | AR4: 4 | AS4: 4 | AU4: =$AQ$1&AQ4&$AR$1&AR4&$AS$1&AS4&$AT$1 -> {"slot":9,"attribute":4,"value":4}, | AV4: 10 | AW4: 5 | AX4: 9 | AZ4: =$AV$1&AV4&$AW$1&AW4&$AX$1&AX4&$AY$1 -> {"slot":10,"attribute":5,"value":9}, | BA4: 11 | BB4: 12 | BC4: 133 | BE4: =$AV$1&BA4&$AW$1&BB4&$AX$1&BC4&$AY$1 -> {"slot":11,"attribute":12,"value":133}, | BF4: 12 | BG4: 12 | BH4: 133 | BJ4: =$AV$1&BF4&$AW$1&BG4&$AX$1&BH4&$BI$1 -> {"slot":12,"attribute":12,"value":133}]
A5: 1 | B5: 4 | C5: 1 | D5: 1 | E5: 8 | G5: =$C$1&C5&$D$1&D5&$E$1&E5&$F$1 -> [{"slot":1,"attribute":1,"value":8}, | H5: 2 | I5: 4 | J5: 14 | L5: =$H$1&H5&$I$1&I5&$J$1&J5&$K$1 -> {"slot":2,"attribute":4,"value":14}, | M5: 3 | N5: 5 | O5: 8 | Q5: =$M$1&M5&$N$1&N5&$O$1&O5&$P$1 -> {"slot":3,"attribute":5,"value":8}, | R5: 4 | S5: 1 | T5: 6 | V5: =$R$1&R5&$S$1&S5&$T$1&T5&$U$1 -> {"slot":4,"attribute":1,"value":6}, | W5: 5 | X5: 1 | Y5: 4 | AA5: =$W$1&W5&$X$1&X5&$Y$1&Y5&$Z$1 -> {"slot":5,"attribute":1,"value":4}, | AB5: 6 | AC5: 1 | AD5: 4 | AF5: =$AB$1&AB5&$AC$1&AC5&$AD$1&AD5&$AE$1 -> {"slot":6,"attribute":1,"value":4}, | AG5: 7 | AH5: 1 | AI5: 4 | AK5: =$AG$1&AG5&$AH$1&AH5&$AI$1&AI5&$AJ$1 -> {"slot":7,"attribute":1,"value":4}, | AL5: 8 | AM5: 1 | AN5: 4 | AP5: =$AL$1&AL5&$AM$1&AM5&$AN$1&AN5&$AO$1 -> {"slot":8,"attribute":1,"value":4}, | AQ5: 9 | AR5: 4 | AS5: 6 | AU5: =$AQ$1&AQ5&$AR$1&AR5&$AS$1&AS5&$AT$1 -> {"slot":9,"attribute":4,"value":6}, | AV5: 10 | AW5: 5 | AX5: 12 | AZ5: =$AV$1&AV5&$AW$1&AW5&$AX$1&AX5&$AY$1 -> {"slot":10,"attribute":5,"value":12}, | BA5: 11 | BB5: 12 | BC5: 178 | BE5: =$AV$1&BA5&$AW$1&BB5&$AX$1&BC5&$AY$1 -> {"slot":11,"attribute":12,"value":178}, | BF5: 12 | BG5: 12 | BH5: 178 | BJ5: =$AV$1&BF5&$AW$1&BG5&$AX$1&BH5&$BI$1 -> {"slot":12,"attribute":12,"value":178}]
A6: 1 | B6: 5 | C6: 1 | D6: 1 | E6: 10 | G6: =$C$1&C6&$D$1&D6&$E$1&E6&$F$1 -> [{"slot":1,"attribute":1,"value":10}, | H6: 2 | I6: 4 | J6: 17 | L6: =$H$1&H6&$I$1&I6&$J$1&J6&$K$1 -> {"slot":2,"attribute":4,"value":17}, | M6: 3 | N6: 5 | O6: 10 | Q6: =$M$1&M6&$N$1&N6&$O$1&O6&$P$1 -> {"slot":3,"attribute":5,"value":10}, | R6: 4 | S6: 1 | T6: 7 | V6: =$R$1&R6&$S$1&S6&$T$1&T6&$U$1 -> {"slot":4,"attribute":1,"value":7}, | W6: 5 | X6: 1 | Y6: 5 | AA6: =$W$1&W6&$X$1&X6&$Y$1&Y6&$Z$1 -> {"slot":5,"attribute":1,"value":5}, | AB6: 6 | AC6: 1 | AD6: 5 | AF6: =$AB$1&AB6&$AC$1&AC6&$AD$1&AD6&$AE$1 -> {"slot":6,"attribute":1,"value":5}, | AG6: 7 | AH6: 1 | AI6: 5 | AK6: =$AG$1&AG6&$AH$1&AH6&$AI$1&AI6&$AJ$1 -> {"slot":7,"attribute":1,"value":5}, | AL6: 8 | AM6: 1 | AN6: 5 | AP6: =$AL$1&AL6&$AM$1&AM6&$AN$1&AN6&$AO$1 -> {"slot":8,"attribute":1,"value":5}, | AQ6: 9 | AR6: 4 | AS6: 7 | AU6: =$AQ$1&AQ6&$AR$1&AR6&$AS$1&AS6&$AT$1 -> {"slot":9,"attribute":4,"value":7}, | AV6: 10 | AW6: 5 | AX6: 15 | AZ6: =$AV$1&AV6&$AW$1&AW6&$AX$1&AX6&$AY$1 -> {"slot":10,"attribute":5,"value":15}, | BA6: 11 | BB6: 12 | BC6: 222 | BE6: =$AV$1&BA6&$AW$1&BB6&$AX$1&BC6&$AY$1 -> {"slot":11,"attribute":12,"value":222}, | BF6: 12 | BG6: 12 | BH6: 222 | BJ6: =$AV$1&BF6&$AW$1&BG6&$AX$1&BH6&$BI$1 -> {"slot":12,"attribute":12,"value":222}]
A7: 1 | B7: 6 | C7: 1 | D7: 1 | E7: 12 | G7: =$C$1&C7&$D$1&D7&$E$1&E7&$F$1 -> [{"slot":1,"attribute":1,"value":12}, | H7: 2 | I7: 4 | J7: 21 | L7: =$H$1&H7&$I$1&I7&$J$1&J7&$K$1 -> {"slot":2,"attribute":4,"value":21}, | M7: 3 | N7: 5 | O7: 12 | Q7: =$M$1&M7&$N$1&N7&$O$1&O7&$P$1 -> {"slot":3,"attribute":5,"value":12}, | R7: 4 | S7: 1 | T7: 8 | V7: =$R$1&R7&$S$1&S7&$T$1&T7&$U$1 -> {"slot":4,"attribute":1,"value":8}, | W7: 5 | X7: 1 | Y7: 6 | AA7: =$W$1&W7&$X$1&X7&$Y$1&Y7&$Z$1 -> {"slot":5,"attribute":1,"value":6}, | AB7: 6 | AC7: 1 | AD7: 6 | AF7: =$AB$1&AB7&$AC$1&AC7&$AD$1&AD7&$AE$1 -> {"slot":6,"attribute":1,"value":6}, | AG7: 7 | AH7: 1 | AI7: 6 | AK7: =$AG$1&AG7&$AH$1&AH7&$AI$1&AI7&$AJ$1 -> {"slot":7,"attribute":1,"value":6}, | AL7: 8 | AM7: 1 | AN7: 6 | AP7: =$AL$1&AL7&$AM$1&AM7&$AN$1&AN7&$AO$1 -> {"slot":8,"attribute":1,"value":6}, | AQ7: 9 | AR7: 4 | AS7: 9 | AU7: =$AQ$1&AQ7&$AR$1&AR7&$AS$1&AS7&$AT$1 -> {"slot":9,"attribute":4,"value":9}, | AV7: 10 | AW7: 5 | AX7: 18 | AZ7: =$AV$1&AV7&$AW$1&AW7&$AX$1&AX7&$AY$1 -> {"slot":10,"attribute":5,"value":18}, | BA7: 11 | BB7: 12 | BC7: 266 | BE7: =$AV$1&BA7&$AW$1&BB7&$AX$1&BC7&$AY$1 -> {"slot":11,"attribute":12,"value":266}, | BF7: 12 | BG7: 12 | BH7: 266 | BJ7: =$AV$1&BF7&$AW$1&BG7&$AX$1&BH7&$BI$1 -> {"slot":12,"attribute":12,"value":266}]
A8: 1 | B8: 7 | C8: 1 | D8: 1 | E8: 14 | G8: =$C$1&C8&$D$1&D8&$E$1&E8&$F$1 -> [{"slot":1,"attribute":1,"value":14}, | H8: 2 | I8: 4 | J8: 24 | L8: =$H$1&H8&$I$1&I8&$J$1&J8&$K$1 -> {"slot":2,"attribute":4,"value":24}, | M8: 3 | N8: 5 | O8: 14 | Q8: =$M$1&M8&$N$1&N8&$O$1&O8&$P$1 -> {"slot":3,"attribute":5,"value":14}, | R8: 4 | S8: 1 | T8: 10 | V8: =$R$1&R8&$S$1&S8&$T$1&T8&$U$1 -> {"slot":4,"attribute":1,"value":10}, | W8: 5 | X8: 1 | Y8: 7 | AA8: =$W$1&W8&$X$1&X8&$Y$1&Y8&$Z$1 -> {"slot":5,"attribute":1,"value":7}, | AB8: 6 | AC8: 1 | AD8: 7 | AF8: =$AB$1&AB8&$AC$1&AC8&$AD$1&AD8&$AE$1 -> {"slot":6,"attribute":1,"value":7}, | AG8: 7 | AH8: 1 | AI8: 7 | AK8: =$AG$1&AG8&$AH$1&AH8&$AI$1&AI8&$AJ$1 -> {"slot":7,"attribute":1,"value":7}, | AL8: 8 | AM8: 1 | AN8: 7 | AP8: =$AL$1&AL8&$AM$1&AM8&$AN$1&AN8&$AO$1 -> {"slot":8,"attribute":1,"value":7}, | AQ8: 9 | AR8: 4 | AS8: 10 | AU8: =$AQ$1&AQ8&$AR$1&AR8&$AS$1&AS8&$AT$1 -> {"slot":9,"attribute":4,"value":10}, | AV8: 10 | AW8: 5 | AX8: 21 | AZ8: =$AV$1&AV8&$AW$1&AW8&$AX$1&AX8&$AY$1 -> {"slot":10,"attribute":5,"value":21}, | BA8: 11 | BB8: 12 | BC8: 311 | BE8: =$AV$1&BA8&$AW$1&BB8&$AX$1&BC8&$AY$1 -> {"slot":11,"attribute":12,"value":311}, | BF8: 12 | BG8: 12 | BH8: 311 | BJ8: =$AV$1&BF8&$AW$1&BG8&$AX$1&BH8&$BI$1 -> {"slot":12,"attribute":12,"value":311}]
A9: 1 | B9: 8 | C9: 1 | D9: 1 | E9: 16 | G9: =$C$1&C9&$D$1&D9&$E$1&E9&$F$1 -> [{"slot":1,"attribute":1,"value":16}, | H9: 2 | I9: 4 | J9: 28 | L9: =$H$1&H9&$I$1&I9&$J$1&J9&$K$1 -> {"slot":2,"attribute":4,"value":28}, | M9: 3 | N9: 5 | O9: 16 | Q9: =$M$1&M9&$N$1&N9&$O$1&O9&$P$1 -> {"slot":3,"attribute":5,"value":16}, | R9: 4 | S9: 1 | T9: 11 | V9: =$R$1&R9&$S$1&S9&$T$1&T9&$U$1 -> {"slot":4,"attribute":1,"value":11}, | W9: 5 | X9: 1 | Y9: 8 | AA9: =$W$1&W9&$X$1&X9&$Y$1&Y9&$Z$1 -> {"slot":5,"attribute":1,"value":8}, | AB9: 6 | AC9: 1 | AD9: 8 | AF9: =$AB$1&AB9&$AC$1&AC9&$AD$1&AD9&$AE$1 -> {"slot":6,"attribute":1,"value":8}, | AG9: 7 | AH9: 1 | AI9: 8 | AK9: =$AG$1&AG9&$AH$1&AH9&$AI$1&AI9&$AJ$1 -> {"slot":7,"attribute":1,"value":8}, | AL9: 8 | AM9: 1 | AN9: 8 | AP9: =$AL$1&AL9&$AM$1&AM9&$AN$1&AN9&$AO$1 -> {"slot":8,"attribute":1,"value":8}, | AQ9: 9 | AR9: 4 | AS9: 12 | AU9: =$AQ$1&AQ9&$AR$1&AR9&$AS$1&AS9&$AT$1 -> {"slot":9,"attribute":4,"value":12}, | AV9: 10 | AW9: 5 | AX9: 24 | AZ9: =$AV$1&AV9&$AW$1&AW9&$AX$1&AX9&$AY$1 -> {"slot":10,"attribute":5,"value":24}, | BA9: 11 | BB9: 12 | BC9: 355 | BE9: =$AV$1&BA9&$AW$1&BB9&$AX$1&BC9&$AY$1 -> {"slot":11,"attribute":12,"value":355}, | BF9: 12 | BG9: 12 | BH9: 355 | BJ9: =$AV$1&BF9&$AW$1&BG9&$AX$1&BH9&$BI$1 -> {"slot":12,"attribute":12,"value":355}]
A10: 1 | B10: 9 | C10: 1 | D10: 1 | E10: 18 | G10: =$C$1&C10&$D$1&D10&$E$1&E10&$F$1 -> [{"slot":1,"attribute":1,"value":18}, | H10: 2 | I10: 4 | J10: 31 | L10: =$H$1&H10&$I$1&I10&$J$1&J10&$K$1 -> {"slot":2,"attribute":4,"value":31}, | M10: 3 | N10: 5 | O10: 18 | Q10: =$M$1&M10&$N$1&N10&$O$1&O10&$P$1 -> {"slot":3,"attribute":5,"value":18}, | R10: 4 | S10: 1 | T10: 13 | V10: =$R$1&R10&$S$1&S10&$T$1&T10&$U$1 -> {"slot":4,"attribute":1,"value":13}, | W10: 5 | X10: 1 | Y10: 9 | AA10: =$W$1&W10&$X$1&X10&$Y$1&Y10&$Z$1 -> {"slot":5,"attribute":1,"value":9}, | AB10: 6 | AC10: 1 | AD10: 9 | AF10: =$AB$1&AB10&$AC$1&AC10&$AD$1&AD10&$AE$1 -> {"slot":6,"attribute":1,"value":9}, | AG10: 7 | AH10: 1 | AI10: 9 | AK10: =$AG$1&AG10&$AH$1&AH10&$AI$1&AI10&$AJ$1 -> {"slot":7,"attribute":1,"value":9}, | AL10: 8 | AM10: 1 | AN10: 9 | AP10: =$AL$1&AL10&$AM$1&AM10&$AN$1&AN10&$AO$1 -> {"slot":8,"attribute":1,"value":9}, | AQ10: 9 | AR10: 4 | AS10: 13 | AU10: =$AQ$1&AQ10&$AR$1&AR10&$AS$1&AS10&$AT$1 -> {"slot":9,"attribute":4,"value":13}, | AV10: 10 | AW10: 5 | AX10: 27 | AZ10: =$AV$1&AV10&$AW$1&AW10&$AX$1&AX10&$AY$1 -> {"slot":10,"attribute":5,"value":27}, | BA10: 11 | BB10: 12 | BC10: 400 | BE10: =$AV$1&BA10&$AW$1&BB10&$AX$1&BC10&$AY$1 -> {"slot":11,"attribute":12,"value":400}, | BF10: 12 | BG10: 12 | BH10: 400 | BJ10: =$AV$1&BF10&$AW$1&BG10&$AX$1&BH10&$BI$1 -> {"slot":12,"attribute":12,"value":400}]
A11: 1 | B11: 10 | C11: 1 | D11: 1 | E11: 20 | G11: =$C$1&C11&$D$1&D11&$E$1&E11&$F$1 -> [{"slot":1,"attribute":1,"value":20}, | H11: 2 | I11: 4 | J11: 35 | L11: =$H$1&H11&$I$1&I11&$J$1&J11&$K$1 -> {"slot":2,"attribute":4,"value":35}, | M11: 3 | N11: 5 | O11: 20 | Q11: =$M$1&M11&$N$1&N11&$O$1&O11&$P$1 -> {"slot":3,"attribute":5,"value":20}, | R11: 4 | S11: 1 | T11: 14 | V11: =$R$1&R11&$S$1&S11&$T$1&T11&$U$1 -> {"slot":4,"attribute":1,"value":14}, | W11: 5 | X11: 1 | Y11: 10 | AA11: =$W$1&W11&$X$1&X11&$Y$1&Y11&$Z$1 -> {"slot":5,"attribute":1,"value":10}, | AB11: 6 | AC11: 1 | AD11: 10 | AF11: =$AB$1&AB11&$AC$1&AC11&$AD$1&AD11&$AE$1 -> {"slot":6,"attribute":1,"value":10}, | AG11: 7 | AH11: 1 | AI11: 10 | AK11: =$AG$1&AG11&$AH$1&AH11&$AI$1&AI11&$AJ$1 -> {"slot":7,"attribute":1,"value":10}, | AL11: 8 | AM11: 1 | AN11: 10 | AP11: =$AL$1&AL11&$AM$1&AM11&$AN$1&AN11&$AO$1 -> {"slot":8,"attribute":1,"value":10}, | AQ11: 9 | AR11: 4 | AS11: 15 | AU11: =$AQ$1&AQ11&$AR$1&AR11&$AS$1&AS11&$AT$1 -> {"slot":9,"attribute":4,"value":15}, | AV11: 10 | AW11: 5 | AX11: 30 | AZ11: =$AV$1&AV11&$AW$1&AW11&$AX$1&AX11&$AY$1 -> {"slot":10,"attribute":5,"value":30}, | BA11: 11 | BB11: 12 | BC11: 444 | BE11: =$AV$1&BA11&$AW$1&BB11&$AX$1&BC11&$AY$1 -> {"slot":11,"attribute":12,"value":444}, | BF11: 12 | BG11: 12 | BH11: 444 | BJ11: =$AV$1&BF11&$AW$1&BG11&$AX$1&BH11&$BI$1 -> {"slot":12,"attribute":12,"value":444}]
A12: 1 | B12: 11 | C12: 1 | D12: 1 | E12: 22 | G12: =$C$1&C12&$D$1&D12&$E$1&E12&$F$1 -> [{"slot":1,"attribute":1,"value":22}, | H12: 2 | I12: 4 | J12: 38 | L12: =$H$1&H12&$I$1&I12&$J$1&J12&$K$1 -> {"slot":2,"attribute":4,"value":38}, | M12: 3 | N12: 5 | O12: 22 | Q12: =$M$1&M12&$N$1&N12&$O$1&O12&$P$1 -> {"slot":3,"attribute":5,"value":22}, | R12: 4 | S12: 1 | T12: 15 | V12: =$R$1&R12&$S$1&S12&$T$1&T12&$U$1 -> {"slot":4,"attribute":1,"value":15}, | W12: 5 | X12: 1 | Y12: 11 | AA12: =$W$1&W12&$X$1&X12&$Y$1&Y12&$Z$1 -> {"slot":5,"attribute":1,"value":11}, | AB12: 6 | AC12: 1 | AD12: 11 | AF12: =$AB$1&AB12&$AC$1&AC12&$AD$1&AD12&$AE$1 -> {"slot":6,"attribute":1,"value":11}, | AG12: 7 | AH12: 1 | AI12: 11 | AK12: =$AG$1&AG12&$AH$1&AH12&$AI$1&AI12&$AJ$1 -> {"slot":7,"attribute":1,"value":11}, | AL12: 8 | AM12: 1 | AN12: 11 | AP12: =$AL$1&AL12&$AM$1&AM12&$AN$1&AN12&$AO$1 -> {"slot":8,"attribute":1,"value":11}, | AQ12: 9 | AR12: 4 | AS12: 16 | AU12: =$AQ$1&AQ12&$AR$1&AR12&$AS$1&AS12&$AT$1 -> {"slot":9,"attribute":4,"value":16}, | AV12: 10 | AW12: 5 | AX12: 33 | AZ12: =$AV$1&AV12&$AW$1&AW12&$AX$1&AX12&$AY$1 -> {"slot":10,"attribute":5,"value":33}, | BA12: 11 | BB12: 12 | BC12: 488 | BE12: =$AV$1&BA12&$AW$1&BB12&$AX$1&BC12&$AY$1 -> {"slot":11,"attribute":12,"value":488}, | BF12: 12 | BG12: 12 | BH12: 488 | BJ12: =$AV$1&BF12&$AW$1&BG12&$AX$1&BH12&$BI$1 -> {"slot":12,"attribute":12,"value":488}]
A13: 1 | B13: 12 | C13: 1 | D13: 1 | E13: 24 | G13: =$C$1&C13&$D$1&D13&$E$1&E13&$F$1 -> [{"slot":1,"attribute":1,"value":24}, | H13: 2 | I13: 4 | J13: 41 | L13: =$H$1&H13&$I$1&I13&$J$1&J13&$K$1 -> {"slot":2,"attribute":4,"value":41}, | M13: 3 | N13: 5 | O13: 24 | Q13: =$M$1&M13&$N$1&N13&$O$1&O13&$P$1 -> {"slot":3,"attribute":5,"value":24}, | R13: 4 | S13: 1 | T13: 17 | V13: =$R$1&R13&$S$1&S13&$T$1&T13&$U$1 -> {"slot":4,"attribute":1,"value":17}, | W13: 5 | X13: 1 | Y13: 12 | AA13: =$W$1&W13&$X$1&X13&$Y$1&Y13&$Z$1 -> {"slot":5,"attribute":1,"value":12}, | AB13: 6 | AC13: 1 | AD13: 12 | AF13: =$AB$1&AB13&$AC$1&AC13&$AD$1&AD13&$AE$1 -> {"slot":6,"attribute":1,"value":12}, | AG13: 7 | AH13: 1 | AI13: 12 | AK13: =$AG$1&AG13&$AH$1&AH13&$AI$1&AI13&$AJ$1 -> {"slot":7,"attribute":1,"value":12}, | AL13: 8 | AM13: 1 | AN13: 12 | AP13: =$AL$1&AL13&$AM$1&AM13&$AN$1&AN13&$AO$1 -> {"slot":8,"attribute":1,"value":12}, | AQ13: 9 | AR13: 4 | AS13: 18 | AU13: =$AQ$1&AQ13&$AR$1&AR13&$AS$1&AS13&$AT$1 -> {"slot":9,"attribute":4,"value":18}, | AV13: 10 | AW13: 5 | AX13: 36 | AZ13: =$AV$1&AV13&$AW$1&AW13&$AX$1&AX13&$AY$1 -> {"slot":10,"attribute":5,"value":36}, | BA13: 11 | BB13: 12 | BC13: 533 | BE13: =$AV$1&BA13&$AW$1&BB13&$AX$1&BC13&$AY$1 -> {"slot":11,"attribute":12,"value":533}, | BF13: 12 | BG13: 12 | BH13: 533 | BJ13: =$AV$1&BF13&$AW$1&BG13&$AX$1&BH13&$BI$1 -> {"slot":12,"attribute":12,"value":533}]
... A302: 1 | B302: 301 | C302: 1 | D302: 1 | E302: 602 | G302: =$C$1&C302&$D$1&D302&$E$1&E302&$F$1 -> [{"slot":1,"attribute":1,"value":602}, | H302: 2 | I302: 4 | J302: 1039 | L302: =$H$1&H302&$I$1&I302&$J$1&J302&$K$1 -> {"slot":2,"attribute":4,"value":1039}, | M302: 3 | N302: 5 | O302: 594 | Q302: =$M$1&M302&$N$1&N302&$O$1&O302&$P$1 -> {"slot":3,"attribute":5,"value":594}, | R302: 4 | S302: 1 | T302: 421 | V302: =$R$1&R302&$S$1&S302&$T$1&T302&$U$1 -> {"slot":4,"attribute":1,"value":421}, | W302: 5 | X302: 1 | Y302: 301 | AA302: =$W$1&W302&$X$1&X302&$Y$1&Y302&$Z$1 -> {"slot":5,"attribute":1,"value":301}, | AB302: 6 | AC302: 1 | AD302: 301 | AF302: =$AB$1&AB302&$AC$1&AC302&$AD$1&AD302&$AE$1 -> {"slot":6,"attribute":1,"value":301}, | AG302: 7 | AH302: 1 | AI302: 301 | AK302: =$AG$1&AG302&$AH$1&AH302&$AI$1&AI302&$AJ$1 -> {"slot":7,"attribute":1,"value":301}, | AL302: 8 | AM302: 1 | AN302: 301 | AP302: =$AL$1&AL302&$AM$1&AM302&$AN$1&AN302&$AO$1 -> {"slot":8,"attribute":1,"value":301}, | AQ302: 9 | AR302: 4 | AS302: 445 | AU302: =$AQ$1&AQ302&$AR$1&AR302&$AS$1&AS302&$AT$1 -> {"slot":9,"attribute":4,"value":445}, | AV302: 10 | AW302: 5 | AX302: 891 | AZ302: =$AV$1&AV302&$AW$1&AW302&$AX$1&AX302&$AY$1 -> {"slot":10,"attribute":5,"value":891}, | BA302: 11 | BB302: 12 | BC302: 13364 | BE302: =$AV$1&BA302&$AW$1&BB302&$AX$1&BC302&$AY$1 -> {"slot":11,"attribute":12,"value":13364}, | BF302: 12 | BG302: 12 | BH302: 13364 | BJ302: =$AV$1&BF302&$AW$1&BG302&$AX$1&BH302&$BI$1 -> {"slot":12,"attribute":12,"value":13364}]
A303: 2 | B303: 1 | C303: 1 | D303: 2 | E303: =ROUND(E2*0.82,0) -> 2 | G303: =$C$1&C303&$D$1&D303&$E$1&E303&$F$1 -> [{"slot":1,"attribute":2,"value":2}, | H303: 2 | I303: 4 | J303: =J2 -> 3 | L303: =$H$1&H303&$I$1&I303&$J$1&J303&$K$1 -> {"slot":2,"attribute":4,"value":3}, | M303: 3 | N303: 5 | O303: =O2 -> 2 | Q303: =$M$1&M303&$N$1&N303&$O$1&O303&$P$1 -> {"slot":3,"attribute":5,"value":2}, | R303: 4 | S303: 2 | T303: =ROUND(T2*0.82,0) -> 1 | V303: =$R$1&R303&$S$1&S303&$T$1&T303&$U$1 -> {"slot":4,"attribute":2,"value":1}, | W303: 5 | X303: 2 | Y303: =ROUND(Y2*0.82,0) -> 1 | AA303: =$W$1&W303&$X$1&X303&$Y$1&Y303&$Z$1 -> {"slot":5,"attribute":2,"value":1}, | AB303: 6 | AC303: 2 | AD303: =ROUND(AD2*0.82,0) -> 1 | AF303: =$AB$1&AB303&$AC$1&AC303&$AD$1&AD303&$AE$1 -> {"slot":6,"attribute":2,"value":1}, | AG303: 7 | AH303: 2 | AI303: =ROUND(AI2*0.82,0) -> 1 | AK303: =$AG$1&AG303&$AH$1&AH303&$AI$1&AI303&$AJ$1 -> {"slot":7,"attribute":2,"value":1}, | AL303: 8 | AM303: 2 | AN303: =ROUND(AN2*0.82,0) -> 1 | AP303: =$AL$1&AL303&$AM$1&AM303&$AN$1&AN303&$AO$1 -> {"slot":8,"attribute":2,"value":1}, | AQ303: 9 | AR303: 4 | AS303: =AS2 -> 1 | AU303: =$AQ$1&AQ303&$AR$1&AR303&$AS$1&AS303&$AT$1 -> {"slot":9,"attribute":4,"value":1}, | AV303: 10 | AW303: 5 | AX303: =AX2 -> 3 | AZ303: =$AV$1&AV303&$AW$1&AW303&$AX$1&AX303&$AY$1 -> {"slot":10,"attribute":5,"value":3}, | BA303: 11 | BB303: 12 | BC303: =ROUND(BC2/3,0) -> 15 | BE303: =$AV$1&BA303&$AW$1&BB303&$AX$1&BC303&$AY$1 -> {"slot":11,"attribute":12,"value":15}, | BF303: 12 | BG303: 12 | BH303: =ROUND(BH2/3,0) -> 15 | BJ303: =$AV$1&BF303&$AW$1&BG303&$AX$1&BH303&$BI$1 -> {"slot":12,"attribute":12,"value":15}]
A304: 2 | B304: 2 | C304: 1 | D304: 2 | E304: =ROUND(E3*0.82,0) -> 3 | G304: =$C$1&C304&$D$1&D304&$E$1&E304&$F$1 -> [{"slot":1,"attribute":2,"value":3}, | H304: 2 | I304: 4 | J304: =J3 -> 7 | L304: =$H$1&H304&$I$1&I304&$J$1&J304&$K$1 -> {"slot":2,"attribute":4,"value":7}, | M304: 3 | N304: 5 | O304: =O3 -> 4 | Q304: =$M$1&M304&$N$1&N304&$O$1&O304&$P$1 -> {"slot":3,"attribute":5,"value":4}, | R304: 4 | S304: 2 | T304: =ROUND(T3*0.82,0) -> 2 | V304: =$R$1&R304&$S$1&S304&$T$1&T304&$U$1 -> {"slot":4,"attribute":2,"value":2}, | W304: 5 | X304: 2 | Y304: =ROUND(Y3*0.82,0) -> 2 | AA304: =$W$1&W304&$X$1&X304&$Y$1&Y304&$Z$1 -> {"slot":5,"attribute":2,"value":2}, | AB304: 6 | AC304: 2 | AD304: =ROUND(AD3*0.82,0) -> 2 | AF304: =$AB$1&AB304&$AC$1&AC304&$AD$1&AD304&$AE$1 -> {"slot":6,"attribute":2,"value":2}, | AG304: 7 | AH304: 2 | AI304: =ROUND(AI3*0.82,0) -> 2 | AK304: =$AG$1&AG304&$AH$1&AH304&$AI$1&AI304&$AJ$1 -> {"slot":7,"attribute":2,"value":2}, | AL304: 8 | AM304: 2 | AN304: =ROUND(AN3*0.82,0) -> 2 | AP304: =$AL$1&AL304&$AM$1&AM304&$AN$1&AN304&$AO$1 -> {"slot":8,"attribute":2,"value":2}, | AQ304: 9 | AR304: 4 | AS304: =AS3 -> 3 | AU304: =$AQ$1&AQ304&$AR$1&AR304&$AS$1&AS304&$AT$1 -> {"slot":9,"attribute":4,"value":3}, | AV304: 10 | AW304: 5 | AX304: =AX3 -> 6 | AZ304: =$AV$1&AV304&$AW$1&AW304&$AX$1&AX304&$AY$1 -> {"slot":10,"attribute":5,"value":6}, | BA304: 11 | BB304: 12 | BC304: =ROUND(BC3/3,0) -> 30 | BE304: =$AV$1&BA304&$AW$1&BB304&$AX$1&BC304&$AY$1 -> {"slot":11,"attribute":12,"value":30}, | BF304: 12 | BG304: 12 | BH304: =ROUND(BH3/3,0) -> 30 | BJ304: =$AV$1&BF304&$AW$1&BG304&$AX$1&BH304&$BI$1 -> {"slot":12,"attribute":12,"value":30}]
A305: 2 | B305: 3 | C305: 1 | D305: 2 | E305: =ROUND(E4*0.82,0) -> 5 | G305: =$C$1&C305&$D$1&D305&$E$1&E305&$F$1 -> [{"slot":1,"attribute":2,"value":5}, | H305: 2 | I305: 4 | J305: =J4 -> 10 | L305: =$H$1&H305&$I$1&I305&$J$1&J305&$K$1 -> {"slot":2,"attribute":4,"value":10}, | M305: 3 | N305: 5 | O305: =O4 -> 6 | Q305: =$M$1&M305&$N$1&N305&$O$1&O305&$P$1 -> {"slot":3,"attribute":5,"value":6}, | R305: 4 | S305: 2 | T305: =ROUND(T4*0.82,0) -> 3 | V305: =$R$1&R305&$S$1&S305&$T$1&T305&$U$1 -> {"slot":4,"attribute":2,"value":3}, | W305: 5 | X305: 2 | Y305: =ROUND(Y4*0.82,0) -> 2 | AA305: =$W$1&W305&$X$1&X305&$Y$1&Y305&$Z$1 -> {"slot":5,"attribute":2,"value":2}, | AB305: 6 | AC305: 2 | AD305: =ROUND(AD4*0.82,0) -> 2 | AF305: =$AB$1&AB305&$AC$1&AC305&$AD$1&AD305&$AE$1 -> {"slot":6,"attribute":2,"value":2}, | AG305: 7 | AH305: 2 | AI305: =ROUND(AI4*0.82,0) -> 2 | AK305: =$AG$1&AG305&$AH$1&AH305&$AI$1&AI305&$AJ$1 -> {"slot":7,"attribute":2,"value":2}, | AL305: 8 | AM305: 2 | AN305: =ROUND(AN4*0.82,0) -> 2 | AP305: =$AL$1&AL305&$AM$1&AM305&$AN$1&AN305&$AO$1 -> {"slot":8,"attribute":2,"value":2}, | AQ305: 9 | AR305: 4 | AS305: =AS4 -> 4 | AU305: =$AQ$1&AQ305&$AR$1&AR305&$AS$1&AS305&$AT$1 -> {"slot":9,"attribute":4,"value":4}, | AV305: 10 | AW305: 5 | AX305: =AX4 -> 9 | AZ305: =$AV$1&AV305&$AW$1&AW305&$AX$1&AX305&$AY$1 -> {"slot":10,"attribute":5,"value":9}, | BA305: 11 | BB305: 12 | BC305: =ROUND(BC4/3,0) -> 44 | BE305: =$AV$1&BA305&$AW$1&BB305&$AX$1&BC305&$AY$1 -> {"slot":11,"attribute":12,"value":44}, | BF305: 12 | BG305: 12 | BH305: =ROUND(BH4/3,0) -> 44 | BJ305: =$AV$1&BF305&$AW$1&BG305&$AX$1&BH305&$BI$1 -> {"slot":12,"attribute":12,"value":44}]
A306: 2 | B306: 4 | C306: 1 | D306: 2 | E306: =ROUND(E5*0.82,0) -> 7 | G306: =$C$1&C306&$D$1&D306&$E$1&E306&$F$1 -> [{"slot":1,"attribute":2,"value":7}, | H306: 2 | I306: 4 | J306: =J5 -> 14 | L306: =$H$1&H306&$I$1&I306&$J$1&J306&$K$1 -> {"slot":2,"attribute":4,"value":14}, | M306: 3 | N306: 5 | O306: =O5 -> 8 | Q306: =$M$1&M306&$N$1&N306&$O$1&O306&$P$1 -> {"slot":3,"attribute":5,"value":8}, | R306: 4 | S306: 2 | T306: =ROUND(T5*0.82,0) -> 5 | V306: =$R$1&R306&$S$1&S306&$T$1&T306&$U$1 -> {"slot":4,"attribute":2,"value":5}, | W306: 5 | X306: 2 | Y306: =ROUND(Y5*0.82,0) -> 3 | AA306: =$W$1&W306&$X$1&X306&$Y$1&Y306&$Z$1 -> {"slot":5,"attribute":2,"value":3}, | AB306: 6 | AC306: 2 | AD306: =ROUND(AD5*0.82,0) -> 3 | AF306: =$AB$1&AB306&$AC$1&AC306&$AD$1&AD306&$AE$1 -> {"slot":6,"attribute":2,"value":3}, | AG306: 7 | AH306: 2 | AI306: =ROUND(AI5*0.82,0) -> 3 | AK306: =$AG$1&AG306&$AH$1&AH306&$AI$1&AI306&$AJ$1 -> {"slot":7,"attribute":2,"value":3}, | AL306: 8 | AM306: 2 | AN306: =ROUND(AN5*0.82,0) -> 3 | AP306: =$AL$1&AL306&$AM$1&AM306&$AN$1&AN306&$AO$1 -> {"slot":8,"attribute":2,"value":3}, | AQ306: 9 | AR306: 4 | AS306: =AS5 -> 6 | AU306: =$AQ$1&AQ306&$AR$1&AR306&$AS$1&AS306&$AT$1 -> {"slot":9,"attribute":4,"value":6}, | AV306: 10 | AW306: 5 | AX306: =AX5 -> 12 | AZ306: =$AV$1&AV306&$AW$1&AW306&$AX$1&AX306&$AY$1 -> {"slot":10,"attribute":5,"value":12}, | BA306: 11 | BB306: 12 | BC306: =ROUND(BC5/3,0) -> 59 | BE306: =$AV$1&BA306&$AW$1&BB306&$AX$1&BC306&$AY$1 -> {"slot":11,"attribute":12,"value":59}, | BF306: 12 | BG306: 12 | BH306: =ROUND(BH5/3,0) -> 59 | BJ306: =$AV$1&BF306&$AW$1&BG306&$AX$1&BH306&$BI$1 -> {"slot":12,"attribute":12,"value":59}]
A307: 2 | B307: 5 | C307: 1 | D307: 2 | E307: =ROUND(E6*0.82,0) -> 8 | G307: =$C$1&C307&$D$1&D307&$E$1&E307&$F$1 -> [{"slot":1,"attribute":2,"value":8}, | H307: 2 | I307: 4 | J307: =J6 -> 17 | L307: =$H$1&H307&$I$1&I307&$J$1&J307&$K$1 -> {"slot":2,"attribute":4,"value":17}, | M307: 3 | N307: 5 | O307: =O6 -> 10 | Q307: =$M$1&M307&$N$1&N307&$O$1&O307&$P$1 -> {"slot":3,"attribute":5,"value":10}, | R307: 4 | S307: 2 | T307: =ROUND(T6*0.82,0) -> 6 | V307: =$R$1&R307&$S$1&S307&$T$1&T307&$U$1 -> {"slot":4,"attribute":2,"value":6}, | W307: 5 | X307: 2 | Y307: =ROUND(Y6*0.82,0) -> 4 | AA307: =$W$1&W307&$X$1&X307&$Y$1&Y307&$Z$1 -> {"slot":5,"attribute":2,"value":4}, | AB307: 6 | AC307: 2 | AD307: =ROUND(AD6*0.82,0) -> 4 | AF307: =$AB$1&AB307&$AC$1&AC307&$AD$1&AD307&$AE$1 -> {"slot":6,"attribute":2,"value":4}, | AG307: 7 | AH307: 2 | AI307: =ROUND(AI6*0.82,0) -> 4 | AK307: =$AG$1&AG307&$AH$1&AH307&$AI$1&AI307&$AJ$1 -> {"slot":7,"attribute":2,"value":4}, | AL307: 8 | AM307: 2 | AN307: =ROUND(AN6*0.82,0) -> 4 | AP307: =$AL$1&AL307&$AM$1&AM307&$AN$1&AN307&$AO$1 -> {"slot":8,"attribute":2,"value":4}, | AQ307: 9 | AR307: 4 | AS307: =AS6 -> 7 | AU307: =$AQ$1&AQ307&$AR$1&AR307&$AS$1&AS307&$AT$1 -> {"slot":9,"attribute":4,"value":7}, | AV307: 10 | AW307: 5 | AX307: =AX6 -> 15 | AZ307: =$AV$1&AV307&$AW$1&AW307&$AX$1&AX307&$AY$1 -> {"slot":10,"attribute":5,"value":15}, | BA307: 11 | BB307: 12 | BC307: =ROUND(BC6/3,0) -> 74 | BE307: =$AV$1&BA307&$AW$1&BB307&$AX$1&BC307&$AY$1 -> {"slot":11,"attribute":12,"value":74}, | BF307: 12 | BG307: 12 | BH307: =ROUND(BH6/3,0) -> 74 | BJ307: =$AV$1&BF307&$AW$1&BG307&$AX$1&BH307&$BI$1 -> {"slot":12,"attribute":12,"value":74}]
A308: 2 | B308: 6 | C308: 1 | D308: 2 | E308: =ROUND(E7*0.82,0) -> 10 | G308: =$C$1&C308&$D$1&D308&$E$1&E308&$F$1 -> [{"slot":1,"attribute":2,"value":10}, | H308: 2 | I308: 4 | J308: =J7 -> 21 | L308: =$H$1&H308&$I$1&I308&$J$1&J308&$K$1 -> {"slot":2,"attribute":4,"value":21}, | M308: 3 | N308: 5 | O308: =O7 -> 12 | Q308: =$M$1&M308&$N$1&N308&$O$1&O308&$P$1 -> {"slot":3,"attribute":5,"value":12}, | R308: 4 | S308: 2 | T308: =ROUND(T7*0.82,0) -> 7 | V308: =$R$1&R308&$S$1&S308&$T$1&T308&$U$1 -> {"slot":4,"attribute":2,"value":7}, | W308: 5 | X308: 2 | Y308: =ROUND(Y7*0.82,0) -> 5 | AA308: =$W$1&W308&$X$1&X308&$Y$1&Y308&$Z$1 -> {"slot":5,"attribute":2,"value":5}, | AB308: 6 | AC308: 2 | AD308: =ROUND(AD7*0.82,0) -> 5 | AF308: =$AB$1&AB308&$AC$1&AC308&$AD$1&AD308&$AE$1 -> {"slot":6,"attribute":2,"value":5}, | AG308: 7 | AH308: 2 | AI308: =ROUND(AI7*0.82,0) -> 5 | AK308: =$AG$1&AG308&$AH$1&AH308&$AI$1&AI308&$AJ$1 -> {"slot":7,"attribute":2,"value":5}, | AL308: 8 | AM308: 2 | AN308: =ROUND(AN7*0.82,0) -> 5 | AP308: =$AL$1&AL308&$AM$1&AM308&$AN$1&AN308&$AO$1 -> {"slot":8,"attribute":2,"value":5}, | AQ308: 9 | AR308: 4 | AS308: =AS7 -> 9 | AU308: =$AQ$1&AQ308&$AR$1&AR308&$AS$1&AS308&$AT$1 -> {"slot":9,"attribute":4,"value":9}, | AV308: 10 | AW308: 5 | AX308: =AX7 -> 18 | AZ308: =$AV$1&AV308&$AW$1&AW308&$AX$1&AX308&$AY$1 -> {"slot":10,"attribute":5,"value":18}, | BA308: 11 | BB308: 12 | BC308: =ROUND(BC7/3,0) -> 89 | BE308: =$AV$1&BA308&$AW$1&BB308&$AX$1&BC308&$AY$1 -> {"slot":11,"attribute":12,"value":89}, | BF308: 12 | BG308: 12 | BH308: =ROUND(BH7/3,0) -> 89 | BJ308: =$AV$1&BF308&$AW$1&BG308&$AX$1&BH308&$BI$1 -> {"slot":12,"attribute":12,"value":89}]
A309: 2 | B309: 7 | C309: 1 | D309: 2 | E309: =ROUND(E8*0.82,0) -> 11 | G309: =$C$1&C309&$D$1&D309&$E$1&E309&$F$1 -> [{"slot":1,"attribute":2,"value":11}, | H309: 2 | I309: 4 | J309: =J8 -> 24 | L309: =$H$1&H309&$I$1&I309&$J$1&J309&$K$1 -> {"slot":2,"attribute":4,"value":24}, | M309: 3 | N309: 5 | O309: =O8 -> 14 | Q309: =$M$1&M309&$N$1&N309&$O$1&O309&$P$1 -> {"slot":3,"attribute":5,"value":14}, | R309: 4 | S309: 2 | T309: =ROUND(T8*0.82,0) -> 8 | V309: =$R$1&R309&$S$1&S309&$T$1&T309&$U$1 -> {"slot":4,"attribute":2,"value":8}, | W309: 5 | X309: 2 | Y309: =ROUND(Y8*0.82,0) -> 6 | AA309: =$W$1&W309&$X$1&X309&$Y$1&Y309&$Z$1 -> {"slot":5,"attribute":2,"value":6}, | AB309: 6 | AC309: 2 | AD309: =ROUND(AD8*0.82,0) -> 6 | AF309: =$AB$1&AB309&$AC$1&AC309&$AD$1&AD309&$AE$1 -> {"slot":6,"attribute":2,"value":6}, | AG309: 7 | AH309: 2 | AI309: =ROUND(AI8*0.82,0) -> 6 | AK309: =$AG$1&AG309&$AH$1&AH309&$AI$1&AI309&$AJ$1 -> {"slot":7,"attribute":2,"value":6}, | AL309: 8 | AM309: 2 | AN309: =ROUND(AN8*0.82,0) -> 6 | AP309: =$AL$1&AL309&$AM$1&AM309&$AN$1&AN309&$AO$1 -> {"slot":8,"attribute":2,"value":6}, | AQ309: 9 | AR309: 4 | AS309: =AS8 -> 10 | AU309: =$AQ$1&AQ309&$AR$1&AR309&$AS$1&AS309&$AT$1 -> {"slot":9,"attribute":4,"value":10}, | AV309: 10 | AW309: 5 | AX309: =AX8 -> 21 | AZ309: =$AV$1&AV309&$AW$1&AW309&$AX$1&AX309&$AY$1 -> {"slot":10,"attribute":5,"value":21}, | BA309: 11 | BB309: 12 | BC309: =ROUND(BC8/3,0) -> 104 | BE309: =$AV$1&BA309&$AW$1&BB309&$AX$1&BC309&$AY$1 -> {"slot":11,"attribute":12,"value":104}, | BF309: 12 | BG309: 12 | BH309: =ROUND(BH8/3,0) -> 104 | BJ309: =$AV$1&BF309&$AW$1&BG309&$AX$1&BH309&$BI$1 -> {"slot":12,"attribute":12,"value":104}]
A310: 2 | B310: 8 | C310: 1 | D310: 2 | E310: =ROUND(E9*0.82,0) -> 13 | G310: =$C$1&C310&$D$1&D310&$E$1&E310&$F$1 -> [{"slot":1,"attribute":2,"value":13}, | H310: 2 | I310: 4 | J310: =J9 -> 28 | L310: =$H$1&H310&$I$1&I310&$J$1&J310&$K$1 -> {"slot":2,"attribute":4,"value":28}, | M310: 3 | N310: 5 | O310: =O9 -> 16 | Q310: =$M$1&M310&$N$1&N310&$O$1&O310&$P$1 -> {"slot":3,"attribute":5,"value":16}, | R310: 4 | S310: 2 | T310: =ROUND(T9*0.82,0) -> 9 | V310: =$R$1&R310&$S$1&S310&$T$1&T310&$U$1 -> {"slot":4,"attribute":2,"value":9}, | W310: 5 | X310: 2 | Y310: =ROUND(Y9*0.82,0) -> 7 | AA310: =$W$1&W310&$X$1&X310&$Y$1&Y310&$Z$1 -> {"slot":5,"attribute":2,"value":7}, | AB310: 6 | AC310: 2 | AD310: =ROUND(AD9*0.82,0) -> 7 | AF310: =$AB$1&AB310&$AC$1&AC310&$AD$1&AD310&$AE$1 -> {"slot":6,"attribute":2,"value":7}, | AG310: 7 | AH310: 2 | AI310: =ROUND(AI9*0.82,0) -> 7 | AK310: =$AG$1&AG310&$AH$1&AH310&$AI$1&AI310&$AJ$1 -> {"slot":7,"attribute":2,"value":7}, | AL310: 8 | AM310: 2 | AN310: =ROUND(AN9*0.82,0) -> 7 | AP310: =$AL$1&AL310&$AM$1&AM310&$AN$1&AN310&$AO$1 -> {"slot":8,"attribute":2,"value":7}, | AQ310: 9 | AR310: 4 | AS310: =AS9 -> 12 | AU310: =$AQ$1&AQ310&$AR$1&AR310&$AS$1&AS310&$AT$1 -> {"slot":9,"attribute":4,"value":12}, | AV310: 10 | AW310: 5 | AX310: =AX9 -> 24 | AZ310: =$AV$1&AV310&$AW$1&AW310&$AX$1&AX310&$AY$1 -> {"slot":10,"attribute":5,"value":24}, | BA310: 11 | BB310: 12 | BC310: =ROUND(BC9/3,0) -> 118 | BE310: =$AV$1&BA310&$AW$1&BB310&$AX$1&BC310&$AY$1 -> {"slot":11,"attribute":12,"value":118}, | BF310: 12 | BG310: 12 | BH310: =ROUND(BH9/3,0) -> 118 | BJ310: =$AV$1&BF310&$AW$1&BG310&$AX$1&BH310&$BI$1 -> {"slot":12,"attribute":12,"value":118}]
A311: 2 | B311: 9 | C311: 1 | D311: 2 | E311: =ROUND(E10*0.82,0) -> 15 | G311: =$C$1&C311&$D$1&D311&$E$1&E311&$F$1 -> [{"slot":1,"attribute":2,"value":15}, | H311: 2 | I311: 4 | J311: =J10 -> 31 | L311: =$H$1&H311&$I$1&I311&$J$1&J311&$K$1 -> {"slot":2,"attribute":4,"value":31}, | M311: 3 | N311: 5 | O311: =O10 -> 18 | Q311: =$M$1&M311&$N$1&N311&$O$1&O311&$P$1 -> {"slot":3,"attribute":5,"value":18}, | R311: 4 | S311: 2 | T311: =ROUND(T10*0.82,0) -> 11 | V311: =$R$1&R311&$S$1&S311&$T$1&T311&$U$1 -> {"slot":4,"attribute":2,"value":11}, | W311: 5 | X311: 2 | Y311: =ROUND(Y10*0.82,0) -> 7 | AA311: =$W$1&W311&$X$1&X311&$Y$1&Y311&$Z$1 -> {"slot":5,"attribute":2,"value":7}, | AB311: 6 | AC311: 2 | AD311: =ROUND(AD10*0.82,0) -> 7 | AF311: =$AB$1&AB311&$AC$1&AC311&$AD$1&AD311&$AE$1 -> {"slot":6,"attribute":2,"value":7}, | AG311: 7 | AH311: 2 | AI311: =ROUND(AI10*0.82,0) -> 7 | AK311: =$AG$1&AG311&$AH$1&AH311&$AI$1&AI311&$AJ$1 -> {"slot":7,"attribute":2,"value":7}, | AL311: 8 | AM311: 2 | AN311: =ROUND(AN10*0.82,0) -> 7 | AP311: =$AL$1&AL311&$AM$1&AM311&$AN$1&AN311&$AO$1 -> {"slot":8,"attribute":2,"value":7}, | AQ311: 9 | AR311: 4 | AS311: =AS10 -> 13 | AU311: =$AQ$1&AQ311&$AR$1&AR311&$AS$1&AS311&$AT$1 -> {"slot":9,"attribute":4,"value":13}, | AV311: 10 | AW311: 5 | AX311: =AX10 -> 27 | AZ311: =$AV$1&AV311&$AW$1&AW311&$AX$1&AX311&$AY$1 -> {"slot":10,"attribute":5,"value":27}, | BA311: 11 | BB311: 12 | BC311: =ROUND(BC10/3,0) -> 133 | BE311: =$AV$1&BA311&$AW$1&BB311&$AX$1&BC311&$AY$1 -> {"slot":11,"attribute":12,"value":133}, | BF311: 12 | BG311: 12 | BH311: =ROUND(BH10/3,0) -> 133 | BJ311: =$AV$1&BF311&$AW$1&BG311&$AX$1&BH311&$BI$1 -> {"slot":12,"attribute":12,"value":133}]
A312: 2 | B312: 10 | C312: 1 | D312: 2 | E312: =ROUND(E11*0.82,0) -> 16 | G312: =$C$1&C312&$D$1&D312&$E$1&E312&$F$1 -> [{"slot":1,"attribute":2,"value":16}, | H312: 2 | I312: 4 | J312: =J11 -> 35 | L312: =$H$1&H312&$I$1&I312&$J$1&J312&$K$1 -> {"slot":2,"attribute":4,"value":35}, | M312: 3 | N312: 5 | O312: =O11 -> 20 | Q312: =$M$1&M312&$N$1&N312&$O$1&O312&$P$1 -> {"slot":3,"attribute":5,"value":20}, | R312: 4 | S312: 2 | T312: =ROUND(T11*0.82,0) -> 11 | V312: =$R$1&R312&$S$1&S312&$T$1&T312&$U$1 -> {"slot":4,"attribute":2,"value":11}, | W312: 5 | X312: 2 | Y312: =ROUND(Y11*0.82,0) -> 8 | AA312: =$W$1&W312&$X$1&X312&$Y$1&Y312&$Z$1 -> {"slot":5,"attribute":2,"value":8}, | AB312: 6 | AC312: 2 | AD312: =ROUND(AD11*0.82,0) -> 8 | AF312: =$AB$1&AB312&$AC$1&AC312&$AD$1&AD312&$AE$1 -> {"slot":6,"attribute":2,"value":8}, | AG312: 7 | AH312: 2 | AI312: =ROUND(AI11*0.82,0) -> 8 | AK312: =$AG$1&AG312&$AH$1&AH312&$AI$1&AI312&$AJ$1 -> {"slot":7,"attribute":2,"value":8}, | AL312: 8 | AM312: 2 | AN312: =ROUND(AN11*0.82,0) -> 8 | AP312: =$AL$1&AL312&$AM$1&AM312&$AN$1&AN312&$AO$1 -> {"slot":8,"attribute":2,"value":8}, | AQ312: 9 | AR312: 4 | AS312: =AS11 -> 15 | AU312: =$AQ$1&AQ312&$AR$1&AR312&$AS$1&AS312&$AT$1 -> {"slot":9,"attribute":4,"value":15}, | AV312: 10 | AW312: 5 | AX312: =AX11 -> 30 | AZ312: =$AV$1&AV312&$AW$1&AW312&$AX$1&AX312&$AY$1 -> {"slot":10,"attribute":5,"value":30}, | BA312: 11 | BB312: 12 | BC312: =ROUND(BC11/3,0) -> 148 | BE312: =$AV$1&BA312&$AW$1&BB312&$AX$1&BC312&$AY$1 -> {"slot":11,"attribute":12,"value":148}, | BF312: 12 | BG312: 12 | BH312: =ROUND(BH11/3,0) -> 148 | BJ312: =$AV$1&BF312&$AW$1&BG312&$AX$1&BH312&$BI$1 -> {"slot":12,"attribute":12,"value":148}]
