Workbook

Sheet Sheet1
A1: 命格等级 | B1: 重数显示 | C1: 级数显示 | D1: 升级经验 | E1: 升级属性 | F1: 进阶消耗 | G1: 进阶属性
A2: int32 | B2: string | C2: string | D2: int32 | E2: json | F2: json | G2: json
A3: FateLevel | B3: Multiplicity | C3: Level | D3: FateExp | E3: UpValue | F3: AdvancedNeed | G3: AdvancedValue
A4: 1 | B4: 0重 | C4: 1级 | D4: 5500
A5: 2 | B5: 0重 | C5: 2级 | D5: 5500 | E5: =配置!O2 -> [{ "key":12,"value":146,"job":1},{ "key":12,"value":37,"job":2}]
A6: 3 | B6: 0重 | C6: 3级 | D6: 5500 | E6: =配置!O3 -> [{ "key":12,"value":235,"job":1},{ "key":12,"value":59,"job":2}]
A7: 4 | B7: 0重 | C7: 4级 | D7: 5500 | E7: =配置!O4 -> [{ "key":12,"value":323,"job":1},{ "key":12,"value":81,"job":2}]
A8: 5 | B8: 0重 | C8: 5级 | D8: 5500 | E8: =配置!O5 -> [{ "key":12,"value":412,"job":1},{ "key":12,"value":103,"job":2}]
A9: 6 | B9: 0重 | C9: 6级 | D9: 5500 | E9: =配置!O6 -> [{ "key":12,"value":501,"job":1},{ "key":12,"value":125,"job":2}]
A10: 7 | B10: 0重 | C10: 7级 | D10: 5500 | E10: =配置!O7 -> [{ "key":12,"value":590,"job":1},{ "key":12,"value":148,"job":2}]
A11: 8 | B11: 0重 | C11: 8级 | D11: 5500 | E11: =配置!O8 -> [{ "key":12,"value":679,"job":1},{ "key":12,"value":170,"job":2}]
A12: 9 | B12: 0重 | C12: 9级 | D12: 5500 | E12: =配置!O9 -> [{ "key":12,"value":767,"job":1},{ "key":12,"value":192,"job":2}]
A13: 10 | B13: 0重 | C13: 10级 | D13: 5500 | E13: =配置!O10 -> [{ "key":12,"value":856,"job":1},{ "key":12,"value":214,"job":2}] | F13: [{ "id": 76,"num": 100},{ "id": 1,"num": 1000000}] | G13: [{ "key": 40,"value": 100}]
A14: 11 | B14: 1重 | C14: 1级 | D14: 15500 | E14: =配置!O11 -> [{ "key":12,"value":1002,"job":1},{ "key":12,"value":251,"job":2}]
A15: 12 | B15: 1重 | C15: 2级 | D15: 15500 | E15: =配置!O12 -> [{ "key":12,"value":1091,"job":1},{ "key":12,"value":273,"job":2}]
A16: 13 | B16: 1重 | C16: 3级 | D16: 15500 | E16: =配置!O13 -> [{ "key":12,"value":1180,"job":1},{ "key":12,"value":295,"job":2}]
A17: 14 | B17: 1重 | C17: 4级 | D17: 15500 | E17: =配置!O14 -> [{ "key":12,"value":1268,"job":1},{ "key":12,"value":317,"job":2}]
A18: 15 | B18: 1重 | C18: 5级 | D18: 15500 | E18: =配置!O15 -> [{ "key":12,"value":1357,"job":1},{ "key":12,"value":339,"job":2}]
A19: 16 | B19: 1重 | C19: 6级 | D19: 15500 | E19: =配置!O16 -> [{ "key":12,"value":1503,"job":1},{ "key":12,"value":376,"job":2}]
A20: 17 | B20: 1重 | C20: 7级 | D20: 15500 | E20: =配置!O17 -> [{ "key":12,"value":1592,"job":1},{ "key":12,"value":398,"job":2}]
A21: 18 | B21: 1重 | C21: 8级 | D21: 15500 | E21: =配置!O18 -> [{ "key":12,"value":1681,"job":1},{ "key":12,"value":420,"job":2}]
A22: 19 | B22: 1重 | C22: 9级 | D22: 15500 | E22: =配置!O19 -> [{ "key":12,"value":1769,"job":1},{ "key":12,"value":442,"job":2}]
A23: 20 | B23: 1重 | C23: 10级 | D23: 15500 | E23: =配置!O20 -> [{ "key":12,"value":1858,"job":1},{ "key":12,"value":465,"job":2}] | F23: [{ "id": 76,"num": 100},{ "id": 1,"num": 1000000}] | G23: [{ "key": 40,"value": 200}]
A24: 21 | B24: 2重 | C24: 1级 | D24: 25500 | E24: =配置!O21 -> [{ "key":12,"value":2504,"job":1},{ "key":12,"value":626,"job":2}]
A25: 22 | B25: 2重 | C25: 2级 | D25: 25500 | E25: =配置!O22 -> [{ "key":12,"value":2615,"job":1},{ "key":12,"value":654,"job":2}]
A26: 23 | B26: 2重 | C26: 3级 | D26: 25500 | E26: =配置!O23 -> [{ "key":12,"value":2726,"job":1},{ "key":12,"value":682,"job":2}]
A27: 24 | B27: 2重 | C27: 4级 | D27: 25500 | E27: =配置!O24 -> [{ "key":12,"value":2837,"job":1},{ "key":12,"value":709,"job":2}]
A28: 25 | B28: 2重 | C28: 5级 | D28: 25500 | E28: =配置!O25 -> [{ "key":12,"value":2948,"job":1},{ "key":12,"value":737,"job":2}]
A29: 26 | B29: 2重 | C29: 6级 | D29: 25500 | E29: =配置!O26 -> [{ "key":12,"value":3130,"job":1},{ "key":12,"value":783,"job":2}]
A30: 27 | B30: 2重 | C30: 7级 | D30: 25500 | E30: =配置!O27 -> [{ "key":12,"value":3241,"job":1},{ "key":12,"value":810,"job":2}]
A31: 28 | B31: 2重 | C31: 8级 | D31: 25500 | E31: =配置!O28 -> [{ "key":12,"value":3352,"job":1},{ "key":12,"value":838,"job":2}]
A32: 29 | B32: 2重 | C32: 9级 | D32: 25500 | E32: =配置!O29 -> [{ "key":12,"value":3463,"job":1},{ "key":12,"value":866,"job":2}]
A33: 30 | B33: 2重 | C33: 10级 | D33: 25500 | E33: =配置!O30 -> [{ "key":12,"value":3574,"job":1},{ "key":12,"value":894,"job":2}] | F33: [{ "id": 76,"num": 100},{ "id": 1,"num": 1000000}] | G33: [{ "key": 40,"value": 300}]
A34: 31 | B34: 3重 | C34: 1级 | D34: 35500 | E34: =配置!O31 -> [{ "key":12,"value":4658,"job":1},{ "key":12,"value":1165,"job":2}]
A35: 32 | B35: 3重 | C35: 2级 | D35: 35500 | E35: =配置!O32 -> [{ "key":12,"value":4796,"job":1},{ "key":12,"value":1199,"job":2}]
A36: 33 | B36: 3重 | C36: 3级 | D36: 35500 | E36: =配置!O33 -> [{ "key":12,"value":4933,"job":1},{ "key":12,"value":1233,"job":2}]
A37: 34 | B37: 3重 | C37: 4级 | D37: 35500 | E37: =配置!O34 -> [{ "key":12,"value":5071,"job":1},{ "key":12,"value":1268,"job":2}]
A38: 35 | B38: 3重 | C38: 5级 | D38: 35500 | E38: =配置!O35 -> [{ "key":12,"value":5209,"job":1},{ "key":12,"value":1302,"job":2}]
A39: 36 | B39: 3重 | C39: 6级 | D39: 35500 | E39: =配置!O36 -> [{ "key":12,"value":5435,"job":1},{ "key":12,"value":1359,"job":2}]
A40: 37 | B40: 3重 | C40: 7级 | D40: 35500 | E40: =配置!O37 -> [{ "key":12,"value":5572,"job":1},{ "key":12,"value":1393,"job":2}]
...

Sheet 配置
A1: 等级 | C1: 属性ID | E1: 战士生命值 | G1: 职业 | I1: 属性ID | K1: 法师生命值 | M1: 职业 | O1: 生成配置
A2: 1 | B2: [{ "key": | C2: 12 | D2: ,"value": | E2: 146 | F2: ,"job": | G2: 1 | H2: },{ "key": | I2: 12 | J2: ,"value": | K2: 37 | L2: ,"job": | M2: 2 | N2: }] | O2: =B2&C2&D2&E2&F2&G2&H2&I2&J2&K2&L2&M2&N2 -> [{ "key":12,"value":146,"job":1},{ "key":12,"value":37,"job":2}]
A3: 2 | B3: [{ "key": | C3: 12 | D3: ,"value": | E3: 235 | F3: ,"job": | G3: 1 | H3: },{ "key": | I3: 12 | J3: ,"value": | K3: 59 | L3: ,"job": | M3: 2 | N3: }] | O3: =B3&C3&D3&E3&F3&G3&H3&I3&J3&K3&L3&M3&N3 -> [{ "key":12,"value":235,"job":1},{ "key":12,"value":59,"job":2}]
A4: 3 | B4: [{ "key": | C4: 12 | D4: ,"value": | E4: 323 | F4: ,"job": | G4: 1 | H4: },{ "key": | I4: 12 | J4: ,"value": | K4: 81 | L4: ,"job": | M4: 2 | N4: }] | O4: =B4&C4&D4&E4&F4&G4&H4&I4&J4&K4&L4&M4&N4 -> [{ "key":12,"value":323,"job":1},{ "key":12,"value":81,"job":2}]
A5: 4 | B5: [{ "key": | C5: 12 | D5: ,"value": | E5: 412 | F5: ,"job": | G5: 1 | H5: },{ "key": | I5: 12 | J5: ,"value": | K5: 103 | L5: ,"job": | M5: 2 | N5: }] | O5: =B5&C5&D5&E5&F5&G5&H5&I5&J5&K5&L5&M5&N5 -> [{ "key":12,"value":412,"job":1},{ "key":12,"value":103,"job":2}]
A6: 5 | B6: [{ "key": | C6: 12 | D6: ,"value": | E6: 501 | F6: ,"job": | G6: 1 | H6: },{ "key": | I6: 12 | J6: ,"value": | K6: 125 | L6: ,"job": | M6: 2 | N6: }] | O6: =B6&C6&D6&E6&F6&G6&H6&I6&J6&K6&L6&M6&N6 -> [{ "key":12,"value":501,"job":1},{ "key":12,"value":125,"job":2}]
A7: 6 | B7: [{ "key": | C7: 12 | D7: ,"value": | E7: 590 | F7: ,"job": | G7: 1 | H7: },{ "key": | I7: 12 | J7: ,"value": | K7: 148 | L7: ,"job": | M7: 2 | N7: }] | O7: =B7&C7&D7&E7&F7&G7&H7&I7&J7&K7&L7&M7&N7 -> [{ "key":12,"value":590,"job":1},{ "key":12,"value":148,"job":2}]
A8: 7 | B8: [{ "key": | C8: 12 | D8: ,"value": | E8: 679 | F8: ,"job": | G8: 1 | H8: },{ "key": | I8: 12 | J8: ,"value": | K8: 170 | L8: ,"job": | M8: 2 | N8: }] | O8: =B8&C8&D8&E8&F8&G8&H8&I8&J8&K8&L8&M8&N8 -> [{ "key":12,"value":679,"job":1},{ "key":12,"value":170,"job":2}]
A9: 8 | B9: [{ "key": | C9: 12 | D9: ,"value": | E9: 767 | F9: ,"job": | G9: 1 | H9: },{ "key": | I9: 12 | J9: ,"value": | K9: 192 | L9: ,"job": | M9: 2 | N9: }] | O9: =B9&C9&D9&E9&F9&G9&H9&I9&J9&K9&L9&M9&N9 -> [{ "key":12,"value":767,"job":1},{ "key":12,"value":192,"job":2}]
A10: 9 | B10: [{ "key": | C10: 12 | D10: ,"value": | E10: 856 | F10: ,"job": | G10: 1 | H10: },{ "key": | I10: 12 | J10: ,"value": | K10: 214 | L10: ,"job": | M10: 2 | N10: }] | O10: =B10&C10&D10&E10&F10&G10&H10&I10&J10&K10&L10&M10&N10 -> [{ "key":12,"value":856,"job":1},{ "key":12,"value":214,"job":2}]
A11: 10 | B11: [{ "key": | C11: 12 | D11: ,"value": | E11: 1002 | F11: ,"job": | G11: 1 | H11: },{ "key": | I11: 12 | J11: ,"value": | K11: 251 | L11: ,"job": | M11: 2 | N11: }] | O11: =B11&C11&D11&E11&F11&G11&H11&I11&J11&K11&L11&M11&N11 -> [{ "key":12,"value":1002,"job":1},{ "key":12,"value":251,"job":2}]
A12: 11 | B12: [{ "key": | C12: 12 | D12: ,"value": | E12: 1091 | F12: ,"job": | G12: 1 | H12: },{ "key": | I12: 12 | J12: ,"value": | K12: 273 | L12: ,"job": | M12: 2 | N12: }] | O12: =B12&C12&D12&E12&F12&G12&H12&I12&J12&K12&L12&M12&N12 -> [{ "key":12,"value":1091,"job":1},{ "key":12,"value":273,"job":2}]
A13: 12 | B13: [{ "key": | C13: 12 | D13: ,"value": | E13: 1180 | F13: ,"job": | G13: 1 | H13: },{ "key": | I13: 12 | J13: ,"value": | K13: 295 | L13: ,"job": | M13: 2 | N13: }] | O13: =B13&C13&D13&E13&F13&G13&H13&I13&J13&K13&L13&M13&N13 -> [{ "key":12,"value":1180,"job":1},{ "key":12,"value":295,"job":2}]
... A151: 150 | B151: [{ "key": | C151: 12 | D151: ,"value": | E151: 48088 | F151: ,"job": | G151: 1 | H151: },{ "key": | I151: 12 | J151: ,"value": | K151: 12022 | L151: ,"job": | M151: 2 | N151: }] | O151: =B151&C151&D151&E151&F151&G151&H151&I151&J151&K151&L151&M151&N151 -> [{ "key":12,"value":48088,"job":1},{ "key":12,"value":12022,"job":2}]
