Workbook

Sheet Sheet1
A1: 行会等级 | B1: 需要经验 | C1: 属性增加 | D1: 特权描述 | E1: 解锁商品数量 | F1: 人数上限
A2: Uint32 | B2: Uint32 | C2: Json | D2: String | E2: Uint32 | F2: Uint32
A3: GuildLevel | B3: NeedEXP | C3: AttributeAdd | D3: PrivilegeDes | E3: WarehouseAdd | F3: MemberNum
A4: 1 | B4: 1000 | C4: =VLOOKUP(A4,属性配置!$A$1:$W$103,23,0) -> [{ "key":1,"value":0},{ "key":2,"value":0},{ "key":4,"value":0},{ "key":5,"value":0},{ "key":12,"value":0}] | E4: 3 | F4: 15 | G4: =ROUND(B4/15/150,3) -> 0.444 | H4: =G4*3 -> 1.332
A5: 2 | B5: 2000 | C5: =VLOOKUP(A5,属性配置!$A$1:$W$103,23,0) -> [{ "key":1,"value":5},{ "key":2,"value":4},{ "key":4,"value":3},{ "key":5,"value":3},{ "key":12,"value":45}] | E5: 3 | F5: 15 | G5: =ROUND(B5/15/150,3) -> 0.889 | H5: =G5*3 -> 2.667
A6: 3 | B6: 3000 | C6: =VLOOKUP(A6,属性配置!$A$1:$W$103,23,0) -> [{ "key":1,"value":6},{ "key":2,"value":4},{ "key":4,"value":4},{ "key":5,"value":4},{ "key":12,"value":60}] | E6: 3 | F6: 15 | G6: =ROUND(B6/15/150,3) -> 1.333 | H6: =G6*3 -> 3.999
A7: 4 | B7: 4000 | C7: =VLOOKUP(A7,属性配置!$A$1:$W$103,23,0) -> [{ "key":1,"value":7},{ "key":2,"value":5},{ "key":4,"value":4},{ "key":5,"value":4},{ "key":12,"value":60}] | E7: 3 | F7: 15 | G7: =ROUND(B7/15/150,3) -> 1.778 | H7: =G7*3 -> 5.334
A8: 5 | B8: 5000 | C8: =VLOOKUP(A8,属性配置!$A$1:$W$103,23,0) -> [{ "key":1,"value":8},{ "key":2,"value":6},{ "key":4,"value":5},{ "key":5,"value":5},{ "key":12,"value":75}] | E8: 4 | F8: 15 | G8: =ROUND(B8/15/150,3) -> 2.222 | H8: =G8*3 -> 6.666
A9: 6 | B9: 6000 | C9: =VLOOKUP(A9,属性配置!$A$1:$W$103,23,0) -> [{ "key":1,"value":9},{ "key":2,"value":7},{ "key":4,"value":6},{ "key":5,"value":6},{ "key":12,"value":90}] | E9: 4 | F9: 15 | G9: =ROUND(B9/15/150,3) -> 2.667 | H9: =G9*3 -> 8.001
A10: 7 | B10: 8000 | C10: =VLOOKUP(A10,属性配置!$A$1:$W$103,23,0) -> [{ "key":1,"value":10},{ "key":2,"value":8},{ "key":4,"value":6},{ "key":5,"value":6},{ "key":12,"value":90}] | E10: 4 | F10: 15 | G10: =ROUND(B10/15/150,3) -> 3.556 | H10: =G10*3 -> 10.668
A11: 8 | B11: 10000 | C11: =VLOOKUP(A11,属性配置!$A$1:$W$103,23,0) -> [{ "key":1,"value":11},{ "key":2,"value":9},{ "key":4,"value":7},{ "key":5,"value":7},{ "key":12,"value":105}] | E11: 4 | F11: 15 | G11: =ROUND(B11/15/150,3) -> 4.444 | H11: =G11*3 -> 13.332
A12: 9 | B12: 12000 | C12: =VLOOKUP(A12,属性配置!$A$1:$W$103,23,0) -> [{ "key":1,"value":12},{ "key":2,"value":9},{ "key":4,"value":8},{ "key":5,"value":8},{ "key":12,"value":120}] | E12: 4 | F12: 15 | G12: =ROUND(B12/15/150,3) -> 5.333 | H12: =G12*3 -> 15.999
A13: 10 | B13: 14000 | C13: =VLOOKUP(A13,属性配置!$A$1:$W$103,23,0) -> [{ "key":1,"value":13},{ "key":2,"value":10},{ "key":4,"value":8},{ "key":5,"value":8},{ "key":12,"value":120}] | D13: 人数上限+1 | E13: 5 | F13: 16 | G13: =ROUND(B13/15/150,3) -> 6.222 | H13: =G13*3 -> 18.666
A14: 11 | B14: 16000 | C14: =VLOOKUP(A14,属性配置!$A$1:$W$103,23,0) -> [{ "key":1,"value":14},{ "key":2,"value":11},{ "key":4,"value":9},{ "key":5,"value":9},{ "key":12,"value":135}] | E14: 5 | F14: 16 | G14: =ROUND(B14/15/150,3) -> 7.111 | H14: =G14*3 -> 21.333
A15: 12 | B15: 19000 | C15: =VLOOKUP(A15,属性配置!$A$1:$W$103,23,0) -> [{ "key":1,"value":15},{ "key":2,"value":12},{ "key":4,"value":10},{ "key":5,"value":10},{ "key":12,"value":150}] | E15: 5 | F15: 16 | G15: =ROUND(B15/15/150,3) -> 8.444 | H15: =G15*3 -> 25.332
A16: 13 | B16: 22000 | C16: =VLOOKUP(A16,属性配置!$A$1:$W$103,23,0) -> [{ "key":1,"value":16},{ "key":2,"value":13},{ "key":4,"value":10},{ "key":5,"value":10},{ "key":12,"value":150}] | E16: 5 | F16: 16 | G16: =ROUND(B16/15/150,3) -> 9.778 | H16: =G16*3 -> 29.334
A17: 14 | B17: 25000 | C17: =VLOOKUP(A17,属性配置!$A$1:$W$103,23,0) -> [{ "key":1,"value":17},{ "key":2,"value":13},{ "key":4,"value":11},{ "key":5,"value":11},{ "key":12,"value":165}] | E17: 5 | F17: 16 | G17: =ROUND(B17/15/150,3) -> 11.111 | H17: =G17*3 -> 33.333
A18: 15 | B18: 28000 | C18: =VLOOKUP(A18,属性配置!$A$1:$W$103,23,0) -> [{ "key":1,"value":18},{ "key":2,"value":14},{ "key":4,"value":12},{ "key":5,"value":12},{ "key":12,"value":180}] | E18: 6 | F18: 16 | G18: =ROUND(B18/15/150,3) -> 12.444 | H18: =G18*3 -> 37.332
A19: 16 | B19: 31000 | C19: =VLOOKUP(A19,属性配置!$A$1:$W$103,23,0) -> [{ "key":1,"value":19},{ "key":2,"value":15},{ "key":4,"value":12},{ "key":5,"value":12},{ "key":12,"value":180}] | E19: 6 | F19: 16 | G19: =ROUND(B19/15/150,3) -> 13.778 | H19: =G19*3 -> 41.334
A20: 17 | B20: 36000 | C20: =VLOOKUP(A20,属性配置!$A$1:$W$103,23,0) -> [{ "key":1,"value":20},{ "key":2,"value":16},{ "key":4,"value":13},{ "key":5,"value":13},{ "key":12,"value":195}] | E20: 6 | F20: 16 | G20: =ROUND(B20/15/150,3) -> 16 | H20: =G20*3 -> 48
A21: 18 | B21: 41000 | C21: =VLOOKUP(A21,属性配置!$A$1:$W$103,23,0) -> [{ "key":1,"value":21},{ "key":2,"value":17},{ "key":4,"value":14},{ "key":5,"value":14},{ "key":12,"value":210}] | E21: 6 | F21: 16 | G21: =ROUND(B21/15/150,3) -> 18.222 | H21: =G21*3 -> 54.666
A22: 19 | B22: 46000 | C22: =VLOOKUP(A22,属性配置!$A$1:$W$103,23,0) -> [{ "key":1,"value":22},{ "key":2,"value":18},{ "key":4,"value":14},{ "key":5,"value":14},{ "key":12,"value":210}] | E22: 6 | F22: 16 | G22: =ROUND(B22/15/150,3) -> 20.444 | H22: =G22*3 -> 61.332
A23: 20 | B23: 51000 | C23: =VLOOKUP(A23,属性配置!$A$1:$W$103,23,0) -> [{ "key":1,"value":23},{ "key":2,"value":18},{ "key":4,"value":15},{ "key":5,"value":15},{ "key":12,"value":225}] | D23: 人数上限+2 | E23: 7 | F23: 17 | G23: =ROUND(B23/15/150,3) -> 22.667 | H23: =G23*3 -> 68.001
A24: 21 | B24: 56000 | C24: =VLOOKUP(A24,属性配置!$A$1:$W$103,23,0) -> [{ "key":1,"value":24},{ "key":2,"value":19},{ "key":4,"value":16},{ "key":5,"value":16},{ "key":12,"value":240}] | E24: 7 | F24: 17 | G24: =ROUND(B24/15/150,3) -> 24.889 | H24: =G24*3 -> 74.667
A25: 22 | B25: 66000 | C25: =VLOOKUP(A25,属性配置!$A$1:$W$103,23,0) -> [{ "key":1,"value":25},{ "key":2,"value":20},{ "key":4,"value":16},{ "key":5,"value":16},{ "key":12,"value":240}] | E25: 7 | F25: 17 | G25: =ROUND(B25/15/150,3) -> 29.333 | H25: =G25*3 -> 87.999
A26: 23 | B26: 76000 | C26: =VLOOKUP(A26,属性配置!$A$1:$W$103,23,0) -> [{ "key":1,"value":26},{ "key":2,"value":21},{ "key":4,"value":17},{ "key":5,"value":17},{ "key":12,"value":255}] | E26: 7 | F26: 17 | G26: =ROUND(B26/15/150,3) -> 33.778 | H26: =G26*3 -> 101.334
A27: 24 | B27: 86000 | C27: =VLOOKUP(A27,属性配置!$A$1:$W$103,23,0) -> [{ "key":1,"value":27},{ "key":2,"value":22},{ "key":4,"value":18},{ "key":5,"value":18},{ "key":12,"value":270}] | E27: 7 | F27: 17 | G27: =ROUND(B27/15/150,3) -> 38.222 | H27: =G27*3 -> 114.666
A28: 25 | B28: 96000 | C28: =VLOOKUP(A28,属性配置!$A$1:$W$103,23,0) -> [{ "key":1,"value":28},{ "key":2,"value":22},{ "key":4,"value":18},{ "key":5,"value":18},{ "key":12,"value":270}] | E28: 8 | F28: 17 | G28: =ROUND(B28/15/150,3) -> 42.667 | H28: =G28*3 -> 128.001
A29: 26 | B29: 106000 | C29: =VLOOKUP(A29,属性配置!$A$1:$W$103,23,0) -> [{ "key":1,"value":29},{ "key":2,"value":23},{ "key":4,"value":19},{ "key":5,"value":19},{ "key":12,"value":285}] | E29: 8 | F29: 17 | G29: =ROUND(B29/15/150,3) -> 47.111 | H29: =G29*3 -> 141.333
A30: 27 | B30: 121000 | C30: =VLOOKUP(A30,属性配置!$A$1:$W$103,23,0) -> [{ "key":1,"value":30},{ "key":2,"value":24},{ "key":4,"value":20},{ "key":5,"value":20},{ "key":12,"value":300}] | E30: 8 | F30: 17 | G30: =ROUND(B30/15/150,3) -> 53.778 | H30: =G30*3 -> 161.334
A31: 28 | B31: 136000 | C31: =VLOOKUP(A31,属性配置!$A$1:$W$103,23,0) -> [{ "key":1,"value":31},{ "key":2,"value":25},{ "key":4,"value":20},{ "key":5,"value":20},{ "key":12,"value":300}] | E31: 8 | F31: 17 | G31: =ROUND(B31/15/150,3) -> 60.444 | H31: =G31*3 -> 181.332
A32: 29 | B32: 151000 | C32: =VLOOKUP(A32,属性配置!$A$1:$W$103,23,0) -> [{ "key":1,"value":32},{ "key":2,"value":26},{ "key":4,"value":21},{ "key":5,"value":21},{ "key":12,"value":315}] | E32: 8 | F32: 17 | G32: =ROUND(B32/15/150,3) -> 67.111 | H32: =G32*3 -> 201.333
A33: 30 | B33: 166000 | C33: =VLOOKUP(A33,属性配置!$A$1:$W$103,23,0) -> [{ "key":1,"value":33},{ "key":2,"value":27},{ "key":4,"value":22},{ "key":5,"value":22},{ "key":12,"value":330}] | D33: 人数上限+3 | E33: 9 | F33: 18 | G33: =ROUND(B33/15/150,3) -> 73.778 | H33: =G33*3 -> 221.334
A34: 31 | B34: 181000 | C34: =VLOOKUP(A34,属性配置!$A$1:$W$103,23,0) -> [{ "key":1,"value":34},{ "key":2,"value":27},{ "key":4,"value":22},{ "key":5,"value":22},{ "key":12,"value":330}] | E34: 9 | F34: 18 | G34: =ROUND(B34/15/150,3) -> 80.444 | H34: =G34*3 -> 241.332
A35: 32 | B35: 201000 | C35: =VLOOKUP(A35,属性配置!$A$1:$W$103,23,0) -> [{ "key":1,"value":35},{ "key":2,"value":28},{ "key":4,"value":23},{ "key":5,"value":23},{ "key":12,"value":345}] | E35: 9 | F35: 18 | G35: =ROUND(B35/15/150,3) -> 89.333 | H35: =G35*3 -> 267.999
A36: 33 | B36: 221000 | C36: =VLOOKUP(A36,属性配置!$A$1:$W$103,23,0) -> [{ "key":1,"value":36},{ "key":2,"value":29},{ "key":4,"value":24},{ "key":5,"value":24},{ "key":12,"value":360}] | E36: 9 | F36: 18 | G36: =ROUND(B36/15/150,3) -> 98.222 | H36: =G36*3 -> 294.666
A37: 34 | B37: 241000 | C37: =VLOOKUP(A37,属性配置!$A$1:$W$103,23,0) -> [{ "key":1,"value":37},{ "key":2,"value":30},{ "key":4,"value":24},{ "key":5,"value":24},{ "key":12,"value":360}] | E37: 9 | F37: 18 | G37: =ROUND(B37/15/150,3) -> 107.111 | H37: =G37*3 -> 321.333
A38: 35 | B38: 261000 | C38: =VLOOKUP(A38,属性配置!$A$1:$W$103,23,0) -> [{ "key":1,"value":38},{ "key":2,"value":31},{ "key":4,"value":25},{ "key":5,"value":25},{ "key":12,"value":375}] | E38: 10 | F38: 18 | G38: =ROUND(B38/15/150,3) -> 116 | H38: =G38*3 -> 348
A39: 36 | B39: 281000 | C39: =VLOOKUP(A39,属性配置!$A$1:$W$103,23,0) -> [{ "key":1,"value":39},{ "key":2,"value":31},{ "key":4,"value":26},{ "key":5,"value":26},{ "key":12,"value":390}] | E39: 10 | F39: 18 | G39: =ROUND(B39/15/150,3) -> 124.889 | H39: =G39*3 -> 374.667
A40: 37 | B40: 311000 | C40: =VLOOKUP(A40,属性配置!$A$1:$W$103,23,0) -> [{ "key":1,"value":40},{ "key":2,"value":32},{ "key":4,"value":26},{ "key":5,"value":26},{ "key":12,"value":390}] | E40: 10 | F40: 18 | G40: =ROUND(B40/15/150,3) -> 138.222 | H40: =G40*3 -> 414.666
...

Sheet 属性配置
A1: 等级 | B1: 前缀1 | C1: 属性1id | D1: 中段1 | E1: 属性1数值 | F1: 前缀2 | G1: 属性2id | H1: 中段2 | I1: 属性2数值 | J1: 前缀3 | K1: 属性3id | L1: 中段3 | M1: 属性3数值 | N1: 前缀4 | O1: 属性4id | P1: 中段4 | Q1: 属性4数值 | R1: 前缀5 | S1: 属性5id | T1: 中段5 | U1: 属性5数值 | V1: 后缀 | W1: 合成
A2: 1 | B2: [{ "key": | C2: 1 | D2: ,"value": | E2: 0 | F2: },{ "key": | G2: 2 | H2: ,"value": | I2: 0 | J2: },{ "key": | K2: 4 | L2: ,"value": | M2: 0 | N2: },{ "key": | O2: 5 | P2: ,"value": | Q2: 0 | R2: },{ "key": | S2: 12 | T2: ,"value": | U2: 0 | V2: }] | W2: =B2&C2&D2&E2&F2&G2&H2&I2&J2&K2&L2&M2&N2&O2&P2&Q2&R2&S2&T2&U2&V2 -> [{ "key":1,"value":0},{ "key":2,"value":0},{ "key":4,"value":0},{ "key":5,"value":0},{ "key":12,"value":0}]
A3: 2 | B3: [{ "key": | C3: 1 | D3: ,"value": | E3: 5 | F3: },{ "key": | G3: 2 | H3: ,"value": | I3: =INT(E3*0.82) -> 4 | J3: },{ "key": | K3: 4 | L3: ,"value": | M3: =INT(E3/1.5) -> 3 | N3: },{ "key": | O3: 5 | P3: ,"value": | Q3: =M3 -> 3 | R3: },{ "key": | S3: 12 | T3: ,"value": | U3: =M3*15 -> 45 | V3: }] | W3: =B3&C3&D3&E3&F3&G3&H3&I3&J3&K3&L3&M3&N3&O3&P3&Q3&R3&S3&T3&U3&V3 -> [{ "key":1,"value":5},{ "key":2,"value":4},{ "key":4,"value":3},{ "key":5,"value":3},{ "key":12,"value":45}]
A4: 3 | B4: [{ "key": | C4: 1 | D4: ,"value": | E4: 6 | F4: },{ "key": | G4: 2 | H4: ,"value": | I4: =INT(E4*0.82) -> 4 | J4: },{ "key": | K4: 4 | L4: ,"value": | M4: =INT(E4/1.5) -> 4 | N4: },{ "key": | O4: 5 | P4: ,"value": | Q4: =M4 -> 4 | R4: },{ "key": | S4: 12 | T4: ,"value": | U4: =M4*15 -> 60 | V4: }] | W4: =B4&C4&D4&E4&F4&G4&H4&I4&J4&K4&L4&M4&N4&O4&P4&Q4&R4&S4&T4&U4&V4 -> [{ "key":1,"value":6},{ "key":2,"value":4},{ "key":4,"value":4},{ "key":5,"value":4},{ "key":12,"value":60}]
A5: 4 | B5: [{ "key": | C5: 1 | D5: ,"value": | E5: 7 | F5: },{ "key": | G5: 2 | H5: ,"value": | I5: =INT(E5*0.82) -> 5 | J5: },{ "key": | K5: 4 | L5: ,"value": | M5: =INT(E5/1.5) -> 4 | N5: },{ "key": | O5: 5 | P5: ,"value": | Q5: =M5 -> 4 | R5: },{ "key": | S5: 12 | T5: ,"value": | U5: =M5*15 -> 60 | V5: }] | W5: =B5&C5&D5&E5&F5&G5&H5&I5&J5&K5&L5&M5&N5&O5&P5&Q5&R5&S5&T5&U5&V5 -> [{ "key":1,"value":7},{ "key":2,"value":5},{ "key":4,"value":4},{ "key":5,"value":4},{ "key":12,"value":60}]
A6: 5 | B6: [{ "key": | C6: 1 | D6: ,"value": | E6: 8 | F6: },{ "key": | G6: 2 | H6: ,"value": | I6: =INT(E6*0.82) -> 6 | J6: },{ "key": | K6: 4 | L6: ,"value": | M6: =INT(E6/1.5) -> 5 | N6: },{ "key": | O6: 5 | P6: ,"value": | Q6: =M6 -> 5 | R6: },{ "key": | S6: 12 | T6: ,"value": | U6: =M6*15 -> 75 | V6: }] | W6: =B6&C6&D6&E6&F6&G6&H6&I6&J6&K6&L6&M6&N6&O6&P6&Q6&R6&S6&T6&U6&V6 -> [{ "key":1,"value":8},{ "key":2,"value":6},{ "key":4,"value":5},{ "key":5,"value":5},{ "key":12,"value":75}]
A7: 6 | B7: [{ "key": | C7: 1 | D7: ,"value": | E7: 9 | F7: },{ "key": | G7: 2 | H7: ,"value": | I7: =INT(E7*0.82) -> 7 | J7: },{ "key": | K7: 4 | L7: ,"value": | M7: =INT(E7/1.5) -> 6 | N7: },{ "key": | O7: 5 | P7: ,"value": | Q7: =M7 -> 6 | R7: },{ "key": | S7: 12 | T7: ,"value": | U7: =M7*15 -> 90 | V7: }] | W7: =B7&C7&D7&E7&F7&G7&H7&I7&J7&K7&L7&M7&N7&O7&P7&Q7&R7&S7&T7&U7&V7 -> [{ "key":1,"value":9},{ "key":2,"value":7},{ "key":4,"value":6},{ "key":5,"value":6},{ "key":12,"value":90}]
A8: 7 | B8: [{ "key": | C8: 1 | D8: ,"value": | E8: 10 | F8: },{ "key": | G8: 2 | H8: ,"value": | I8: =INT(E8*0.82) -> 8 | J8: },{ "key": | K8: 4 | L8: ,"value": | M8: =INT(E8/1.5) -> 6 | N8: },{ "key": | O8: 5 | P8: ,"value": | Q8: =M8 -> 6 | R8: },{ "key": | S8: 12 | T8: ,"value": | U8: =M8*15 -> 90 | V8: }] | W8: =B8&C8&D8&E8&F8&G8&H8&I8&J8&K8&L8&M8&N8&O8&P8&Q8&R8&S8&T8&U8&V8 -> [{ "key":1,"value":10},{ "key":2,"value":8},{ "key":4,"value":6},{ "key":5,"value":6},{ "key":12,"value":90}]
A9: 8 | B9: [{ "key": | C9: 1 | D9: ,"value": | E9: 11 | F9: },{ "key": | G9: 2 | H9: ,"value": | I9: =INT(E9*0.82) -> 9 | J9: },{ "key": | K9: 4 | L9: ,"value": | M9: =INT(E9/1.5) -> 7 | N9: },{ "key": | O9: 5 | P9: ,"value": | Q9: =M9 -> 7 | R9: },{ "key": | S9: 12 | T9: ,"value": | U9: =M9*15 -> 105 | V9: }] | W9: =B9&C9&D9&E9&F9&G9&H9&I9&J9&K9&L9&M9&N9&O9&P9&Q9&R9&S9&T9&U9&V9 -> [{ "key":1,"value":11},{ "key":2,"value":9},{ "key":4,"value":7},{ "key":5,"value":7},{ "key":12,"value":105}]
A10: 9 | B10: [{ "key": | C10: 1 | D10: ,"value": | E10: 12 | F10: },{ "key": | G10: 2 | H10: ,"value": | I10: =INT(E10*0.82) -> 9 | J10: },{ "key": | K10: 4 | L10: ,"value": | M10: =INT(E10/1.5) -> 8 | N10: },{ "key": | O10: 5 | P10: ,"value": | Q10: =M10 -> 8 | R10: },{ "key": | S10: 12 | T10: ,"value": | U10: =M10*15 -> 120 | V10: }] | W10: =B10&C10&D10&E10&F10&G10&H10&I10&J10&K10&L10&M10&N10&O10&P10&Q10&R10&S10&T10&U10&V10 -> [{ "key":1,"value":12},{ "key":2,"value":9},{ "key":4,"value":8},{ "key":5,"value":8},{ "key":12,"value":120}]
A11: 10 | B11: [{ "key": | C11: 1 | D11: ,"value": | E11: 13 | F11: },{ "key": | G11: 2 | H11: ,"value": | I11: =INT(E11*0.82) -> 10 | J11: },{ "key": | K11: 4 | L11: ,"value": | M11: =INT(E11/1.5) -> 8 | N11: },{ "key": | O11: 5 | P11: ,"value": | Q11: =M11 -> 8 | R11: },{ "key": | S11: 12 | T11: ,"value": | U11: =M11*15 -> 120 | V11: }] | W11: =B11&C11&D11&E11&F11&G11&H11&I11&J11&K11&L11&M11&N11&O11&P11&Q11&R11&S11&T11&U11&V11 -> [{ "key":1,"value":13},{ "key":2,"value":10},{ "key":4,"value":8},{ "key":5,"value":8},{ "key":12,"value":120}]
A12: 11 | B12: [{ "key": | C12: 1 | D12: ,"value": | E12: 14 | F12: },{ "key": | G12: 2 | H12: ,"value": | I12: =INT(E12*0.82) -> 11 | J12: },{ "key": | K12: 4 | L12: ,"value": | M12: =INT(E12/1.5) -> 9 | N12: },{ "key": | O12: 5 | P12: ,"value": | Q12: =M12 -> 9 | R12: },{ "key": | S12: 12 | T12: ,"value": | U12: =M12*15 -> 135 | V12: }] | W12: =B12&C12&D12&E12&F12&G12&H12&I12&J12&K12&L12&M12&N12&O12&P12&Q12&R12&S12&T12&U12&V12 -> [{ "key":1,"value":14},{ "key":2,"value":11},{ "key":4,"value":9},{ "key":5,"value":9},{ "key":12,"value":135}]
A13: 12 | B13: [{ "key": | C13: 1 | D13: ,"value": | E13: 15 | F13: },{ "key": | G13: 2 | H13: ,"value": | I13: =INT(E13*0.82) -> 12 | J13: },{ "key": | K13: 4 | L13: ,"value": | M13: =INT(E13/1.5) -> 10 | N13: },{ "key": | O13: 5 | P13: ,"value": | Q13: =M13 -> 10 | R13: },{ "key": | S13: 12 | T13: ,"value": | U13: =M13*15 -> 150 | V13: }] | W13: =B13&C13&D13&E13&F13&G13&H13&I13&J13&K13&L13&M13&N13&O13&P13&Q13&R13&S13&T13&U13&V13 -> [{ "key":1,"value":15},{ "key":2,"value":12},{ "key":4,"value":10},{ "key":5,"value":10},{ "key":12,"value":150}]
A14: 13 | B14: [{ "key": | C14: 1 | D14: ,"value": | E14: 16 | F14: },{ "key": | G14: 2 | H14: ,"value": | I14: =INT(E14*0.82) -> 13 | J14: },{ "key": | K14: 4 | L14: ,"value": | M14: =INT(E14/1.5) -> 10 | N14: },{ "key": | O14: 5 | P14: ,"value": | Q14: =M14 -> 10 | R14: },{ "key": | S14: 12 | T14: ,"value": | U14: =M14*15 -> 150 | V14: }] | W14: =B14&C14&D14&E14&F14&G14&H14&I14&J14&K14&L14&M14&N14&O14&P14&Q14&R14&S14&T14&U14&V14 -> [{ "key":1,"value":16},{ "key":2,"value":13},{ "key":4,"value":10},{ "key":5,"value":10},{ "key":12,"value":150}]
... A101: 100 | B101: [{ "key": | C101: 1 | D101: ,"value": | E101: 103 | F101: },{ "key": | G101: 2 | H101: ,"value": | I101: =INT(E101*0.82) -> 84 | J101: },{ "key": | K101: 4 | L101: ,"value": | M101: =INT(E101/1.5) -> 68 | N101: },{ "key": | O101: 5 | P101: ,"value": | Q101: =M101 -> 68 | R101: },{ "key": | S101: 12 | T101: ,"value": | U101: =M101*15 -> 1020 | V101: }] | W101: =B101&C101&D101&E101&F101&G101&H101&I101&J101&K101&L101&M101&N101&O101&P101&Q101&R101&S101&T101&U101&V101 -> [{ "key":1,"value":103},{ "key":2,"value":84},{ "key":4,"value":68},{ "key":5,"value":68},{ "key":12,"value":1020}]

Sheet Sheet3
