Workbook

Sheet Sheet1
A1: 唯一ID | B1: 类别 | C1: 排名 | D1: 排名奖励
A2: int32 | B2: int32 | C2: int32 | D2: json
A3: UUID | B3: type | C3: rank | D3: award
A4: =B4*10000+C4 -> 10001 | B4: 1 | C4: 1 | D4: [{"5":8000},{"34":1},{"37":1}]
A5: =B5*10000+C5 -> 10002 | B5: 1 | C5: 2 | D5: [{"5":5000},{"33":1},{"36":1}]
A6: =B6*10000+C6 -> 10003 | B6: 1 | C6: 3 | D6: [{"5":2000},{"32":3},{"36":1}]
A7: =B7*10000+C7 -> 10004 | B7: 1 | C7: 4 | D7: [{"5":1000},{"32":2},{"35":5}]
A8: =B8*10000+C8 -> 10005 | B8: 1 | C8: 5 | D8: [{"5":800},{"32":1},{"35":3}]
A9: =B9*10000+C9 -> 10006 | B9: 1 | C9: 6 | D9: [{"5":500},{"31":1},{"35":2}]
A10: =B10*10000+C10 -> 10007 | B10: 1 | C10: 7 | D10: [{"5":500},{"31":1},{"35":2}]
A11: =B11*10000+C11 -> 10008 | B11: 1 | C11: 8 | D11: [{"5":500},{"31":1},{"35":2}]
A12: =B12*10000+C12 -> 10009 | B12: 1 | C12: 9 | D12: [{"5":500},{"31":1},{"35":2}]
A13: =B13*10000+C13 -> 10010 | B13: 1 | C13: 10 | D13: [{"5":500},{"31":1},{"35":2}]
A14: =B14*10000+C14 -> 10011 | B14: 1 | C14: 11 | D14: [{"5":400},{"31":1},{"35":1}]
A15: =B15*10000+C15 -> 10012 | B15: 1 | C15: 12 | D15: [{"5":400},{"31":1},{"35":1}]
... A903: =B903*10000+C903 -> 100100 | B903: 10 | C903: 100 | D903: [{"5":100},{"4":6000},{"35":1}]
A904: =B904*10000+C904 -> 200001 | B904: 20 | C904: =C804 -> 1 | D904: [{"5":1500},{"50013":1},{"87":1}]
A905: =B905*10000+C905 -> 200002 | B905: 20 | C905: =C805 -> 2 | D905: [{"5":1200},{"50014":2},{"86":2}]
A906: =B906*10000+C906 -> 200003 | B906: 20 | C906: =C806 -> 3 | D906: [{"5":1000},{"50014":2},{"86":2}]
A907: =B907*10000+C907 -> 200004 | B907: 20 | C907: =C807 -> 4 | D907: [{"5":800},{"50014":2},{"85":3}]
A908: =B908*10000+C908 -> 200005 | B908: 20 | C908: =C808 -> 5 | D908: [{"5":800},{"50014":2},{"85":3}]
A909: =B909*10000+C909 -> 200006 | B909: 20 | C909: =C809 -> 6 | D909: [{"5":800},{"50014":1},{"85":3}]
A910: =B910*10000+C910 -> 200007 | B910: 20 | C910: =C810 -> 7 | D910: [{"5":800},{"50014":1},{"85":3}]
A911: =B911*10000+C911 -> 200008 | B911: 20 | C911: =C811 -> 8 | D911: [{"5":800},{"50014":1},{"85":3}]
A912: =B912*10000+C912 -> 200009 | B912: 20 | C912: =C812 -> 9 | D912: [{"5":800},{"50014":1},{"85":3}]
A913: =B913*10000+C913 -> 200010 | B913: 20 | C913: =C813 -> 10 | D913: [{"5":800},{"50014":1},{"85":3}]
A914: =B914*10000+C914 -> 200011 | B914: 20 | C914: =C814 -> 11 | D914: [{"5":800},{"50014":1},{"85":3}]
A915: =B915*10000+C915 -> 200012 | B915: 20 | C915: =C815 -> 12 | D915: [{"5":800},{"50014":1},{"85":3}]
... A1003: =B1003*10000+C1003 -> 200100 | B1003: 20 | C1003: =C903 -> 100 | D1003: [{"5":100},{"50016":2},{"85":1}]
A1004: =B1004*10000+C1004 -> 210001 | B1004: 21 | C1004: 1 | D1004: [{"5":500},{"50014":1},{"11":25}]
A1005: =B1005*10000+C1005 -> 210002 | B1005: 21 | C1005: 2 | D1005: [{"5":400},{"50014":1},{"11":15}]
A1006: =B1006*10000+C1006 -> 210003 | B1006: 21 | C1006: 3 | D1006: [{"5":300},{"50015":2},{"11":15}]
A1007: =B1007*10000+C1007 -> 210004 | B1007: 21 | C1007: 4 | D1007: [{"5":200},{"50016":4},{"11":15}]
A1008: =B1008*10000+C1008 -> 210005 | B1008: 21 | C1008: 5 | D1008: [{"5":200},{"50016":4},{"11":15}]
A1009: =B1009*10000+C1009 -> 210006 | B1009: 21 | C1009: 6 | D1009: [{"5":200},{"50016":4},{"11":15}]
A1010: =B1010*10000+C1010 -> 210007 | B1010: 21 | C1010: 7 | D1010: [{"5":200},{"50016":4},{"11":15}]
A1011: =B1011*10000+C1011 -> 210008 | B1011: 21 | C1011: 8 | D1011: [{"5":200},{"50016":4},{"11":15}]
A1012: =B1012*10000+C1012 -> 210009 | B1012: 21 | C1012: 9 | D1012: [{"5":100},{"50016":3},{"11":8}]
A1013: =B1013*10000+C1013 -> 210010 | B1013: 21 | C1013: 10 | D1013: [{"5":100},{"50016":3},{"11":8}]
A1014: =B1014*10000+C1014 -> 210011 | B1014: 21 | C1014: 11 | D1014: [{"5":100},{"50016":3},{"11":8}]
...

Sheet Sheet2

Sheet Sheet3
A1: 战力榜奖励 | O1: 即时赛榜奖励 | Z1: 回合赛榜奖励
A2: 排名 | B2: 周结奖励 | O2: 排名 | P2: 周结奖励 | Z2: 排名 | AA2: 日结奖励 | AG2: 周结奖励
A3: 1 | B3: 无双突破丹 | C3: =VLOOKUP(B3,[1]道具商城!$W:$X,2,FALSE) -> 87 | D3: 1 | E3: 特级升星符 | F3: =VLOOKUP(E3,[1]道具商城!$W:$X,2,FALSE) -> 28 | G3: 3 | H3: 大型经验珠 | I3: =VLOOKUP(H3,[1]道具商城!$W:$X,2,FALSE) -> 32 | J3: 10 | O3: 1 | P3: 技能书卷轴 | Q3: =VLOOKUP(P3,[1]道具商城!$W:$X,2,FALSE) -> 24 | R3: 500 | S3: 书页 | T3: =VLOOKUP(S3,[1]道具商城!$W:$X,2,FALSE) -> 23 | U3: 5000 | Z3: 1 | AA3: 红色伙伴碎片随机箱 | AB3: =VLOOKUP(AA3,[1]道具商城!$W:$X,2,FALSE) -> 63 | AC3: 10 | AD3: 大型宝箱 | AE3: =VLOOKUP(AD3,[1]道具商城!$W:$X,2,FALSE) -> 13 | AF3: 10 | AG3: 金砖 | AH3: =VLOOKUP(AG3,[1]道具商城!$W:$X,2,FALSE) -> 37 | AI3: 5 | AJ3: 强化石 | AK3: =VLOOKUP(AJ3,[1]道具商城!$W:$X,2,FALSE) -> 21 | AL3: 5000
A4: 2 | B4: 完美突破丹 | C4: =VLOOKUP(B4,[1]道具商城!$W:$X,2,FALSE) -> 86 | D4: 2 | E4: 特级升星符 | F4: =VLOOKUP(E4,[1]道具商城!$W:$X,2,FALSE) -> 28 | G4: 2 | H4: 大型经验珠 | I4: =VLOOKUP(H4,[1]道具商城!$W:$X,2,FALSE) -> 32 | J4: 7 | O4: 2 | P4: 技能书卷轴 | Q4: =VLOOKUP(P4,[1]道具商城!$W:$X,2,FALSE) -> 24 | R4: 300 | S4: 书页 | T4: =VLOOKUP(S4,[1]道具商城!$W:$X,2,FALSE) -> 23 | U4: 4000 | Z4: 2 | AA4: 红色伙伴碎片随机箱 | AB4: =VLOOKUP(AA4,[1]道具商城!$W:$X,2,FALSE) -> 63 | AC4: 7 | AD4: 大型宝箱 | AE4: =VLOOKUP(AD4,[1]道具商城!$W:$X,2,FALSE) -> 13 | AF4: 7 | AG4: 金砖 | AH4: =VLOOKUP(AG4,[1]道具商城!$W:$X,2,FALSE) -> 37 | AI4: 4 | AJ4: 强化石 | AK4: =VLOOKUP(AJ4,[1]道具商城!$W:$X,2,FALSE) -> 21 | AL4: 4000
A5: 3 | B5: 完美突破丹 | C5: =VLOOKUP(B5,[1]道具商城!$W:$X,2,FALSE) -> 86 | D5: 1 | E5: 特级升星符 | F5: =VLOOKUP(E5,[1]道具商城!$W:$X,2,FALSE) -> 28 | G5: 1 | H5: 大型经验珠 | I5: =VLOOKUP(H5,[1]道具商城!$W:$X,2,FALSE) -> 32 | J5: 5 | O5: 3 | P5: 技能书卷轴 | Q5: =VLOOKUP(P5,[1]道具商城!$W:$X,2,FALSE) -> 24 | R5: 200 | S5: 书页 | T5: =VLOOKUP(S5,[1]道具商城!$W:$X,2,FALSE) -> 23 | U5: 3000 | Z5: 3 | AA5: 红色伙伴碎片随机箱 | AB5: =VLOOKUP(AA5,[1]道具商城!$W:$X,2,FALSE) -> 63 | AC5: 5 | AD5: 大型宝箱 | AE5: =VLOOKUP(AD5,[1]道具商城!$W:$X,2,FALSE) -> 13 | AF5: 5 | AG5: 金砖 | AH5: =VLOOKUP(AG5,[1]道具商城!$W:$X,2,FALSE) -> 37 | AI5: 3 | AJ5: 强化石 | AK5: =VLOOKUP(AJ5,[1]道具商城!$W:$X,2,FALSE) -> 21 | AL5: 3000
A6: 4 | B6: 稀有突破丹 | C6: =VLOOKUP(B6,[1]道具商城!$W:$X,2,FALSE) -> 85 | D6: 2 | E6: 高级升星符 | F6: =VLOOKUP(E6,[1]道具商城!$W:$X,2,FALSE) -> 27 | G6: 1 | H6: 大型经验珠 | I6: =VLOOKUP(H6,[1]道具商城!$W:$X,2,FALSE) -> 32 | J6: 3 | O6: 4 | P6: 技能书卷轴 | Q6: =VLOOKUP(P6,[1]道具商城!$W:$X,2,FALSE) -> 24 | R6: 100 | S6: 书页 | T6: =VLOOKUP(S6,[1]道具商城!$W:$X,2,FALSE) -> 23 | U6: 2000 | Z6: 4 | AA6: 红色伙伴碎片随机箱 | AB6: =VLOOKUP(AA6,[1]道具商城!$W:$X,2,FALSE) -> 63 | AC6: 3 | AD6: 大型宝箱 | AE6: =VLOOKUP(AD6,[1]道具商城!$W:$X,2,FALSE) -> 13 | AF6: 3 | AG6: 金砖 | AH6: =VLOOKUP(AG6,[1]道具商城!$W:$X,2,FALSE) -> 37 | AI6: 2 | AJ6: 强化石 | AK6: =VLOOKUP(AJ6,[1]道具商城!$W:$X,2,FALSE) -> 21 | AL6: 2000
A7: 5 | B7: 稀有突破丹 | C7: =VLOOKUP(B7,[1]道具商城!$W:$X,2,FALSE) -> 85 | D7: 1 | E7: 高级升星符 | F7: =VLOOKUP(E7,[1]道具商城!$W:$X,2,FALSE) -> 27 | G7: 1 | H7: 大型经验珠 | I7: =VLOOKUP(H7,[1]道具商城!$W:$X,2,FALSE) -> 32 | J7: 2 | O7: 5 | P7: 技能书卷轴 | Q7: =VLOOKUP(P7,[1]道具商城!$W:$X,2,FALSE) -> 24 | R7: 100 | S7: 书页 | T7: =VLOOKUP(S7,[1]道具商城!$W:$X,2,FALSE) -> 23 | U7: 1000 | Z7: 5 | AA7: 红色伙伴碎片随机箱 | AB7: =VLOOKUP(AA7,[1]道具商城!$W:$X,2,FALSE) -> 63 | AC7: 1 | AD7: 大型宝箱 | AE7: =VLOOKUP(AD7,[1]道具商城!$W:$X,2,FALSE) -> 13 | AF7: 1 | AG7: 金砖 | AH7: =VLOOKUP(AG7,[1]道具商城!$W:$X,2,FALSE) -> 37 | AI7: 1 | AJ7: 强化石 | AK7: =VLOOKUP(AJ7,[1]道具商城!$W:$X,2,FALSE) -> 21 | AL7: 1000
A8: 6 | B8: 普通突破丹 | C8: =VLOOKUP(B8,[1]道具商城!$W:$X,2,FALSE) -> 84 | D8: 3 | E8: 高级升星符 | F8: =VLOOKUP(E8,[1]道具商城!$W:$X,2,FALSE) -> 27 | G8: 1 | H8: 大型经验珠 | I8: =VLOOKUP(H8,[1]道具商城!$W:$X,2,FALSE) -> 32 | J8: 1 | O8: 6 | P8: 技能书卷轴 | Q8: =VLOOKUP(P8,[1]道具商城!$W:$X,2,FALSE) -> 24 | R8: 70 | S8: 书页 | T8: =VLOOKUP(S8,[1]道具商城!$W:$X,2,FALSE) -> 23 | U8: 800 | Z8: 6 | AA8: 橙色伙伴碎片随机箱 | AB8: =VLOOKUP(AA8,[1]道具商城!$W:$X,2,FALSE) -> 62 | AC8: 3 | AD8: 中型宝箱 | AE8: =VLOOKUP(AD8,[1]道具商城!$W:$X,2,FALSE) -> 12 | AF8: 1 | AG8: 金条 | AH8: =VLOOKUP(AG8,[1]道具商城!$W:$X,2,FALSE) -> 36 | AI8: 3 | AJ8: 强化石 | AK8: =VLOOKUP(AJ8,[1]道具商城!$W:$X,2,FALSE) -> 21 | AL8: 700
A9: 7 | B9: 普通突破丹 | C9: =VLOOKUP(B9,[1]道具商城!$W:$X,2,FALSE) -> 84 | D9: 3 | E9: 高级升星符 | F9: =VLOOKUP(E9,[1]道具商城!$W:$X,2,FALSE) -> 27 | G9: 1 | H9: 大型经验珠 | I9: =VLOOKUP(H9,[1]道具商城!$W:$X,2,FALSE) -> 32 | J9: 1 | O9: 7 | P9: 技能书卷轴 | Q9: =VLOOKUP(P9,[1]道具商城!$W:$X,2,FALSE) -> 24 | R9: 70 | S9: 书页 | T9: =VLOOKUP(S9,[1]道具商城!$W:$X,2,FALSE) -> 23 | U9: 800 | Z9: 7 | AA9: 橙色伙伴碎片随机箱 | AB9: =VLOOKUP(AA9,[1]道具商城!$W:$X,2,FALSE) -> 62 | AC9: 3 | AD9: 中型宝箱 | AE9: =VLOOKUP(AD9,[1]道具商城!$W:$X,2,FALSE) -> 12 | AF9: 1 | AG9: 金条 | AH9: =VLOOKUP(AG9,[1]道具商城!$W:$X,2,FALSE) -> 36 | AI9: 3 | AJ9: 强化石 | AK9: =VLOOKUP(AJ9,[1]道具商城!$W:$X,2,FALSE) -> 21 | AL9: 700
A10: 8 | B10: 普通突破丹 | C10: =VLOOKUP(B10,[1]道具商城!$W:$X,2,FALSE) -> 84 | D10: 3 | E10: 高级升星符 | F10: =VLOOKUP(E10,[1]道具商城!$W:$X,2,FALSE) -> 27 | G10: 1 | H10: 大型经验珠 | I10: =VLOOKUP(H10,[1]道具商城!$W:$X,2,FALSE) -> 32 | J10: 1 | O10: 8 | P10: 技能书卷轴 | Q10: =VLOOKUP(P10,[1]道具商城!$W:$X,2,FALSE) -> 24 | R10: 70 | S10: 书页 | T10: =VLOOKUP(S10,[1]道具商城!$W:$X,2,FALSE) -> 23 | U10: 800 | Z10: 8 | AA10: 橙色伙伴碎片随机箱 | AB10: =VLOOKUP(AA10,[1]道具商城!$W:$X,2,FALSE) -> 62 | AC10: 3 | AD10: 中型宝箱 | AE10: =VLOOKUP(AD10,[1]道具商城!$W:$X,2,FALSE) -> 12 | AF10: 1 | AG10: 金条 | AH10: =VLOOKUP(AG10,[1]道具商城!$W:$X,2,FALSE) -> 36 | AI10: 3 | AJ10: 强化石 | AK10: =VLOOKUP(AJ10,[1]道具商城!$W:$X,2,FALSE) -> 21 | AL10: 700
A11: 9 | B11: 普通突破丹 | C11: =VLOOKUP(B11,[1]道具商城!$W:$X,2,FALSE) -> 84 | D11: 3 | E11: 高级升星符 | F11: =VLOOKUP(E11,[1]道具商城!$W:$X,2,FALSE) -> 27 | G11: 1 | H11: 大型经验珠 | I11: =VLOOKUP(H11,[1]道具商城!$W:$X,2,FALSE) -> 32 | J11: 1 | O11: 9 | P11: 技能书卷轴 | Q11: =VLOOKUP(P11,[1]道具商城!$W:$X,2,FALSE) -> 24 | R11: 70 | S11: 书页 | T11: =VLOOKUP(S11,[1]道具商城!$W:$X,2,FALSE) -> 23 | U11: 800 | Z11: 9 | AA11: 橙色伙伴碎片随机箱 | AB11: =VLOOKUP(AA11,[1]道具商城!$W:$X,2,FALSE) -> 62 | AC11: 3 | AD11: 中型宝箱 | AE11: =VLOOKUP(AD11,[1]道具商城!$W:$X,2,FALSE) -> 12 | AF11: 1 | AG11: 金条 | AH11: =VLOOKUP(AG11,[1]道具商城!$W:$X,2,FALSE) -> 36 | AI11: 3 | AJ11: 强化石 | AK11: =VLOOKUP(AJ11,[1]道具商城!$W:$X,2,FALSE) -> 21 | AL11: 700
A12: 10 | B12: 普通突破丹 | C12: =VLOOKUP(B12,[1]道具商城!$W:$X,2,FALSE) -> 84 | D12: 3 | E12: 高级升星符 | F12: =VLOOKUP(E12,[1]道具商城!$W:$X,2,FALSE) -> 27 | G12: 1 | H12: 大型经验珠 | I12: =VLOOKUP(H12,[1]道具商城!$W:$X,2,FALSE) -> 32 | J12: 1 | O12: 10 | P12: 技能书卷轴 | Q12: =VLOOKUP(P12,[1]道具商城!$W:$X,2,FALSE) -> 24 | R12: 70 | S12: 书页 | T12: =VLOOKUP(S12,[1]道具商城!$W:$X,2,FALSE) -> 23 | U12: 800 | Z12: 10 | AA12: 橙色伙伴碎片随机箱 | AB12: =VLOOKUP(AA12,[1]道具商城!$W:$X,2,FALSE) -> 62 | AC12: 3 | AD12: 中型宝箱 | AE12: =VLOOKUP(AD12,[1]道具商城!$W:$X,2,FALSE) -> 12 | AF12: 1 | AG12: 金条 | AH12: =VLOOKUP(AG12,[1]道具商城!$W:$X,2,FALSE) -> 36 | AI12: 3 | AJ12: 强化石 | AK12: =VLOOKUP(AJ12,[1]道具商城!$W:$X,2,FALSE) -> 21 | AL12: 700
A13: 11 | B13: 普通突破丹 | C13: =VLOOKUP(B13,[1]道具商城!$W:$X,2,FALSE) -> 84 | D13: 2 | E13: 中级升星符 | F13: =VLOOKUP(E13,[1]道具商城!$W:$X,2,FALSE) -> 26 | G13: 1 | H13: 中型经验珠 | I13: =VLOOKUP(H13,[1]道具商城!$W:$X,2,FALSE) -> 31 | J13: 1 | O13: 11 | P13: 技能书卷轴 | Q13: =VLOOKUP(P13,[1]道具商城!$W:$X,2,FALSE) -> 24 | R13: 50 | S13: 书页 | T13: =VLOOKUP(S13,[1]道具商城!$W:$X,2,FALSE) -> 23 | U13: 600 | Z13: 11 | AA13: 橙色伙伴碎片随机箱 | AB13: =VLOOKUP(AA13,[1]道具商城!$W:$X,2,FALSE) -> 62 | AC13: 1 | AD13: 中型宝箱 | AE13: =VLOOKUP(AD13,[1]道具商城!$W:$X,2,FALSE) -> 12 | AF13: 1 | AG13: 金条 | AH13: =VLOOKUP(AG13,[1]道具商城!$W:$X,2,FALSE) -> 36 | AI13: 2 | AJ13: 强化石 | AK13: =VLOOKUP(AJ13,[1]道具商城!$W:$X,2,FALSE) -> 21 | AL13: 500
A14: 12 | B14: 普通突破丹 | C14: =VLOOKUP(B14,[1]道具商城!$W:$X,2,FALSE) -> 84 | D14: 2 | E14: 中级升星符 | F14: =VLOOKUP(E14,[1]道具商城!$W:$X,2,FALSE) -> 26 | G14: 1 | H14: 中型经验珠 | I14: =VLOOKUP(H14,[1]道具商城!$W:$X,2,FALSE) -> 31 | J14: 1 | O14: 12 | P14: 技能书卷轴 | Q14: =VLOOKUP(P14,[1]道具商城!$W:$X,2,FALSE) -> 24 | R14: 50 | S14: 书页 | T14: =VLOOKUP(S14,[1]道具商城!$W:$X,2,FALSE) -> 23 | U14: 600 | Z14: 12 | AA14: 橙色伙伴碎片随机箱 | AB14: =VLOOKUP(AA14,[1]道具商城!$W:$X,2,FALSE) -> 62 | AC14: 1 | AD14: 中型宝箱 | AE14: =VLOOKUP(AD14,[1]道具商城!$W:$X,2,FALSE) -> 12 | AF14: 1 | AG14: 金条 | AH14: =VLOOKUP(AG14,[1]道具商城!$W:$X,2,FALSE) -> 36 | AI14: 2 | AJ14: 强化石 | AK14: =VLOOKUP(AJ14,[1]道具商城!$W:$X,2,FALSE) -> 21 | AL14: 500
... A102: 100 | B102: 普通突破丹 | C102: =VLOOKUP(B102,[1]道具商城!$W:$X,2,FALSE) -> 84 | D102: 1 | E102: 初级升星符 | F102: =VLOOKUP(E102,[1]道具商城!$W:$X,2,FALSE) -> 25 | G102: 1 | H102: 小型经验珠 | I102: =VLOOKUP(H102,[1]道具商城!$W:$X,2,FALSE) -> 30 | J102: 2 | O102: 100 | P102: 技能书卷轴 | Q102: =VLOOKUP(P102,[1]道具商城!$W:$X,2,FALSE) -> 24 | R102: 30 | S102: 书页 | T102: =VLOOKUP(S102,[1]道具商城!$W:$X,2,FALSE) -> 23 | U102: 400 | Z102: 100 | AA102: 紫色伙伴碎片随机箱 | AB102: =VLOOKUP(AA102,[1]道具商城!$W:$X,2,FALSE) -> 61 | AC102: 1 | AD102: 中型宝箱 | AE102: =VLOOKUP(AD102,[1]道具商城!$W:$X,2,FALSE) -> 12 | AF102: 1 | AG102: 金条 | AH102: =VLOOKUP(AG102,[1]道具商城!$W:$X,2,FALSE) -> 36 | AI102: 1 | AJ102: 强化石 | AK102: =VLOOKUP(AJ102,[1]道具商城!$W:$X,2,FALSE) -> 21 | AL102: 150
