Workbook

Sheet Sheet1
A1: 唯一ID | B1: 等级 | C1: 所需经验 | D1: 职业区分 | E1: 基础属性
A2: int32 | B2: int32 | C2: int32 | D2: int32 | E2: json
A3: UID | B3: Level | C3: NeedEXP | D3: job | E3: WarriorBassProperty
A4: =D4*1000+B4 -> 1001 | B4: 1 | C4: 1000 | D4: 1 | E4: =主角属性配置!N2 -> [{"1":40},{"4":26},{"5":26},{"12":476},{"7":8},{"6":0},{"8":10},{"9":0}]
A5: =D5*1000+B5 -> 1002 | B5: 2 | C5: 1500 | D5: 1 | E5: =主角属性配置!N3 -> [{"1":40},{"4":26},{"5":26},{"12":552},{"7":8},{"6":0},{"8":10},{"9":0}]
A6: =D6*1000+B6 -> 1003 | B6: 3 | C6: 2500 | D6: 1 | E6: =主角属性配置!N4 -> [{"1":40},{"4":26},{"5":26},{"12":628},{"7":8},{"6":0},{"8":10},{"9":0}]
A7: =D7*1000+B7 -> 1004 | B7: 4 | C7: 4000 | D7: 1 | E7: =主角属性配置!N5 -> [{"1":40},{"4":26},{"5":26},{"12":704},{"7":8},{"6":0},{"8":10},{"9":0}]
A8: =D8*1000+B8 -> 1005 | B8: 5 | C8: 6000 | D8: 1 | E8: =主角属性配置!N6 -> [{"1":40},{"4":26},{"5":26},{"12":779},{"7":8},{"6":0},{"8":10},{"9":0}]
A9: =D9*1000+B9 -> 1006 | B9: 6 | C9: 8500 | D9: 1 | E9: =主角属性配置!N7 -> [{"1":40},{"4":26},{"5":26},{"12":855},{"7":8},{"6":0},{"8":10},{"9":0}]
A10: =D10*1000+B10 -> 1007 | B10: 7 | C10: 11500 | D10: 1 | E10: =主角属性配置!N8 -> [{"1":40},{"4":26},{"5":26},{"12":931},{"7":8},{"6":0},{"8":10},{"9":0}]
A11: =D11*1000+B11 -> 1008 | B11: 8 | C11: 15000 | D11: 1 | E11: =主角属性配置!N9 -> [{"1":40},{"4":26},{"5":26},{"12":1007},{"7":8},{"6":0},{"8":10},{"9":0}]
A12: =D12*1000+B12 -> 1009 | B12: 9 | C12: 19000 | D12: 1 | E12: =主角属性配置!N10 -> [{"1":40},{"4":26},{"5":26},{"12":1083},{"7":8},{"6":0},{"8":10},{"9":0}]
A13: =D13*1000+B13 -> 1010 | B13: 10 | C13: 23500 | D13: 1 | E13: =主角属性配置!N11 -> [{"1":42},{"4":27},{"5":27},{"12":1159},{"7":8},{"6":0},{"8":10},{"9":0}]
A14: =D14*1000+B14 -> 1011 | B14: 11 | C14: 29000 | D14: 1 | E14: =主角属性配置!N12 -> [{"1":42},{"4":27},{"5":27},{"12":1235},{"7":8},{"6":0},{"8":10},{"9":0}]
A15: =D15*1000+B15 -> 1012 | B15: 12 | C15: 35500 | D15: 1 | E15: =主角属性配置!N13 -> [{"1":42},{"4":27},{"5":27},{"12":1311},{"7":8},{"6":0},{"8":10},{"9":0}]
... A153: =D153*1000+B153 -> 1150 | B153: 150 | C153: 103978118500 | D153: 1 | E153: =主角属性配置!N151 -> [{"1":71},{"4":47},{"5":47},{"12":48217},{"7":8},{"6":0},{"8":10},{"9":0}]
A154: =D154*1000+B154 -> 2001 | B154: =B4 -> 1 | C154: =C4 -> 1000 | D154: 2 | E154: =主角属性配置!W2 -> [{"2":32},{"4":26},{"5":26},{"12":158},{"7":8},{"6":0},{"8":10},{"9":0}]
A155: =D155*1000+B155 -> 2002 | B155: =B5 -> 2 | C155: =C5 -> 1500 | D155: 2 | E155: =主角属性配置!W3 -> [{"2":32},{"4":26},{"5":26},{"12":184},{"7":8},{"6":0},{"8":10},{"9":0}]
A156: =D156*1000+B156 -> 2003 | B156: =B6 -> 3 | C156: =C6 -> 2500 | D156: 2 | E156: =主角属性配置!W4 -> [{"2":32},{"4":26},{"5":26},{"12":209},{"7":8},{"6":0},{"8":10},{"9":0}]
A157: =D157*1000+B157 -> 2004 | B157: =B7 -> 4 | C157: =C7 -> 4000 | D157: 2 | E157: =主角属性配置!W5 -> [{"2":32},{"4":26},{"5":26},{"12":234},{"7":8},{"6":0},{"8":10},{"9":0}]
A158: =D158*1000+B158 -> 2005 | B158: =B8 -> 5 | C158: =C8 -> 6000 | D158: 2 | E158: =主角属性配置!W6 -> [{"2":32},{"4":26},{"5":26},{"12":259},{"7":8},{"6":0},{"8":10},{"9":0}]
A159: =D159*1000+B159 -> 2006 | B159: =B9 -> 6 | C159: =C9 -> 8500 | D159: 2 | E159: =主角属性配置!W7 -> [{"2":32},{"4":26},{"5":26},{"12":285},{"7":8},{"6":0},{"8":10},{"9":0}]
A160: =D160*1000+B160 -> 2007 | B160: =B10 -> 7 | C160: =C10 -> 11500 | D160: 2 | E160: =主角属性配置!W8 -> [{"2":32},{"4":26},{"5":26},{"12":310},{"7":8},{"6":0},{"8":10},{"9":0}]
A161: =D161*1000+B161 -> 2008 | B161: =B11 -> 8 | C161: =C11 -> 15000 | D161: 2 | E161: =主角属性配置!W9 -> [{"2":32},{"4":26},{"5":26},{"12":335},{"7":8},{"6":0},{"8":10},{"9":0}]
A162: =D162*1000+B162 -> 2009 | B162: =B12 -> 9 | C162: =C12 -> 19000 | D162: 2 | E162: =主角属性配置!W10 -> [{"2":32},{"4":26},{"5":26},{"12":361},{"7":8},{"6":0},{"8":10},{"9":0}]
A163: =D163*1000+B163 -> 2010 | B163: =B13 -> 10 | C163: =C13 -> 23500 | D163: 2 | E163: =主角属性配置!W11 -> [{"2":34},{"4":27},{"5":27},{"12":386},{"7":8},{"6":0},{"8":10},{"9":0}]
A164: =D164*1000+B164 -> 2011 | B164: =B14 -> 11 | C164: =C14 -> 29000 | D164: 2 | E164: =主角属性配置!W12 -> [{"2":34},{"4":27},{"5":27},{"12":411},{"7":8},{"6":0},{"8":10},{"9":0}]
A165: =D165*1000+B165 -> 2012 | B165: =B15 -> 12 | C165: =C15 -> 35500 | D165: 2 | E165: =主角属性配置!W13 -> [{"2":34},{"4":27},{"5":27},{"12":437},{"7":8},{"6":0},{"8":10},{"9":0}]
... A303: =D303*1000+B303 -> 2150 | B303: =B153 -> 150 | C303: =C153 -> 103978118500 | D303: 2 | E303: =主角属性配置!W151 -> [{"2":58},{"4":47},{"5":47},{"12":16072},{"7":8},{"6":0},{"8":10},{"9":0}]
A304: =D304*1000+B304 -> 3001 | B304: =B154 -> 1 | C304: =C154 -> 1000 | D304: 3 | E304: =主角属性配置!AE2 -> [{"2":32},{"4":26},{"5":26},{"12":238},{"7":8},{"6":0},{"8":10},{"9":0}]
A305: =D305*1000+B305 -> 3002 | B305: =B155 -> 2 | C305: =C155 -> 1500 | D305: 3 | E305: =主角属性配置!AE3 -> [{"2":32},{"4":26},{"5":26},{"12":276},{"7":8},{"6":0},{"8":10},{"9":0}]
A306: =D306*1000+B306 -> 3003 | B306: =B156 -> 3 | C306: =C156 -> 2500 | D306: 3 | E306: =主角属性配置!AE4 -> [{"2":32},{"4":26},{"5":26},{"12":314},{"7":8},{"6":0},{"8":10},{"9":0}]
A307: =D307*1000+B307 -> 3004 | B307: =B157 -> 4 | C307: =C157 -> 4000 | D307: 3 | E307: =主角属性配置!AE5 -> [{"2":32},{"4":26},{"5":26},{"12":352},{"7":8},{"6":0},{"8":10},{"9":0}]
A308: =D308*1000+B308 -> 3005 | B308: =B158 -> 5 | C308: =C158 -> 6000 | D308: 3 | E308: =主角属性配置!AE6 -> [{"2":32},{"4":26},{"5":26},{"12":390},{"7":8},{"6":0},{"8":10},{"9":0}]
A309: =D309*1000+B309 -> 3006 | B309: =B159 -> 6 | C309: =C159 -> 8500 | D309: 3 | E309: =主角属性配置!AE7 -> [{"2":32},{"4":26},{"5":26},{"12":428},{"7":8},{"6":0},{"8":10},{"9":0}]
A310: =D310*1000+B310 -> 3007 | B310: =B160 -> 7 | C310: =C160 -> 11500 | D310: 3 | E310: =主角属性配置!AE8 -> [{"2":32},{"4":26},{"5":26},{"12":466},{"7":8},{"6":0},{"8":10},{"9":0}]
A311: =D311*1000+B311 -> 3008 | B311: =B161 -> 8 | C311: =C161 -> 15000 | D311: 3 | E311: =主角属性配置!AE9 -> [{"2":32},{"4":26},{"5":26},{"12":504},{"7":8},{"6":0},{"8":10},{"9":0}]
A312: =D312*1000+B312 -> 3009 | B312: =B162 -> 9 | C312: =C162 -> 19000 | D312: 3 | E312: =主角属性配置!AE10 -> [{"2":32},{"4":26},{"5":26},{"12":542},{"7":8},{"6":0},{"8":10},{"9":0}]
A313: =D313*1000+B313 -> 3010 | B313: =B163 -> 10 | C313: =C163 -> 23500 | D313: 3 | E313: =主角属性配置!AE11 -> [{"2":34},{"4":27},{"5":27},{"12":580},{"7":8},{"6":0},{"8":10},{"9":0}]
A314: =D314*1000+B314 -> 3011 | B314: =B164 -> 11 | C314: =C164 -> 29000 | D314: 3 | E314: =主角属性配置!AE12 -> [{"2":34},{"4":27},{"5":27},{"12":618},{"7":8},{"6":0},{"8":10},{"9":0}]
...

Sheet 主角属性配置
A1: 等级 | B1: 物理攻击 | C1: 魔法攻击 | D1: 物理防御 | E1: 魔法防御 | F1: 战士生命值 | G1: 命中 | H1: 闪避 | I1: 暴击值 | J1: 韧性值 | K1: 法师生命值 | L1: 祭祀生命值 | N1: [ | O1: ] | P1: { | Q1: } | R1: : | S1: , | T1: " | U1: " | W1: 法师配置 | AE1: 祭祀配置 | AG1: 攻击 | AH1: 物防 | AI1: 魔防 | AJ1: 生命 | AK1: 魔躲 | AL1: 命中 | AM1: 闪避 | AN1: 暴击 | AP1: 基础攻击 | AQ1: 基础物防 | AR1: 基础魔防 | AS1: 基础生命 | AT1: 基础命中 | AU1: 基础闪避 | AV1: 基础暴击
A2: 0 | B2: 1 | C2: 2 | D2: 4 | E2: 5 | F2: 12 | G2: 7 | H2: 6 | I2: 8 | J2: 9 | K2: =INT(F2/4) -> 3 | N2: =$N$1&$P$1&$T$1&$B$2&$T$1&$R$1&B3&$Q$1&$S$1&$P$1&$T$1&$D$2&$T$1&$R$1&D3&$Q$1&$S$1&$P$1&$T$1&$E$2&$T$1&$R$1&E3&$Q$1&$S$1&$P$1&$T$1&$F$2&$T$1&$R$1&F3&$Q$1&$S$1&$P$1&$T$1&$G$2&$T$1&$R$1&G3&$Q$1&$S$1&$P$1&$T$1&$H$2&$T$1&$R$1&H3&$Q$1&$S$1&$P$1&$T$1&$I$2&$T$1&$R$1&I3&$Q$1&$S$1&$P$1&$T$1&$J$2&$T$1&$R$1&J3&$Q$1&$O$1 -> [{"1":40},{"4":26},{"5":26},{"12":476},{"7":8},{"6":0},{"8":10},{"9":0}] | W2: =$N$1&$P$1&$T$1&$C$2&$T$1&$R$1&C3&$Q$1&$S$1&$P$1&$T$1&$D$2&$T$1&$R$1&D3&$Q$1&$S$1&$P$1&$T$1&$E$2&$T$1&$R$1&E3&$Q$1&$S$1&$P$1&$T$1&$F$2&$T$1&$R$1&K3&$Q$1&$S$1&$P$1&$T$1&$G$2&$T$1&$R$1&G3&$Q$1&$S$1&$P$1&$T$1&$H$2&$T$1&$R$1&H3&$Q$1&$S$1&$P$1&$T$1&$I$2&$T$1&$R$1&I3&$Q$1&$S$1&$P$1&$T$1&$J$2&$T$1&$R$1&J3&$Q$1&$O$1 -> [{"2":32},{"4":26},{"5":26},{"12":158},{"7":8},{"6":0},{"8":10},{"9":0}] | AE2: =$N$1&$P$1&$T$1&$C$2&$T$1&$R$1&C3&$Q$1&$S$1&$P$1&$T$1&$D$2&$T$1&$R$1&D3&$Q$1&$S$1&$P$1&$T$1&$E$2&$T$1&$R$1&E3&$Q$1&$S$1&$P$1&$T$1&$F$2&$T$1&$R$1&L3&$Q$1&$S$1&$P$1&$T$1&$G$2&$T$1&$R$1&G3&$Q$1&$S$1&$P$1&$T$1&$H$2&$T$1&$R$1&H3&$Q$1&$S$1&$P$1&$T$1&$I$2&$T$1&$R$1&I3&$Q$1&$S$1&$P$1&$T$1&$J$2&$T$1&$R$1&J3&$Q$1&$O$1 -> [{"2":32},{"4":26},{"5":26},{"12":238},{"7":8},{"6":0},{"8":10},{"9":0}] | AG2: 1.5 | AH2: 1 | AI2: 1 | AJ2: 10 | AK2: 0.4 | AL2: 0.4 | AM2: 0.4 | AN2: 0.4 | AP2: 40 | AQ2: =INT(AP2/1.5) -> 26 | AR2: =AQ2 -> 26 | AS2: =AR2*15 -> 390 | AT2: 10 | AU2: 0 | AV2: 10
A3: 1 | B3: =$AP$2+AG3 -> 40 | C3: =INT(B3*0.82) -> 32 | D3: =AH3+$AQ$2 -> 26 | E3: =D3 -> 26 | F3: 476 | G3: 8 | H3: 0 | I3: 10 | J3: 0 | K3: 158 | L3: 238 | N3: =$N$1&$P$1&$T$1&$B$2&$T$1&$R$1&B4&$Q$1&$S$1&$P$1&$T$1&$D$2&$T$1&$R$1&D4&$Q$1&$S$1&$P$1&$T$1&$E$2&$T$1&$R$1&E4&$Q$1&$S$1&$P$1&$T$1&$F$2&$T$1&$R$1&F4&$Q$1&$S$1&$P$1&$T$1&$G$2&$T$1&$R$1&G4&$Q$1&$S$1&$P$1&$T$1&$H$2&$T$1&$R$1&H4&$Q$1&$S$1&$P$1&$T$1&$I$2&$T$1&$R$1&I4&$Q$1&$S$1&$P$1&$T$1&$J$2&$T$1&$R$1&J4&$Q$1&$O$1 -> [{"1":40},{"4":26},{"5":26},{"12":552},{"7":8},{"6":0},{"8":10},{"9":0}] | W3: =$N$1&$P$1&$T$1&$C$2&$T$1&$R$1&C4&$Q$1&$S$1&$P$1&$T$1&$D$2&$T$1&$R$1&D4&$Q$1&$S$1&$P$1&$T$1&$E$2&$T$1&$R$1&E4&$Q$1&$S$1&$P$1&$T$1&$F$2&$T$1&$R$1&K4&$Q$1&$S$1&$P$1&$T$1&$G$2&$T$1&$R$1&G4&$Q$1&$S$1&$P$1&$T$1&$H$2&$T$1&$R$1&H4&$Q$1&$S$1&$P$1&$T$1&$I$2&$T$1&$R$1&I4&$Q$1&$S$1&$P$1&$T$1&$J$2&$T$1&$R$1&J4&$Q$1&$O$1 -> [{"2":32},{"4":26},{"5":26},{"12":184},{"7":8},{"6":0},{"8":10},{"9":0}] | AE3: =$N$1&$P$1&$T$1&$C$2&$T$1&$R$1&C4&$Q$1&$S$1&$P$1&$T$1&$D$2&$T$1&$R$1&D4&$Q$1&$S$1&$P$1&$T$1&$E$2&$T$1&$R$1&E4&$Q$1&$S$1&$P$1&$T$1&$F$2&$T$1&$R$1&L4&$Q$1&$S$1&$P$1&$T$1&$G$2&$T$1&$R$1&G4&$Q$1&$S$1&$P$1&$T$1&$H$2&$T$1&$R$1&H4&$Q$1&$S$1&$P$1&$T$1&$I$2&$T$1&$R$1&I4&$Q$1&$S$1&$P$1&$T$1&$J$2&$T$1&$R$1&J4&$Q$1&$O$1 -> [{"2":32},{"4":26},{"5":26},{"12":276},{"7":8},{"6":0},{"8":10},{"9":0}] | AG3: 0 | AH3: 0 | AI3: 0 | AJ3: 22 | AK3: 4 | AL3: 8 | AM3: 0 | AN3: 10
A4: 2 | B4: =$AP$2+AG4 -> 40 | C4: =INT(B4*0.82) -> 32 | D4: =AH4+$AQ$2 -> 26 | E4: =D4 -> 26 | F4: 552 | G4: 8 | H4: 0 | I4: 10 | J4: 0 | K4: 184 | L4: 276 | N4: =$N$1&$P$1&$T$1&$B$2&$T$1&$R$1&B5&$Q$1&$S$1&$P$1&$T$1&$D$2&$T$1&$R$1&D5&$Q$1&$S$1&$P$1&$T$1&$E$2&$T$1&$R$1&E5&$Q$1&$S$1&$P$1&$T$1&$F$2&$T$1&$R$1&F5&$Q$1&$S$1&$P$1&$T$1&$G$2&$T$1&$R$1&G5&$Q$1&$S$1&$P$1&$T$1&$H$2&$T$1&$R$1&H5&$Q$1&$S$1&$P$1&$T$1&$I$2&$T$1&$R$1&I5&$Q$1&$S$1&$P$1&$T$1&$J$2&$T$1&$R$1&J5&$Q$1&$O$1 -> [{"1":40},{"4":26},{"5":26},{"12":628},{"7":8},{"6":0},{"8":10},{"9":0}] | W4: =$N$1&$P$1&$T$1&$C$2&$T$1&$R$1&C5&$Q$1&$S$1&$P$1&$T$1&$D$2&$T$1&$R$1&D5&$Q$1&$S$1&$P$1&$T$1&$E$2&$T$1&$R$1&E5&$Q$1&$S$1&$P$1&$T$1&$F$2&$T$1&$R$1&K5&$Q$1&$S$1&$P$1&$T$1&$G$2&$T$1&$R$1&G5&$Q$1&$S$1&$P$1&$T$1&$H$2&$T$1&$R$1&H5&$Q$1&$S$1&$P$1&$T$1&$I$2&$T$1&$R$1&I5&$Q$1&$S$1&$P$1&$T$1&$J$2&$T$1&$R$1&J5&$Q$1&$O$1 -> [{"2":32},{"4":26},{"5":26},{"12":209},{"7":8},{"6":0},{"8":10},{"9":0}] | AE4: =$N$1&$P$1&$T$1&$C$2&$T$1&$R$1&C5&$Q$1&$S$1&$P$1&$T$1&$D$2&$T$1&$R$1&D5&$Q$1&$S$1&$P$1&$T$1&$E$2&$T$1&$R$1&E5&$Q$1&$S$1&$P$1&$T$1&$F$2&$T$1&$R$1&L5&$Q$1&$S$1&$P$1&$T$1&$G$2&$T$1&$R$1&G5&$Q$1&$S$1&$P$1&$T$1&$H$2&$T$1&$R$1&H5&$Q$1&$S$1&$P$1&$T$1&$I$2&$T$1&$R$1&I5&$Q$1&$S$1&$P$1&$T$1&$J$2&$T$1&$R$1&J5&$Q$1&$O$1 -> [{"2":32},{"4":26},{"5":26},{"12":314},{"7":8},{"6":0},{"8":10},{"9":0}] | AG4: 0 | AH4: 0 | AI4: 0 | AJ4: 29 | AK4: 4 | AL4: 8 | AM4: 0 | AN4: 10
A5: 3 | B5: =$AP$2+AG5 -> 40 | C5: =INT(B5*0.82) -> 32 | D5: =AH5+$AQ$2 -> 26 | E5: =D5 -> 26 | F5: 628 | G5: 8 | H5: 0 | I5: 10 | J5: 0 | K5: 209 | L5: 314 | N5: =$N$1&$P$1&$T$1&$B$2&$T$1&$R$1&B6&$Q$1&$S$1&$P$1&$T$1&$D$2&$T$1&$R$1&D6&$Q$1&$S$1&$P$1&$T$1&$E$2&$T$1&$R$1&E6&$Q$1&$S$1&$P$1&$T$1&$F$2&$T$1&$R$1&F6&$Q$1&$S$1&$P$1&$T$1&$G$2&$T$1&$R$1&G6&$Q$1&$S$1&$P$1&$T$1&$H$2&$T$1&$R$1&H6&$Q$1&$S$1&$P$1&$T$1&$I$2&$T$1&$R$1&I6&$Q$1&$S$1&$P$1&$T$1&$J$2&$T$1&$R$1&J6&$Q$1&$O$1 -> [{"1":40},{"4":26},{"5":26},{"12":704},{"7":8},{"6":0},{"8":10},{"9":0}] | W5: =$N$1&$P$1&$T$1&$C$2&$T$1&$R$1&C6&$Q$1&$S$1&$P$1&$T$1&$D$2&$T$1&$R$1&D6&$Q$1&$S$1&$P$1&$T$1&$E$2&$T$1&$R$1&E6&$Q$1&$S$1&$P$1&$T$1&$F$2&$T$1&$R$1&K6&$Q$1&$S$1&$P$1&$T$1&$G$2&$T$1&$R$1&G6&$Q$1&$S$1&$P$1&$T$1&$H$2&$T$1&$R$1&H6&$Q$1&$S$1&$P$1&$T$1&$I$2&$T$1&$R$1&I6&$Q$1&$S$1&$P$1&$T$1&$J$2&$T$1&$R$1&J6&$Q$1&$O$1 -> [{"2":32},{"4":26},{"5":26},{"12":234},{"7":8},{"6":0},{"8":10},{"9":0}] | AE5: =$N$1&$P$1&$T$1&$C$2&$T$1&$R$1&C6&$Q$1&$S$1&$P$1&$T$1&$D$2&$T$1&$R$1&D6&$Q$1&$S$1&$P$1&$T$1&$E$2&$T$1&$R$1&E6&$Q$1&$S$1&$P$1&$T$1&$F$2&$T$1&$R$1&L6&$Q$1&$S$1&$P$1&$T$1&$G$2&$T$1&$R$1&G6&$Q$1&$S$1&$P$1&$T$1&$H$2&$T$1&$R$1&H6&$Q$1&$S$1&$P$1&$T$1&$I$2&$T$1&$R$1&I6&$Q$1&$S$1&$P$1&$T$1&$J$2&$T$1&$R$1&J6&$Q$1&$O$1 -> [{"2":32},{"4":26},{"5":26},{"12":352},{"7":8},{"6":0},{"8":10},{"9":0}] | AG5: 0 | AH5: 0 | AI5: 0 | AJ5: 36 | AK5: 4 | AL5: 8 | AM5: 0 | AN5: 10
A6: 4 | B6: =$AP$2+AG6 -> 40 | C6: =INT(B6*0.82) -> 32 | D6: =AH6+$AQ$2 -> 26 | E6: =D6 -> 26 | F6: 704 | G6: 8 | H6: 0 | I6: 10 | J6: 0 | K6: 234 | L6: 352 | N6: =$N$1&$P$1&$T$1&$B$2&$T$1&$R$1&B7&$Q$1&$S$1&$P$1&$T$1&$D$2&$T$1&$R$1&D7&$Q$1&$S$1&$P$1&$T$1&$E$2&$T$1&$R$1&E7&$Q$1&$S$1&$P$1&$T$1&$F$2&$T$1&$R$1&F7&$Q$1&$S$1&$P$1&$T$1&$G$2&$T$1&$R$1&G7&$Q$1&$S$1&$P$1&$T$1&$H$2&$T$1&$R$1&H7&$Q$1&$S$1&$P$1&$T$1&$I$2&$T$1&$R$1&I7&$Q$1&$S$1&$P$1&$T$1&$J$2&$T$1&$R$1&J7&$Q$1&$O$1 -> [{"1":40},{"4":26},{"5":26},{"12":779},{"7":8},{"6":0},{"8":10},{"9":0}] | W6: =$N$1&$P$1&$T$1&$C$2&$T$1&$R$1&C7&$Q$1&$S$1&$P$1&$T$1&$D$2&$T$1&$R$1&D7&$Q$1&$S$1&$P$1&$T$1&$E$2&$T$1&$R$1&E7&$Q$1&$S$1&$P$1&$T$1&$F$2&$T$1&$R$1&K7&$Q$1&$S$1&$P$1&$T$1&$G$2&$T$1&$R$1&G7&$Q$1&$S$1&$P$1&$T$1&$H$2&$T$1&$R$1&H7&$Q$1&$S$1&$P$1&$T$1&$I$2&$T$1&$R$1&I7&$Q$1&$S$1&$P$1&$T$1&$J$2&$T$1&$R$1&J7&$Q$1&$O$1 -> [{"2":32},{"4":26},{"5":26},{"12":259},{"7":8},{"6":0},{"8":10},{"9":0}] | AE6: =$N$1&$P$1&$T$1&$C$2&$T$1&$R$1&C7&$Q$1&$S$1&$P$1&$T$1&$D$2&$T$1&$R$1&D7&$Q$1&$S$1&$P$1&$T$1&$E$2&$T$1&$R$1&E7&$Q$1&$S$1&$P$1&$T$1&$F$2&$T$1&$R$1&L7&$Q$1&$S$1&$P$1&$T$1&$G$2&$T$1&$R$1&G7&$Q$1&$S$1&$P$1&$T$1&$H$2&$T$1&$R$1&H7&$Q$1&$S$1&$P$1&$T$1&$I$2&$T$1&$R$1&I7&$Q$1&$S$1&$P$1&$T$1&$J$2&$T$1&$R$1&J7&$Q$1&$O$1 -> [{"2":32},{"4":26},{"5":26},{"12":390},{"7":8},{"6":0},{"8":10},{"9":0}] | AG6: 0 | AH6: 0 | AI6: 0 | AJ6: 44 | AK6: 4 | AL6: 8 | AM6: 0 | AN6: 10
A7: 5 | B7: =$AP$2+AG7 -> 40 | C7: =INT(B7*0.82) -> 32 | D7: =AH7+$AQ$2 -> 26 | E7: =D7 -> 26 | F7: 779 | G7: 8 | H7: 0 | I7: 10 | J7: 0 | K7: 259 | L7: 390 | N7: =$N$1&$P$1&$T$1&$B$2&$T$1&$R$1&B8&$Q$1&$S$1&$P$1&$T$1&$D$2&$T$1&$R$1&D8&$Q$1&$S$1&$P$1&$T$1&$E$2&$T$1&$R$1&E8&$Q$1&$S$1&$P$1&$T$1&$F$2&$T$1&$R$1&F8&$Q$1&$S$1&$P$1&$T$1&$G$2&$T$1&$R$1&G8&$Q$1&$S$1&$P$1&$T$1&$H$2&$T$1&$R$1&H8&$Q$1&$S$1&$P$1&$T$1&$I$2&$T$1&$R$1&I8&$Q$1&$S$1&$P$1&$T$1&$J$2&$T$1&$R$1&J8&$Q$1&$O$1 -> [{"1":40},{"4":26},{"5":26},{"12":855},{"7":8},{"6":0},{"8":10},{"9":0}] | W7: =$N$1&$P$1&$T$1&$C$2&$T$1&$R$1&C8&$Q$1&$S$1&$P$1&$T$1&$D$2&$T$1&$R$1&D8&$Q$1&$S$1&$P$1&$T$1&$E$2&$T$1&$R$1&E8&$Q$1&$S$1&$P$1&$T$1&$F$2&$T$1&$R$1&K8&$Q$1&$S$1&$P$1&$T$1&$G$2&$T$1&$R$1&G8&$Q$1&$S$1&$P$1&$T$1&$H$2&$T$1&$R$1&H8&$Q$1&$S$1&$P$1&$T$1&$I$2&$T$1&$R$1&I8&$Q$1&$S$1&$P$1&$T$1&$J$2&$T$1&$R$1&J8&$Q$1&$O$1 -> [{"2":32},{"4":26},{"5":26},{"12":285},{"7":8},{"6":0},{"8":10},{"9":0}] | AE7: =$N$1&$P$1&$T$1&$C$2&$T$1&$R$1&C8&$Q$1&$S$1&$P$1&$T$1&$D$2&$T$1&$R$1&D8&$Q$1&$S$1&$P$1&$T$1&$E$2&$T$1&$R$1&E8&$Q$1&$S$1&$P$1&$T$1&$F$2&$T$1&$R$1&L8&$Q$1&$S$1&$P$1&$T$1&$G$2&$T$1&$R$1&G8&$Q$1&$S$1&$P$1&$T$1&$H$2&$T$1&$R$1&H8&$Q$1&$S$1&$P$1&$T$1&$I$2&$T$1&$R$1&I8&$Q$1&$S$1&$P$1&$T$1&$J$2&$T$1&$R$1&J8&$Q$1&$O$1 -> [{"2":32},{"4":26},{"5":26},{"12":428},{"7":8},{"6":0},{"8":10},{"9":0}] | AG7: 0 | AH7: 0 | AI7: 0 | AJ7: 51 | AK7: 4 | AL7: 8 | AM7: 0 | AN7: 10
A8: 6 | B8: =$AP$2+AG8 -> 40 | C8: =INT(B8*0.82) -> 32 | D8: =AH8+$AQ$2 -> 26 | E8: =D8 -> 26 | F8: 855 | G8: 8 | H8: 0 | I8: 10 | J8: 0 | K8: 285 | L8: 428 | N8: =$N$1&$P$1&$T$1&$B$2&$T$1&$R$1&B9&$Q$1&$S$1&$P$1&$T$1&$D$2&$T$1&$R$1&D9&$Q$1&$S$1&$P$1&$T$1&$E$2&$T$1&$R$1&E9&$Q$1&$S$1&$P$1&$T$1&$F$2&$T$1&$R$1&F9&$Q$1&$S$1&$P$1&$T$1&$G$2&$T$1&$R$1&G9&$Q$1&$S$1&$P$1&$T$1&$H$2&$T$1&$R$1&H9&$Q$1&$S$1&$P$1&$T$1&$I$2&$T$1&$R$1&I9&$Q$1&$S$1&$P$1&$T$1&$J$2&$T$1&$R$1&J9&$Q$1&$O$1 -> [{"1":40},{"4":26},{"5":26},{"12":931},{"7":8},{"6":0},{"8":10},{"9":0}] | W8: =$N$1&$P$1&$T$1&$C$2&$T$1&$R$1&C9&$Q$1&$S$1&$P$1&$T$1&$D$2&$T$1&$R$1&D9&$Q$1&$S$1&$P$1&$T$1&$E$2&$T$1&$R$1&E9&$Q$1&$S$1&$P$1&$T$1&$F$2&$T$1&$R$1&K9&$Q$1&$S$1&$P$1&$T$1&$G$2&$T$1&$R$1&G9&$Q$1&$S$1&$P$1&$T$1&$H$2&$T$1&$R$1&H9&$Q$1&$S$1&$P$1&$T$1&$I$2&$T$1&$R$1&I9&$Q$1&$S$1&$P$1&$T$1&$J$2&$T$1&$R$1&J9&$Q$1&$O$1 -> [{"2":32},{"4":26},{"5":26},{"12":310},{"7":8},{"6":0},{"8":10},{"9":0}] | AE8: =$N$1&$P$1&$T$1&$C$2&$T$1&$R$1&C9&$Q$1&$S$1&$P$1&$T$1&$D$2&$T$1&$R$1&D9&$Q$1&$S$1&$P$1&$T$1&$E$2&$T$1&$R$1&E9&$Q$1&$S$1&$P$1&$T$1&$F$2&$T$1&$R$1&L9&$Q$1&$S$1&$P$1&$T$1&$G$2&$T$1&$R$1&G9&$Q$1&$S$1&$P$1&$T$1&$H$2&$T$1&$R$1&H9&$Q$1&$S$1&$P$1&$T$1&$I$2&$T$1&$R$1&I9&$Q$1&$S$1&$P$1&$T$1&$J$2&$T$1&$R$1&J9&$Q$1&$O$1 -> [{"2":32},{"4":26},{"5":26},{"12":466},{"7":8},{"6":0},{"8":10},{"9":0}] | AG8: 0 | AH8: 0 | AI8: 0 | AJ8: 58 | AK8: 4 | AL8: 8 | AM8: 0 | AN8: 10
A9: 7 | B9: =$AP$2+AG9 -> 40 | C9: =INT(B9*0.82) -> 32 | D9: =AH9+$AQ$2 -> 26 | E9: =D9 -> 26 | F9: 931 | G9: 8 | H9: 0 | I9: 10 | J9: 0 | K9: 310 | L9: 466 | N9: =$N$1&$P$1&$T$1&$B$2&$T$1&$R$1&B10&$Q$1&$S$1&$P$1&$T$1&$D$2&$T$1&$R$1&D10&$Q$1&$S$1&$P$1&$T$1&$E$2&$T$1&$R$1&E10&$Q$1&$S$1&$P$1&$T$1&$F$2&$T$1&$R$1&F10&$Q$1&$S$1&$P$1&$T$1&$G$2&$T$1&$R$1&G10&$Q$1&$S$1&$P$1&$T$1&$H$2&$T$1&$R$1&H10&$Q$1&$S$1&$P$1&$T$1&$I$2&$T$1&$R$1&I10&$Q$1&$S$1&$P$1&$T$1&$J$2&$T$1&$R$1&J10&$Q$1&$O$1 -> [{"1":40},{"4":26},{"5":26},{"12":1007},{"7":8},{"6":0},{"8":10},{"9":0}] | W9: =$N$1&$P$1&$T$1&$C$2&$T$1&$R$1&C10&$Q$1&$S$1&$P$1&$T$1&$D$2&$T$1&$R$1&D10&$Q$1&$S$1&$P$1&$T$1&$E$2&$T$1&$R$1&E10&$Q$1&$S$1&$P$1&$T$1&$F$2&$T$1&$R$1&K10&$Q$1&$S$1&$P$1&$T$1&$G$2&$T$1&$R$1&G10&$Q$1&$S$1&$P$1&$T$1&$H$2&$T$1&$R$1&H10&$Q$1&$S$1&$P$1&$T$1&$I$2&$T$1&$R$1&I10&$Q$1&$S$1&$P$1&$T$1&$J$2&$T$1&$R$1&J10&$Q$1&$O$1 -> [{"2":32},{"4":26},{"5":26},{"12":335},{"7":8},{"6":0},{"8":10},{"9":0}] | AE9: =$N$1&$P$1&$T$1&$C$2&$T$1&$R$1&C10&$Q$1&$S$1&$P$1&$T$1&$D$2&$T$1&$R$1&D10&$Q$1&$S$1&$P$1&$T$1&$E$2&$T$1&$R$1&E10&$Q$1&$S$1&$P$1&$T$1&$F$2&$T$1&$R$1&L10&$Q$1&$S$1&$P$1&$T$1&$G$2&$T$1&$R$1&G10&$Q$1&$S$1&$P$1&$T$1&$H$2&$T$1&$R$1&H10&$Q$1&$S$1&$P$1&$T$1&$I$2&$T$1&$R$1&I10&$Q$1&$S$1&$P$1&$T$1&$J$2&$T$1&$R$1&J10&$Q$1&$O$1 -> [{"2":32},{"4":26},{"5":26},{"12":504},{"7":8},{"6":0},{"8":10},{"9":0}] | AG9: 0 | AH9: 0 | AI9: 0 | AJ9: 66 | AK9: 4 | AL9: 8 | AM9: 0 | AN9: 10
A10: 8 | B10: =$AP$2+AG10 -> 40 | C10: =INT(B10*0.82) -> 32 | D10: =AH10+$AQ$2 -> 26 | E10: =D10 -> 26 | F10: 1007 | G10: 8 | H10: 0 | I10: 10 | J10: 0 | K10: 335 | L10: 504 | N10: =$N$1&$P$1&$T$1&$B$2&$T$1&$R$1&B11&$Q$1&$S$1&$P$1&$T$1&$D$2&$T$1&$R$1&D11&$Q$1&$S$1&$P$1&$T$1&$E$2&$T$1&$R$1&E11&$Q$1&$S$1&$P$1&$T$1&$F$2&$T$1&$R$1&F11&$Q$1&$S$1&$P$1&$T$1&$G$2&$T$1&$R$1&G11&$Q$1&$S$1&$P$1&$T$1&$H$2&$T$1&$R$1&H11&$Q$1&$S$1&$P$1&$T$1&$I$2&$T$1&$R$1&I11&$Q$1&$S$1&$P$1&$T$1&$J$2&$T$1&$R$1&J11&$Q$1&$O$1 -> [{"1":40},{"4":26},{"5":26},{"12":1083},{"7":8},{"6":0},{"8":10},{"9":0}] | W10: =$N$1&$P$1&$T$1&$C$2&$T$1&$R$1&C11&$Q$1&$S$1&$P$1&$T$1&$D$2&$T$1&$R$1&D11&$Q$1&$S$1&$P$1&$T$1&$E$2&$T$1&$R$1&E11&$Q$1&$S$1&$P$1&$T$1&$F$2&$T$1&$R$1&K11&$Q$1&$S$1&$P$1&$T$1&$G$2&$T$1&$R$1&G11&$Q$1&$S$1&$P$1&$T$1&$H$2&$T$1&$R$1&H11&$Q$1&$S$1&$P$1&$T$1&$I$2&$T$1&$R$1&I11&$Q$1&$S$1&$P$1&$T$1&$J$2&$T$1&$R$1&J11&$Q$1&$O$1 -> [{"2":32},{"4":26},{"5":26},{"12":361},{"7":8},{"6":0},{"8":10},{"9":0}] | AE10: =$N$1&$P$1&$T$1&$C$2&$T$1&$R$1&C11&$Q$1&$S$1&$P$1&$T$1&$D$2&$T$1&$R$1&D11&$Q$1&$S$1&$P$1&$T$1&$E$2&$T$1&$R$1&E11&$Q$1&$S$1&$P$1&$T$1&$F$2&$T$1&$R$1&L11&$Q$1&$S$1&$P$1&$T$1&$G$2&$T$1&$R$1&G11&$Q$1&$S$1&$P$1&$T$1&$H$2&$T$1&$R$1&H11&$Q$1&$S$1&$P$1&$T$1&$I$2&$T$1&$R$1&I11&$Q$1&$S$1&$P$1&$T$1&$J$2&$T$1&$R$1&J11&$Q$1&$O$1 -> [{"2":32},{"4":26},{"5":26},{"12":542},{"7":8},{"6":0},{"8":10},{"9":0}] | AG10: 0 | AH10: 0 | AI10: 0 | AJ10: 73 | AK10: 4 | AL10: 8 | AM10: 0 | AN10: 10
A11: 9 | B11: =$AP$2+AG11 -> 40 | C11: =INT(B11*0.82) -> 32 | D11: =AH11+$AQ$2 -> 26 | E11: =D11 -> 26 | F11: 1083 | G11: 8 | H11: 0 | I11: 10 | J11: 0 | K11: 361 | L11: 542 | N11: =$N$1&$P$1&$T$1&$B$2&$T$1&$R$1&B12&$Q$1&$S$1&$P$1&$T$1&$D$2&$T$1&$R$1&D12&$Q$1&$S$1&$P$1&$T$1&$E$2&$T$1&$R$1&E12&$Q$1&$S$1&$P$1&$T$1&$F$2&$T$1&$R$1&F12&$Q$1&$S$1&$P$1&$T$1&$G$2&$T$1&$R$1&G12&$Q$1&$S$1&$P$1&$T$1&$H$2&$T$1&$R$1&H12&$Q$1&$S$1&$P$1&$T$1&$I$2&$T$1&$R$1&I12&$Q$1&$S$1&$P$1&$T$1&$J$2&$T$1&$R$1&J12&$Q$1&$O$1 -> [{"1":42},{"4":27},{"5":27},{"12":1159},{"7":8},{"6":0},{"8":10},{"9":0}] | W11: =$N$1&$P$1&$T$1&$C$2&$T$1&$R$1&C12&$Q$1&$S$1&$P$1&$T$1&$D$2&$T$1&$R$1&D12&$Q$1&$S$1&$P$1&$T$1&$E$2&$T$1&$R$1&E12&$Q$1&$S$1&$P$1&$T$1&$F$2&$T$1&$R$1&K12&$Q$1&$S$1&$P$1&$T$1&$G$2&$T$1&$R$1&G12&$Q$1&$S$1&$P$1&$T$1&$H$2&$T$1&$R$1&H12&$Q$1&$S$1&$P$1&$T$1&$I$2&$T$1&$R$1&I12&$Q$1&$S$1&$P$1&$T$1&$J$2&$T$1&$R$1&J12&$Q$1&$O$1 -> [{"2":34},{"4":27},{"5":27},{"12":386},{"7":8},{"6":0},{"8":10},{"9":0}] | AE11: =$N$1&$P$1&$T$1&$C$2&$T$1&$R$1&C12&$Q$1&$S$1&$P$1&$T$1&$D$2&$T$1&$R$1&D12&$Q$1&$S$1&$P$1&$T$1&$E$2&$T$1&$R$1&E12&$Q$1&$S$1&$P$1&$T$1&$F$2&$T$1&$R$1&L12&$Q$1&$S$1&$P$1&$T$1&$G$2&$T$1&$R$1&G12&$Q$1&$S$1&$P$1&$T$1&$H$2&$T$1&$R$1&H12&$Q$1&$S$1&$P$1&$T$1&$I$2&$T$1&$R$1&I12&$Q$1&$S$1&$P$1&$T$1&$J$2&$T$1&$R$1&J12&$Q$1&$O$1 -> [{"2":34},{"4":27},{"5":27},{"12":580},{"7":8},{"6":0},{"8":10},{"9":0}] | AG11: 0 | AH11: 0 | AI11: 0 | AJ11: 80 | AK11: 4 | AL11: 8 | AM11: 0 | AN11: 10
A12: 10 | B12: =$AP$2+AG12 -> 42 | C12: =INT(B12*0.82) -> 34 | D12: =AH12+$AQ$2 -> 27 | E12: =D12 -> 27 | F12: 1159 | G12: 8 | H12: 0 | I12: 10 | J12: 0 | K12: 386 | L12: 580 | N12: =$N$1&$P$1&$T$1&$B$2&$T$1&$R$1&B13&$Q$1&$S$1&$P$1&$T$1&$D$2&$T$1&$R$1&D13&$Q$1&$S$1&$P$1&$T$1&$E$2&$T$1&$R$1&E13&$Q$1&$S$1&$P$1&$T$1&$F$2&$T$1&$R$1&F13&$Q$1&$S$1&$P$1&$T$1&$G$2&$T$1&$R$1&G13&$Q$1&$S$1&$P$1&$T$1&$H$2&$T$1&$R$1&H13&$Q$1&$S$1&$P$1&$T$1&$I$2&$T$1&$R$1&I13&$Q$1&$S$1&$P$1&$T$1&$J$2&$T$1&$R$1&J13&$Q$1&$O$1 -> [{"1":42},{"4":27},{"5":27},{"12":1235},{"7":8},{"6":0},{"8":10},{"9":0}] | W12: =$N$1&$P$1&$T$1&$C$2&$T$1&$R$1&C13&$Q$1&$S$1&$P$1&$T$1&$D$2&$T$1&$R$1&D13&$Q$1&$S$1&$P$1&$T$1&$E$2&$T$1&$R$1&E13&$Q$1&$S$1&$P$1&$T$1&$F$2&$T$1&$R$1&K13&$Q$1&$S$1&$P$1&$T$1&$G$2&$T$1&$R$1&G13&$Q$1&$S$1&$P$1&$T$1&$H$2&$T$1&$R$1&H13&$Q$1&$S$1&$P$1&$T$1&$I$2&$T$1&$R$1&I13&$Q$1&$S$1&$P$1&$T$1&$J$2&$T$1&$R$1&J13&$Q$1&$O$1 -> [{"2":34},{"4":27},{"5":27},{"12":411},{"7":8},{"6":0},{"8":10},{"9":0}] | AE12: =$N$1&$P$1&$T$1&$C$2&$T$1&$R$1&C13&$Q$1&$S$1&$P$1&$T$1&$D$2&$T$1&$R$1&D13&$Q$1&$S$1&$P$1&$T$1&$E$2&$T$1&$R$1&E13&$Q$1&$S$1&$P$1&$T$1&$F$2&$T$1&$R$1&L13&$Q$1&$S$1&$P$1&$T$1&$G$2&$T$1&$R$1&G13&$Q$1&$S$1&$P$1&$T$1&$H$2&$T$1&$R$1&H13&$Q$1&$S$1&$P$1&$T$1&$I$2&$T$1&$R$1&I13&$Q$1&$S$1&$P$1&$T$1&$J$2&$T$1&$R$1&J13&$Q$1&$O$1 -> [{"2":34},{"4":27},{"5":27},{"12":618},{"7":8},{"6":0},{"8":10},{"9":0}] | AG12: 2 | AH12: 1 | AI12: 1 | AJ12: 88 | AK12: 4 | AL12: 8 | AM12: 0 | AN12: 10
A13: 11 | B13: =$AP$2+AG13 -> 42 | C13: =INT(B13*0.82) -> 34 | D13: =AH13+$AQ$2 -> 27 | E13: =D13 -> 27 | F13: 1235 | G13: 8 | H13: 0 | I13: 10 | J13: 0 | K13: 411 | L13: 618 | N13: =$N$1&$P$1&$T$1&$B$2&$T$1&$R$1&B14&$Q$1&$S$1&$P$1&$T$1&$D$2&$T$1&$R$1&D14&$Q$1&$S$1&$P$1&$T$1&$E$2&$T$1&$R$1&E14&$Q$1&$S$1&$P$1&$T$1&$F$2&$T$1&$R$1&F14&$Q$1&$S$1&$P$1&$T$1&$G$2&$T$1&$R$1&G14&$Q$1&$S$1&$P$1&$T$1&$H$2&$T$1&$R$1&H14&$Q$1&$S$1&$P$1&$T$1&$I$2&$T$1&$R$1&I14&$Q$1&$S$1&$P$1&$T$1&$J$2&$T$1&$R$1&J14&$Q$1&$O$1 -> [{"1":42},{"4":27},{"5":27},{"12":1311},{"7":8},{"6":0},{"8":10},{"9":0}] | W13: =$N$1&$P$1&$T$1&$C$2&$T$1&$R$1&C14&$Q$1&$S$1&$P$1&$T$1&$D$2&$T$1&$R$1&D14&$Q$1&$S$1&$P$1&$T$1&$E$2&$T$1&$R$1&E14&$Q$1&$S$1&$P$1&$T$1&$F$2&$T$1&$R$1&K14&$Q$1&$S$1&$P$1&$T$1&$G$2&$T$1&$R$1&G14&$Q$1&$S$1&$P$1&$T$1&$H$2&$T$1&$R$1&H14&$Q$1&$S$1&$P$1&$T$1&$I$2&$T$1&$R$1&I14&$Q$1&$S$1&$P$1&$T$1&$J$2&$T$1&$R$1&J14&$Q$1&$O$1 -> [{"2":34},{"4":27},{"5":27},{"12":437},{"7":8},{"6":0},{"8":10},{"9":0}] | AE13: =$N$1&$P$1&$T$1&$C$2&$T$1&$R$1&C14&$Q$1&$S$1&$P$1&$T$1&$D$2&$T$1&$R$1&D14&$Q$1&$S$1&$P$1&$T$1&$E$2&$T$1&$R$1&E14&$Q$1&$S$1&$P$1&$T$1&$F$2&$T$1&$R$1&L14&$Q$1&$S$1&$P$1&$T$1&$G$2&$T$1&$R$1&G14&$Q$1&$S$1&$P$1&$T$1&$H$2&$T$1&$R$1&H14&$Q$1&$S$1&$P$1&$T$1&$I$2&$T$1&$R$1&I14&$Q$1&$S$1&$P$1&$T$1&$J$2&$T$1&$R$1&J14&$Q$1&$O$1 -> [{"2":34},{"4":27},{"5":27},{"12":656},{"7":8},{"6":0},{"8":10},{"9":0}] | AG13: 2 | AH13: 1 | AI13: 1 | AJ13: 95 | AK13: 4 | AL13: 8 | AM13: 0 | AN13: 10
A14: 12 | B14: =$AP$2+AG14 -> 42 | C14: =INT(B14*0.82) -> 34 | D14: =AH14+$AQ$2 -> 27 | E14: =D14 -> 27 | F14: 1311 | G14: 8 | H14: 0 | I14: 10 | J14: 0 | K14: 437 | L14: 656 | N14: =$N$1&$P$1&$T$1&$B$2&$T$1&$R$1&B15&$Q$1&$S$1&$P$1&$T$1&$D$2&$T$1&$R$1&D15&$Q$1&$S$1&$P$1&$T$1&$E$2&$T$1&$R$1&E15&$Q$1&$S$1&$P$1&$T$1&$F$2&$T$1&$R$1&F15&$Q$1&$S$1&$P$1&$T$1&$G$2&$T$1&$R$1&G15&$Q$1&$S$1&$P$1&$T$1&$H$2&$T$1&$R$1&H15&$Q$1&$S$1&$P$1&$T$1&$I$2&$T$1&$R$1&I15&$Q$1&$S$1&$P$1&$T$1&$J$2&$T$1&$R$1&J15&$Q$1&$O$1 -> [{"1":42},{"4":27},{"5":27},{"12":1387},{"7":8},{"6":0},{"8":10},{"9":0}] | W14: =$N$1&$P$1&$T$1&$C$2&$T$1&$R$1&C15&$Q$1&$S$1&$P$1&$T$1&$D$2&$T$1&$R$1&D15&$Q$1&$S$1&$P$1&$T$1&$E$2&$T$1&$R$1&E15&$Q$1&$S$1&$P$1&$T$1&$F$2&$T$1&$R$1&K15&$Q$1&$S$1&$P$1&$T$1&$G$2&$T$1&$R$1&G15&$Q$1&$S$1&$P$1&$T$1&$H$2&$T$1&$R$1&H15&$Q$1&$S$1&$P$1&$T$1&$I$2&$T$1&$R$1&I15&$Q$1&$S$1&$P$1&$T$1&$J$2&$T$1&$R$1&J15&$Q$1&$O$1 -> [{"2":34},{"4":27},{"5":27},{"12":462},{"7":8},{"6":0},{"8":10},{"9":0}] | AE14: =$N$1&$P$1&$T$1&$C$2&$T$1&$R$1&C15&$Q$1&$S$1&$P$1&$T$1&$D$2&$T$1&$R$1&D15&$Q$1&$S$1&$P$1&$T$1&$E$2&$T$1&$R$1&E15&$Q$1&$S$1&$P$1&$T$1&$F$2&$T$1&$R$1&L15&$Q$1&$S$1&$P$1&$T$1&$G$2&$T$1&$R$1&G15&$Q$1&$S$1&$P$1&$T$1&$H$2&$T$1&$R$1&H15&$Q$1&$S$1&$P$1&$T$1&$I$2&$T$1&$R$1&I15&$Q$1&$S$1&$P$1&$T$1&$J$2&$T$1&$R$1&J15&$Q$1&$O$1 -> [{"2":34},{"4":27},{"5":27},{"12":694},{"7":8},{"6":0},{"8":10},{"9":0}] | AG14: 2 | AH14: 1 | AI14: 1 | AJ14: 103 | AK14: 4 | AL14: 8 | AM14: 0 | AN14: 10
... A152: 150 | B152: =$AP$2+AG152 -> 71 | C152: =INT(B152*0.82) -> 58 | D152: =AH152+$AQ$2 -> 47 | E152: =D152 -> 47 | F152: 48217 | G152: 8 | H152: 0 | I152: 10 | J152: 0 | K152: 16072 | L152: 24109 | N152: =$N$1&$P$1&$T$1&$B$2&$T$1&$R$1&B153&$Q$1&$S$1&$P$1&$T$1&$D$2&$T$1&$R$1&D153&$Q$1&$S$1&$P$1&$T$1&$E$2&$T$1&$R$1&E153&$Q$1&$S$1&$P$1&$T$1&$F$2&$T$1&$R$1&F153&$Q$1&$S$1&$P$1&$T$1&$G$2&$T$1&$R$1&G153&$Q$1&$S$1&$P$1&$T$1&$H$2&$T$1&$R$1&H153&$Q$1&$S$1&$P$1&$T$1&$I$2&$T$1&$R$1&I153&$Q$1&$S$1&$P$1&$T$1&$J$2&$T$1&$R$1&J153&$Q$1&$O$1 -> [{"1":},{"4":},{"5":},{"12":},{"7":},{"6":},{"8":},{"9":}] | W152: =$N$1&$P$1&$T$1&$C$2&$T$1&$R$1&C153&$Q$1&$S$1&$P$1&$T$1&$D$2&$T$1&$R$1&D153&$Q$1&$S$1&$P$1&$T$1&$E$2&$T$1&$R$1&E153&$Q$1&$S$1&$P$1&$T$1&$F$2&$T$1&$R$1&K153&$Q$1&$S$1&$P$1&$T$1&$G$2&$T$1&$R$1&G153&$Q$1&$S$1&$P$1&$T$1&$H$2&$T$1&$R$1&H153&$Q$1&$S$1&$P$1&$T$1&$I$2&$T$1&$R$1&I153&$Q$1&$S$1&$P$1&$T$1&$J$2&$T$1&$R$1&J153&$Q$1&$O$1 -> [{"2":},{"4":},{"5":},{"12":},{"7":},{"6":},{"8":},{"9":}] | AE152: =$N$1&$P$1&$T$1&$C$2&$T$1&$R$1&C153&$Q$1&$S$1&$P$1&$T$1&$D$2&$T$1&$R$1&D153&$Q$1&$S$1&$P$1&$T$1&$E$2&$T$1&$R$1&E153&$Q$1&$S$1&$P$1&$T$1&$F$2&$T$1&$R$1&L153&$Q$1&$S$1&$P$1&$T$1&$G$2&$T$1&$R$1&G153&$Q$1&$S$1&$P$1&$T$1&$H$2&$T$1&$R$1&H153&$Q$1&$S$1&$P$1&$T$1&$I$2&$T$1&$R$1&I153&$Q$1&$S$1&$P$1&$T$1&$J$2&$T$1&$R$1&J153&$Q$1&$O$1 -> [{"2":},{"4":},{"5":},{"12":},{"7":},{"6":},{"8":},{"9":}] | AG152: 31 | AH152: 21 | AI152: 21 | AJ152: 1202 | AK152: 4 | AL152: 8 | AM152: 0 | AN152: 10

Sheet 伙伴属性配置
A1: 等级 | B1: 物理攻击 | C1: 魔法攻击 | D1: 物理防御 | E1: 魔法防御 | F1: 战士生命值 | G1: 命中 | H1: 闪避 | I1: 暴击值 | J1: 韧性值 | K1: 法师生命值 | L1: 祭祀生命值 | N1: [ | O1: ] | P1: { | Q1: } | R1: : | S1: , | T1: " | U1: " | W1: 法师配置 | AE1: 祭祀配置 | AG1: 攻击 | AH1: 物防 | AI1: 魔防 | AJ1: 生命 | AK1: 魔躲 | AL1: 命中 | AM1: 闪避 | AN1: 暴击 | AP1: 基础攻击 | AQ1: 基础物防 | AR1: 基础魔防 | AS1: 基础生命 | AT1: 基础命中 | AU1: 基础闪避 | AV1: 基础暴击
A2: 0 | B2: 1 | C2: 2 | D2: 4 | E2: 5 | F2: 12 | G2: 7 | H2: 6 | I2: 8 | J2: 9 | K2: =INT(F2/4) -> 3 | N2: =$N$1&$P$1&$T$1&$B$2&$T$1&$R$1&B3&$Q$1&$S$1&$P$1&$T$1&$D$2&$T$1&$R$1&D3&$Q$1&$S$1&$P$1&$T$1&$E$2&$T$1&$R$1&E3&$Q$1&$S$1&$P$1&$T$1&$F$2&$T$1&$R$1&F3&$Q$1&$S$1&$P$1&$T$1&$G$2&$T$1&$R$1&G3&$Q$1&$S$1&$P$1&$T$1&$H$2&$T$1&$R$1&H3&$Q$1&$S$1&$P$1&$T$1&$I$2&$T$1&$R$1&I3&$Q$1&$S$1&$P$1&$T$1&$J$2&$T$1&$R$1&J3&$Q$1&$O$1 -> [{"1":101},{"4":66},{"5":66},{"12":658},{"7":8},{"6":0},{"8":10},{"9":0}] | W2: =$N$1&$P$1&$T$1&$C$2&$T$1&$R$1&C3&$Q$1&$S$1&$P$1&$T$1&$D$2&$T$1&$R$1&D3&$Q$1&$S$1&$P$1&$T$1&$E$2&$T$1&$R$1&E3&$Q$1&$S$1&$P$1&$T$1&$F$2&$T$1&$R$1&K3&$Q$1&$S$1&$P$1&$T$1&$G$2&$T$1&$R$1&G3&$Q$1&$S$1&$P$1&$T$1&$H$2&$T$1&$R$1&H3&$Q$1&$S$1&$P$1&$T$1&$I$2&$T$1&$R$1&I3&$Q$1&$S$1&$P$1&$T$1&$J$2&$T$1&$R$1&J3&$Q$1&$O$1 -> [{"2":121},{"4":66},{"5":66},{"12":219},{"7":8},{"6":0},{"8":10},{"9":0}] | AE2: =$N$1&$P$1&$T$1&$C$2&$T$1&$R$1&C3&$Q$1&$S$1&$P$1&$T$1&$D$2&$T$1&$R$1&D3&$Q$1&$S$1&$P$1&$T$1&$E$2&$T$1&$R$1&E3&$Q$1&$S$1&$P$1&$T$1&$F$2&$T$1&$R$1&L3&$Q$1&$S$1&$P$1&$T$1&$G$2&$T$1&$R$1&G3&$Q$1&$S$1&$P$1&$T$1&$H$2&$T$1&$R$1&H3&$Q$1&$S$1&$P$1&$T$1&$I$2&$T$1&$R$1&I3&$Q$1&$S$1&$P$1&$T$1&$J$2&$T$1&$R$1&J3&$Q$1&$O$1 -> [{"2":121},{"4":66},{"5":66},{"12":329},{"7":8},{"6":0},{"8":10},{"9":0}] | AG2: 1.5 | AH2: 1 | AI2: 1 | AJ2: 10 | AK2: 0.4 | AL2: 0.4 | AM2: 0.4 | AN2: 0.4 | AP2: 100 | AQ2: =INT(AP2/1.5) -> 66 | AR2: =AQ2 -> 66 | AS2: 500 | AT2: 10 | AU2: 0 | AV2: 10
A3: 1 | B3: =$AP$2+AG3 -> 101 | C3: =INT(B3*1.2) -> 121 | D3: =AH3+$AQ$2 -> 66 | E3: =D3 -> 66 | F3: =INT(主角属性配置!F3/3+$AS$2) -> 658 | G3: 8 | H3: 0 | I3: 10 | J3: 0 | K3: =ROUND(F3/3,0) -> 219 | L3: =ROUND(F3/2,0) -> 329 | N3: =$N$1&$P$1&$T$1&$B$2&$T$1&$R$1&B4&$Q$1&$S$1&$P$1&$T$1&$D$2&$T$1&$R$1&D4&$Q$1&$S$1&$P$1&$T$1&$E$2&$T$1&$R$1&E4&$Q$1&$S$1&$P$1&$T$1&$F$2&$T$1&$R$1&F4&$Q$1&$S$1&$P$1&$T$1&$G$2&$T$1&$R$1&G4&$Q$1&$S$1&$P$1&$T$1&$H$2&$T$1&$R$1&H4&$Q$1&$S$1&$P$1&$T$1&$I$2&$T$1&$R$1&I4&$Q$1&$S$1&$P$1&$T$1&$J$2&$T$1&$R$1&J4&$Q$1&$O$1 -> [{"1":102},{"4":67},{"5":67},{"12":684},{"7":8},{"6":0},{"8":10},{"9":0}] | W3: =$N$1&$P$1&$T$1&$C$2&$T$1&$R$1&C4&$Q$1&$S$1&$P$1&$T$1&$D$2&$T$1&$R$1&D4&$Q$1&$S$1&$P$1&$T$1&$E$2&$T$1&$R$1&E4&$Q$1&$S$1&$P$1&$T$1&$F$2&$T$1&$R$1&K4&$Q$1&$S$1&$P$1&$T$1&$G$2&$T$1&$R$1&G4&$Q$1&$S$1&$P$1&$T$1&$H$2&$T$1&$R$1&H4&$Q$1&$S$1&$P$1&$T$1&$I$2&$T$1&$R$1&I4&$Q$1&$S$1&$P$1&$T$1&$J$2&$T$1&$R$1&J4&$Q$1&$O$1 -> [{"2":122},{"4":67},{"5":67},{"12":228},{"7":8},{"6":0},{"8":10},{"9":0}] | AE3: =$N$1&$P$1&$T$1&$C$2&$T$1&$R$1&C4&$Q$1&$S$1&$P$1&$T$1&$D$2&$T$1&$R$1&D4&$Q$1&$S$1&$P$1&$T$1&$E$2&$T$1&$R$1&E4&$Q$1&$S$1&$P$1&$T$1&$F$2&$T$1&$R$1&L4&$Q$1&$S$1&$P$1&$T$1&$G$2&$T$1&$R$1&G4&$Q$1&$S$1&$P$1&$T$1&$H$2&$T$1&$R$1&H4&$Q$1&$S$1&$P$1&$T$1&$I$2&$T$1&$R$1&I4&$Q$1&$S$1&$P$1&$T$1&$J$2&$T$1&$R$1&J4&$Q$1&$O$1 -> [{"2":122},{"4":67},{"5":67},{"12":342},{"7":8},{"6":0},{"8":10},{"9":0}] | AG3: 1 | AH3: =INT(AG3/1.5) -> 0 | AI3: =AH3 -> 0 | AJ3: 22 | AK3: 4 | AL3: 8 | AM3: 0 | AN3: 10
A4: 2 | B4: =$AP$2+AG4 -> 102 | C4: =INT(B4*1.2) -> 122 | D4: =AH4+$AQ$2 -> 67 | E4: =D4 -> 67 | F4: =INT(主角属性配置!F4/3+$AS$2) -> 684 | G4: 8 | H4: 0 | I4: 10 | J4: 0 | K4: =ROUND(F4/3,0) -> 228 | L4: =ROUND(F4/2,0) -> 342 | N4: =$N$1&$P$1&$T$1&$B$2&$T$1&$R$1&B5&$Q$1&$S$1&$P$1&$T$1&$D$2&$T$1&$R$1&D5&$Q$1&$S$1&$P$1&$T$1&$E$2&$T$1&$R$1&E5&$Q$1&$S$1&$P$1&$T$1&$F$2&$T$1&$R$1&F5&$Q$1&$S$1&$P$1&$T$1&$G$2&$T$1&$R$1&G5&$Q$1&$S$1&$P$1&$T$1&$H$2&$T$1&$R$1&H5&$Q$1&$S$1&$P$1&$T$1&$I$2&$T$1&$R$1&I5&$Q$1&$S$1&$P$1&$T$1&$J$2&$T$1&$R$1&J5&$Q$1&$O$1 -> [{"1":103},{"4":68},{"5":68},{"12":709},{"7":8},{"6":0},{"8":10},{"9":0}] | W4: =$N$1&$P$1&$T$1&$C$2&$T$1&$R$1&C5&$Q$1&$S$1&$P$1&$T$1&$D$2&$T$1&$R$1&D5&$Q$1&$S$1&$P$1&$T$1&$E$2&$T$1&$R$1&E5&$Q$1&$S$1&$P$1&$T$1&$F$2&$T$1&$R$1&K5&$Q$1&$S$1&$P$1&$T$1&$G$2&$T$1&$R$1&G5&$Q$1&$S$1&$P$1&$T$1&$H$2&$T$1&$R$1&H5&$Q$1&$S$1&$P$1&$T$1&$I$2&$T$1&$R$1&I5&$Q$1&$S$1&$P$1&$T$1&$J$2&$T$1&$R$1&J5&$Q$1&$O$1 -> [{"2":123},{"4":68},{"5":68},{"12":236},{"7":8},{"6":0},{"8":10},{"9":0}] | AE4: =$N$1&$P$1&$T$1&$C$2&$T$1&$R$1&C5&$Q$1&$S$1&$P$1&$T$1&$D$2&$T$1&$R$1&D5&$Q$1&$S$1&$P$1&$T$1&$E$2&$T$1&$R$1&E5&$Q$1&$S$1&$P$1&$T$1&$F$2&$T$1&$R$1&L5&$Q$1&$S$1&$P$1&$T$1&$G$2&$T$1&$R$1&G5&$Q$1&$S$1&$P$1&$T$1&$H$2&$T$1&$R$1&H5&$Q$1&$S$1&$P$1&$T$1&$I$2&$T$1&$R$1&I5&$Q$1&$S$1&$P$1&$T$1&$J$2&$T$1&$R$1&J5&$Q$1&$O$1 -> [{"2":123},{"4":68},{"5":68},{"12":355},{"7":8},{"6":0},{"8":10},{"9":0}] | AG4: 2 | AH4: =INT(AG4/1.5) -> 1 | AI4: =AH4 -> 1 | AJ4: 29 | AK4: 4 | AL4: 8 | AM4: 0 | AN4: 10
A5: 3 | B5: =$AP$2+AG5 -> 103 | C5: =INT(B5*1.2) -> 123 | D5: =AH5+$AQ$2 -> 68 | E5: =D5 -> 68 | F5: =INT(主角属性配置!F5/3+$AS$2) -> 709 | G5: 8 | H5: 0 | I5: 10 | J5: 0 | K5: =ROUND(F5/3,0) -> 236 | L5: =ROUND(F5/2,0) -> 355 | N5: =$N$1&$P$1&$T$1&$B$2&$T$1&$R$1&B6&$Q$1&$S$1&$P$1&$T$1&$D$2&$T$1&$R$1&D6&$Q$1&$S$1&$P$1&$T$1&$E$2&$T$1&$R$1&E6&$Q$1&$S$1&$P$1&$T$1&$F$2&$T$1&$R$1&F6&$Q$1&$S$1&$P$1&$T$1&$G$2&$T$1&$R$1&G6&$Q$1&$S$1&$P$1&$T$1&$H$2&$T$1&$R$1&H6&$Q$1&$S$1&$P$1&$T$1&$I$2&$T$1&$R$1&I6&$Q$1&$S$1&$P$1&$T$1&$J$2&$T$1&$R$1&J6&$Q$1&$O$1 -> [{"1":104},{"4":68},{"5":68},{"12":734},{"7":8},{"6":0},{"8":10},{"9":0}] | W5: =$N$1&$P$1&$T$1&$C$2&$T$1&$R$1&C6&$Q$1&$S$1&$P$1&$T$1&$D$2&$T$1&$R$1&D6&$Q$1&$S$1&$P$1&$T$1&$E$2&$T$1&$R$1&E6&$Q$1&$S$1&$P$1&$T$1&$F$2&$T$1&$R$1&K6&$Q$1&$S$1&$P$1&$T$1&$G$2&$T$1&$R$1&G6&$Q$1&$S$1&$P$1&$T$1&$H$2&$T$1&$R$1&H6&$Q$1&$S$1&$P$1&$T$1&$I$2&$T$1&$R$1&I6&$Q$1&$S$1&$P$1&$T$1&$J$2&$T$1&$R$1&J6&$Q$1&$O$1 -> [{"2":124},{"4":68},{"5":68},{"12":245},{"7":8},{"6":0},{"8":10},{"9":0}] | AE5: =$N$1&$P$1&$T$1&$C$2&$T$1&$R$1&C6&$Q$1&$S$1&$P$1&$T$1&$D$2&$T$1&$R$1&D6&$Q$1&$S$1&$P$1&$T$1&$E$2&$T$1&$R$1&E6&$Q$1&$S$1&$P$1&$T$1&$F$2&$T$1&$R$1&L6&$Q$1&$S$1&$P$1&$T$1&$G$2&$T$1&$R$1&G6&$Q$1&$S$1&$P$1&$T$1&$H$2&$T$1&$R$1&H6&$Q$1&$S$1&$P$1&$T$1&$I$2&$T$1&$R$1&I6&$Q$1&$S$1&$P$1&$T$1&$J$2&$T$1&$R$1&J6&$Q$1&$O$1 -> [{"2":124},{"4":68},{"5":68},{"12":367},{"7":8},{"6":0},{"8":10},{"9":0}] | AG5: 3 | AH5: =INT(AG5/1.5) -> 2 | AI5: =AH5 -> 2 | AJ5: 36 | AK5: 4 | AL5: 8 | AM5: 0 | AN5: 10
A6: 4 | B6: =$AP$2+AG6 -> 104 | C6: =INT(B6*1.2) -> 124 | D6: =AH6+$AQ$2 -> 68 | E6: =D6 -> 68 | F6: =INT(主角属性配置!F6/3+$AS$2) -> 734 | G6: 8 | H6: 0 | I6: 10 | J6: 0 | K6: =ROUND(F6/3,0) -> 245 | L6: =ROUND(F6/2,0) -> 367 | N6: =$N$1&$P$1&$T$1&$B$2&$T$1&$R$1&B7&$Q$1&$S$1&$P$1&$T$1&$D$2&$T$1&$R$1&D7&$Q$1&$S$1&$P$1&$T$1&$E$2&$T$1&$R$1&E7&$Q$1&$S$1&$P$1&$T$1&$F$2&$T$1&$R$1&F7&$Q$1&$S$1&$P$1&$T$1&$G$2&$T$1&$R$1&G7&$Q$1&$S$1&$P$1&$T$1&$H$2&$T$1&$R$1&H7&$Q$1&$S$1&$P$1&$T$1&$I$2&$T$1&$R$1&I7&$Q$1&$S$1&$P$1&$T$1&$J$2&$T$1&$R$1&J7&$Q$1&$O$1 -> [{"1":105},{"4":69},{"5":69},{"12":759},{"7":8},{"6":0},{"8":10},{"9":0}] | W6: =$N$1&$P$1&$T$1&$C$2&$T$1&$R$1&C7&$Q$1&$S$1&$P$1&$T$1&$D$2&$T$1&$R$1&D7&$Q$1&$S$1&$P$1&$T$1&$E$2&$T$1&$R$1&E7&$Q$1&$S$1&$P$1&$T$1&$F$2&$T$1&$R$1&K7&$Q$1&$S$1&$P$1&$T$1&$G$2&$T$1&$R$1&G7&$Q$1&$S$1&$P$1&$T$1&$H$2&$T$1&$R$1&H7&$Q$1&$S$1&$P$1&$T$1&$I$2&$T$1&$R$1&I7&$Q$1&$S$1&$P$1&$T$1&$J$2&$T$1&$R$1&J7&$Q$1&$O$1 -> [{"2":126},{"4":69},{"5":69},{"12":253},{"7":8},{"6":0},{"8":10},{"9":0}] | AE6: =$N$1&$P$1&$T$1&$C$2&$T$1&$R$1&C7&$Q$1&$S$1&$P$1&$T$1&$D$2&$T$1&$R$1&D7&$Q$1&$S$1&$P$1&$T$1&$E$2&$T$1&$R$1&E7&$Q$1&$S$1&$P$1&$T$1&$F$2&$T$1&$R$1&L7&$Q$1&$S$1&$P$1&$T$1&$G$2&$T$1&$R$1&G7&$Q$1&$S$1&$P$1&$T$1&$H$2&$T$1&$R$1&H7&$Q$1&$S$1&$P$1&$T$1&$I$2&$T$1&$R$1&I7&$Q$1&$S$1&$P$1&$T$1&$J$2&$T$1&$R$1&J7&$Q$1&$O$1 -> [{"2":126},{"4":69},{"5":69},{"12":380},{"7":8},{"6":0},{"8":10},{"9":0}] | AG6: 4 | AH6: =INT(AG6/1.5) -> 2 | AI6: =AH6 -> 2 | AJ6: 44 | AK6: 4 | AL6: 8 | AM6: 0 | AN6: 10
A7: 5 | B7: =$AP$2+AG7 -> 105 | C7: =INT(B7*1.2) -> 126 | D7: =AH7+$AQ$2 -> 69 | E7: =D7 -> 69 | F7: =INT(主角属性配置!F7/3+$AS$2) -> 759 | G7: 8 | H7: 0 | I7: 10 | J7: 0 | K7: =ROUND(F7/3,0) -> 253 | L7: =ROUND(F7/2,0) -> 380 | N7: =$N$1&$P$1&$T$1&$B$2&$T$1&$R$1&B8&$Q$1&$S$1&$P$1&$T$1&$D$2&$T$1&$R$1&D8&$Q$1&$S$1&$P$1&$T$1&$E$2&$T$1&$R$1&E8&$Q$1&$S$1&$P$1&$T$1&$F$2&$T$1&$R$1&F8&$Q$1&$S$1&$P$1&$T$1&$G$2&$T$1&$R$1&G8&$Q$1&$S$1&$P$1&$T$1&$H$2&$T$1&$R$1&H8&$Q$1&$S$1&$P$1&$T$1&$I$2&$T$1&$R$1&I8&$Q$1&$S$1&$P$1&$T$1&$J$2&$T$1&$R$1&J8&$Q$1&$O$1 -> [{"1":106},{"4":70},{"5":70},{"12":785},{"7":8},{"6":0},{"8":10},{"9":0}] | W7: =$N$1&$P$1&$T$1&$C$2&$T$1&$R$1&C8&$Q$1&$S$1&$P$1&$T$1&$D$2&$T$1&$R$1&D8&$Q$1&$S$1&$P$1&$T$1&$E$2&$T$1&$R$1&E8&$Q$1&$S$1&$P$1&$T$1&$F$2&$T$1&$R$1&K8&$Q$1&$S$1&$P$1&$T$1&$G$2&$T$1&$R$1&G8&$Q$1&$S$1&$P$1&$T$1&$H$2&$T$1&$R$1&H8&$Q$1&$S$1&$P$1&$T$1&$I$2&$T$1&$R$1&I8&$Q$1&$S$1&$P$1&$T$1&$J$2&$T$1&$R$1&J8&$Q$1&$O$1 -> [{"2":127},{"4":70},{"5":70},{"12":262},{"7":8},{"6":0},{"8":10},{"9":0}] | AE7: =$N$1&$P$1&$T$1&$C$2&$T$1&$R$1&C8&$Q$1&$S$1&$P$1&$T$1&$D$2&$T$1&$R$1&D8&$Q$1&$S$1&$P$1&$T$1&$E$2&$T$1&$R$1&E8&$Q$1&$S$1&$P$1&$T$1&$F$2&$T$1&$R$1&L8&$Q$1&$S$1&$P$1&$T$1&$G$2&$T$1&$R$1&G8&$Q$1&$S$1&$P$1&$T$1&$H$2&$T$1&$R$1&H8&$Q$1&$S$1&$P$1&$T$1&$I$2&$T$1&$R$1&I8&$Q$1&$S$1&$P$1&$T$1&$J$2&$T$1&$R$1&J8&$Q$1&$O$1 -> [{"2":127},{"4":70},{"5":70},{"12":393},{"7":8},{"6":0},{"8":10},{"9":0}] | AG7: 5 | AH7: =INT(AG7/1.5) -> 3 | AI7: =AH7 -> 3 | AJ7: 51 | AK7: 4 | AL7: 8 | AM7: 0 | AN7: 10
A8: 6 | B8: =$AP$2+AG8 -> 106 | C8: =INT(B8*1.2) -> 127 | D8: =AH8+$AQ$2 -> 70 | E8: =D8 -> 70 | F8: =INT(主角属性配置!F8/3+$AS$2) -> 785 | G8: 8 | H8: 0 | I8: 10 | J8: 0 | K8: =ROUND(F8/3,0) -> 262 | L8: =ROUND(F8/2,0) -> 393 | N8: =$N$1&$P$1&$T$1&$B$2&$T$1&$R$1&B9&$Q$1&$S$1&$P$1&$T$1&$D$2&$T$1&$R$1&D9&$Q$1&$S$1&$P$1&$T$1&$E$2&$T$1&$R$1&E9&$Q$1&$S$1&$P$1&$T$1&$F$2&$T$1&$R$1&F9&$Q$1&$S$1&$P$1&$T$1&$G$2&$T$1&$R$1&G9&$Q$1&$S$1&$P$1&$T$1&$H$2&$T$1&$R$1&H9&$Q$1&$S$1&$P$1&$T$1&$I$2&$T$1&$R$1&I9&$Q$1&$S$1&$P$1&$T$1&$J$2&$T$1&$R$1&J9&$Q$1&$O$1 -> [{"1":107},{"4":70},{"5":70},{"12":810},{"7":8},{"6":0},{"8":10},{"9":0}] | W8: =$N$1&$P$1&$T$1&$C$2&$T$1&$R$1&C9&$Q$1&$S$1&$P$1&$T$1&$D$2&$T$1&$R$1&D9&$Q$1&$S$1&$P$1&$T$1&$E$2&$T$1&$R$1&E9&$Q$1&$S$1&$P$1&$T$1&$F$2&$T$1&$R$1&K9&$Q$1&$S$1&$P$1&$T$1&$G$2&$T$1&$R$1&G9&$Q$1&$S$1&$P$1&$T$1&$H$2&$T$1&$R$1&H9&$Q$1&$S$1&$P$1&$T$1&$I$2&$T$1&$R$1&I9&$Q$1&$S$1&$P$1&$T$1&$J$2&$T$1&$R$1&J9&$Q$1&$O$1 -> [{"2":128},{"4":70},{"5":70},{"12":270},{"7":8},{"6":0},{"8":10},{"9":0}] | AE8: =$N$1&$P$1&$T$1&$C$2&$T$1&$R$1&C9&$Q$1&$S$1&$P$1&$T$1&$D$2&$T$1&$R$1&D9&$Q$1&$S$1&$P$1&$T$1&$E$2&$T$1&$R$1&E9&$Q$1&$S$1&$P$1&$T$1&$F$2&$T$1&$R$1&L9&$Q$1&$S$1&$P$1&$T$1&$G$2&$T$1&$R$1&G9&$Q$1&$S$1&$P$1&$T$1&$H$2&$T$1&$R$1&H9&$Q$1&$S$1&$P$1&$T$1&$I$2&$T$1&$R$1&I9&$Q$1&$S$1&$P$1&$T$1&$J$2&$T$1&$R$1&J9&$Q$1&$O$1 -> [{"2":128},{"4":70},{"5":70},{"12":405},{"7":8},{"6":0},{"8":10},{"9":0}] | AG8: 6 | AH8: =INT(AG8/1.5) -> 4 | AI8: =AH8 -> 4 | AJ8: 58 | AK8: 4 | AL8: 8 | AM8: 0 | AN8: 10
A9: 7 | B9: =$AP$2+AG9 -> 107 | C9: =INT(B9*1.2) -> 128 | D9: =AH9+$AQ$2 -> 70 | E9: =D9 -> 70 | F9: =INT(主角属性配置!F9/3+$AS$2) -> 810 | G9: 8 | H9: 0 | I9: 10 | J9: 0 | K9: =ROUND(F9/3,0) -> 270 | L9: =ROUND(F9/2,0) -> 405 | N9: =$N$1&$P$1&$T$1&$B$2&$T$1&$R$1&B10&$Q$1&$S$1&$P$1&$T$1&$D$2&$T$1&$R$1&D10&$Q$1&$S$1&$P$1&$T$1&$E$2&$T$1&$R$1&E10&$Q$1&$S$1&$P$1&$T$1&$F$2&$T$1&$R$1&F10&$Q$1&$S$1&$P$1&$T$1&$G$2&$T$1&$R$1&G10&$Q$1&$S$1&$P$1&$T$1&$H$2&$T$1&$R$1&H10&$Q$1&$S$1&$P$1&$T$1&$I$2&$T$1&$R$1&I10&$Q$1&$S$1&$P$1&$T$1&$J$2&$T$1&$R$1&J10&$Q$1&$O$1 -> [{"1":108},{"4":71},{"5":71},{"12":835},{"7":8},{"6":0},{"8":10},{"9":0}] | W9: =$N$1&$P$1&$T$1&$C$2&$T$1&$R$1&C10&$Q$1&$S$1&$P$1&$T$1&$D$2&$T$1&$R$1&D10&$Q$1&$S$1&$P$1&$T$1&$E$2&$T$1&$R$1&E10&$Q$1&$S$1&$P$1&$T$1&$F$2&$T$1&$R$1&K10&$Q$1&$S$1&$P$1&$T$1&$G$2&$T$1&$R$1&G10&$Q$1&$S$1&$P$1&$T$1&$H$2&$T$1&$R$1&H10&$Q$1&$S$1&$P$1&$T$1&$I$2&$T$1&$R$1&I10&$Q$1&$S$1&$P$1&$T$1&$J$2&$T$1&$R$1&J10&$Q$1&$O$1 -> [{"2":129},{"4":71},{"5":71},{"12":278},{"7":8},{"6":0},{"8":10},{"9":0}] | AE9: =$N$1&$P$1&$T$1&$C$2&$T$1&$R$1&C10&$Q$1&$S$1&$P$1&$T$1&$D$2&$T$1&$R$1&D10&$Q$1&$S$1&$P$1&$T$1&$E$2&$T$1&$R$1&E10&$Q$1&$S$1&$P$1&$T$1&$F$2&$T$1&$R$1&L10&$Q$1&$S$1&$P$1&$T$1&$G$2&$T$1&$R$1&G10&$Q$1&$S$1&$P$1&$T$1&$H$2&$T$1&$R$1&H10&$Q$1&$S$1&$P$1&$T$1&$I$2&$T$1&$R$1&I10&$Q$1&$S$1&$P$1&$T$1&$J$2&$T$1&$R$1&J10&$Q$1&$O$1 -> [{"2":129},{"4":71},{"5":71},{"12":418},{"7":8},{"6":0},{"8":10},{"9":0}] | AG9: 7 | AH9: =INT(AG9/1.5) -> 4 | AI9: =AH9 -> 4 | AJ9: 66 | AK9: 4 | AL9: 8 | AM9: 0 | AN9: 10
A10: 8 | B10: =$AP$2+AG10 -> 108 | C10: =INT(B10*1.2) -> 129 | D10: =AH10+$AQ$2 -> 71 | E10: =D10 -> 71 | F10: =INT(主角属性配置!F10/3+$AS$2) -> 835 | G10: 8 | H10: 0 | I10: 10 | J10: 0 | K10: =ROUND(F10/3,0) -> 278 | L10: =ROUND(F10/2,0) -> 418 | N10: =$N$1&$P$1&$T$1&$B$2&$T$1&$R$1&B11&$Q$1&$S$1&$P$1&$T$1&$D$2&$T$1&$R$1&D11&$Q$1&$S$1&$P$1&$T$1&$E$2&$T$1&$R$1&E11&$Q$1&$S$1&$P$1&$T$1&$F$2&$T$1&$R$1&F11&$Q$1&$S$1&$P$1&$T$1&$G$2&$T$1&$R$1&G11&$Q$1&$S$1&$P$1&$T$1&$H$2&$T$1&$R$1&H11&$Q$1&$S$1&$P$1&$T$1&$I$2&$T$1&$R$1&I11&$Q$1&$S$1&$P$1&$T$1&$J$2&$T$1&$R$1&J11&$Q$1&$O$1 -> [{"1":109},{"4":72},{"5":72},{"12":861},{"7":8},{"6":0},{"8":10},{"9":0}] | W10: =$N$1&$P$1&$T$1&$C$2&$T$1&$R$1&C11&$Q$1&$S$1&$P$1&$T$1&$D$2&$T$1&$R$1&D11&$Q$1&$S$1&$P$1&$T$1&$E$2&$T$1&$R$1&E11&$Q$1&$S$1&$P$1&$T$1&$F$2&$T$1&$R$1&K11&$Q$1&$S$1&$P$1&$T$1&$G$2&$T$1&$R$1&G11&$Q$1&$S$1&$P$1&$T$1&$H$2&$T$1&$R$1&H11&$Q$1&$S$1&$P$1&$T$1&$I$2&$T$1&$R$1&I11&$Q$1&$S$1&$P$1&$T$1&$J$2&$T$1&$R$1&J11&$Q$1&$O$1 -> [{"2":130},{"4":72},{"5":72},{"12":287},{"7":8},{"6":0},{"8":10},{"9":0}] | AE10: =$N$1&$P$1&$T$1&$C$2&$T$1&$R$1&C11&$Q$1&$S$1&$P$1&$T$1&$D$2&$T$1&$R$1&D11&$Q$1&$S$1&$P$1&$T$1&$E$2&$T$1&$R$1&E11&$Q$1&$S$1&$P$1&$T$1&$F$2&$T$1&$R$1&L11&$Q$1&$S$1&$P$1&$T$1&$G$2&$T$1&$R$1&G11&$Q$1&$S$1&$P$1&$T$1&$H$2&$T$1&$R$1&H11&$Q$1&$S$1&$P$1&$T$1&$I$2&$T$1&$R$1&I11&$Q$1&$S$1&$P$1&$T$1&$J$2&$T$1&$R$1&J11&$Q$1&$O$1 -> [{"2":130},{"4":72},{"5":72},{"12":431},{"7":8},{"6":0},{"8":10},{"9":0}] | AG10: 8 | AH10: =INT(AG10/1.5) -> 5 | AI10: =AH10 -> 5 | AJ10: 73 | AK10: 4 | AL10: 8 | AM10: 0 | AN10: 10
A11: 9 | B11: =$AP$2+AG11 -> 109 | C11: =INT(B11*1.2) -> 130 | D11: =AH11+$AQ$2 -> 72 | E11: =D11 -> 72 | F11: =INT(主角属性配置!F11/3+$AS$2) -> 861 | G11: 8 | H11: 0 | I11: 10 | J11: 0 | K11: =ROUND(F11/3,0) -> 287 | L11: =ROUND(F11/2,0) -> 431 | N11: =$N$1&$P$1&$T$1&$B$2&$T$1&$R$1&B12&$Q$1&$S$1&$P$1&$T$1&$D$2&$T$1&$R$1&D12&$Q$1&$S$1&$P$1&$T$1&$E$2&$T$1&$R$1&E12&$Q$1&$S$1&$P$1&$T$1&$F$2&$T$1&$R$1&F12&$Q$1&$S$1&$P$1&$T$1&$G$2&$T$1&$R$1&G12&$Q$1&$S$1&$P$1&$T$1&$H$2&$T$1&$R$1&H12&$Q$1&$S$1&$P$1&$T$1&$I$2&$T$1&$R$1&I12&$Q$1&$S$1&$P$1&$T$1&$J$2&$T$1&$R$1&J12&$Q$1&$O$1 -> [{"1":110},{"4":72},{"5":72},{"12":886},{"7":8},{"6":0},{"8":10},{"9":0}] | W11: =$N$1&$P$1&$T$1&$C$2&$T$1&$R$1&C12&$Q$1&$S$1&$P$1&$T$1&$D$2&$T$1&$R$1&D12&$Q$1&$S$1&$P$1&$T$1&$E$2&$T$1&$R$1&E12&$Q$1&$S$1&$P$1&$T$1&$F$2&$T$1&$R$1&K12&$Q$1&$S$1&$P$1&$T$1&$G$2&$T$1&$R$1&G12&$Q$1&$S$1&$P$1&$T$1&$H$2&$T$1&$R$1&H12&$Q$1&$S$1&$P$1&$T$1&$I$2&$T$1&$R$1&I12&$Q$1&$S$1&$P$1&$T$1&$J$2&$T$1&$R$1&J12&$Q$1&$O$1 -> [{"2":132},{"4":72},{"5":72},{"12":295},{"7":8},{"6":0},{"8":10},{"9":0}] | AE11: =$N$1&$P$1&$T$1&$C$2&$T$1&$R$1&C12&$Q$1&$S$1&$P$1&$T$1&$D$2&$T$1&$R$1&D12&$Q$1&$S$1&$P$1&$T$1&$E$2&$T$1&$R$1&E12&$Q$1&$S$1&$P$1&$T$1&$F$2&$T$1&$R$1&L12&$Q$1&$S$1&$P$1&$T$1&$G$2&$T$1&$R$1&G12&$Q$1&$S$1&$P$1&$T$1&$H$2&$T$1&$R$1&H12&$Q$1&$S$1&$P$1&$T$1&$I$2&$T$1&$R$1&I12&$Q$1&$S$1&$P$1&$T$1&$J$2&$T$1&$R$1&J12&$Q$1&$O$1 -> [{"2":132},{"4":72},{"5":72},{"12":443},{"7":8},{"6":0},{"8":10},{"9":0}] | AG11: 9 | AH11: =INT(AG11/1.5) -> 6 | AI11: =AH11 -> 6 | AJ11: 80 | AK11: 4 | AL11: 8 | AM11: 0 | AN11: 10
A12: 10 | B12: =$AP$2+AG12 -> 110 | C12: =INT(B12*1.2) -> 132 | D12: =AH12+$AQ$2 -> 72 | E12: =D12 -> 72 | F12: =INT(主角属性配置!F12/3+$AS$2) -> 886 | G12: 8 | H12: 0 | I12: 10 | J12: 0 | K12: =ROUND(F12/3,0) -> 295 | L12: =ROUND(F12/2,0) -> 443 | N12: =$N$1&$P$1&$T$1&$B$2&$T$1&$R$1&B13&$Q$1&$S$1&$P$1&$T$1&$D$2&$T$1&$R$1&D13&$Q$1&$S$1&$P$1&$T$1&$E$2&$T$1&$R$1&E13&$Q$1&$S$1&$P$1&$T$1&$F$2&$T$1&$R$1&F13&$Q$1&$S$1&$P$1&$T$1&$G$2&$T$1&$R$1&G13&$Q$1&$S$1&$P$1&$T$1&$H$2&$T$1&$R$1&H13&$Q$1&$S$1&$P$1&$T$1&$I$2&$T$1&$R$1&I13&$Q$1&$S$1&$P$1&$T$1&$J$2&$T$1&$R$1&J13&$Q$1&$O$1 -> [{"1":111},{"4":73},{"5":73},{"12":911},{"7":8},{"6":0},{"8":10},{"9":0}] | W12: =$N$1&$P$1&$T$1&$C$2&$T$1&$R$1&C13&$Q$1&$S$1&$P$1&$T$1&$D$2&$T$1&$R$1&D13&$Q$1&$S$1&$P$1&$T$1&$E$2&$T$1&$R$1&E13&$Q$1&$S$1&$P$1&$T$1&$F$2&$T$1&$R$1&K13&$Q$1&$S$1&$P$1&$T$1&$G$2&$T$1&$R$1&G13&$Q$1&$S$1&$P$1&$T$1&$H$2&$T$1&$R$1&H13&$Q$1&$S$1&$P$1&$T$1&$I$2&$T$1&$R$1&I13&$Q$1&$S$1&$P$1&$T$1&$J$2&$T$1&$R$1&J13&$Q$1&$O$1 -> [{"2":133},{"4":73},{"5":73},{"12":304},{"7":8},{"6":0},{"8":10},{"9":0}] | AE12: =$N$1&$P$1&$T$1&$C$2&$T$1&$R$1&C13&$Q$1&$S$1&$P$1&$T$1&$D$2&$T$1&$R$1&D13&$Q$1&$S$1&$P$1&$T$1&$E$2&$T$1&$R$1&E13&$Q$1&$S$1&$P$1&$T$1&$F$2&$T$1&$R$1&L13&$Q$1&$S$1&$P$1&$T$1&$G$2&$T$1&$R$1&G13&$Q$1&$S$1&$P$1&$T$1&$H$2&$T$1&$R$1&H13&$Q$1&$S$1&$P$1&$T$1&$I$2&$T$1&$R$1&I13&$Q$1&$S$1&$P$1&$T$1&$J$2&$T$1&$R$1&J13&$Q$1&$O$1 -> [{"2":133},{"4":73},{"5":73},{"12":456},{"7":8},{"6":0},{"8":10},{"9":0}] | AG12: 10 | AH12: =INT(AG12/1.5) -> 6 | AI12: =AH12 -> 6 | AJ12: 88 | AK12: 4 | AL12: 8 | AM12: 0 | AN12: 10
A13: 11 | B13: =$AP$2+AG13 -> 111 | C13: =INT(B13*1.2) -> 133 | D13: =AH13+$AQ$2 -> 73 | E13: =D13 -> 73 | F13: =INT(主角属性配置!F13/3+$AS$2) -> 911 | G13: 8 | H13: 0 | I13: 10 | J13: 0 | K13: =ROUND(F13/3,0) -> 304 | L13: =ROUND(F13/2,0) -> 456 | N13: =$N$1&$P$1&$T$1&$B$2&$T$1&$R$1&B14&$Q$1&$S$1&$P$1&$T$1&$D$2&$T$1&$R$1&D14&$Q$1&$S$1&$P$1&$T$1&$E$2&$T$1&$R$1&E14&$Q$1&$S$1&$P$1&$T$1&$F$2&$T$1&$R$1&F14&$Q$1&$S$1&$P$1&$T$1&$G$2&$T$1&$R$1&G14&$Q$1&$S$1&$P$1&$T$1&$H$2&$T$1&$R$1&H14&$Q$1&$S$1&$P$1&$T$1&$I$2&$T$1&$R$1&I14&$Q$1&$S$1&$P$1&$T$1&$J$2&$T$1&$R$1&J14&$Q$1&$O$1 -> [{"1":112},{"4":74},{"5":74},{"12":937},{"7":8},{"6":0},{"8":10},{"9":0}] | W13: =$N$1&$P$1&$T$1&$C$2&$T$1&$R$1&C14&$Q$1&$S$1&$P$1&$T$1&$D$2&$T$1&$R$1&D14&$Q$1&$S$1&$P$1&$T$1&$E$2&$T$1&$R$1&E14&$Q$1&$S$1&$P$1&$T$1&$F$2&$T$1&$R$1&K14&$Q$1&$S$1&$P$1&$T$1&$G$2&$T$1&$R$1&G14&$Q$1&$S$1&$P$1&$T$1&$H$2&$T$1&$R$1&H14&$Q$1&$S$1&$P$1&$T$1&$I$2&$T$1&$R$1&I14&$Q$1&$S$1&$P$1&$T$1&$J$2&$T$1&$R$1&J14&$Q$1&$O$1 -> [{"2":134},{"4":74},{"5":74},{"12":312},{"7":8},{"6":0},{"8":10},{"9":0}] | AE13: =$N$1&$P$1&$T$1&$C$2&$T$1&$R$1&C14&$Q$1&$S$1&$P$1&$T$1&$D$2&$T$1&$R$1&D14&$Q$1&$S$1&$P$1&$T$1&$E$2&$T$1&$R$1&E14&$Q$1&$S$1&$P$1&$T$1&$F$2&$T$1&$R$1&L14&$Q$1&$S$1&$P$1&$T$1&$G$2&$T$1&$R$1&G14&$Q$1&$S$1&$P$1&$T$1&$H$2&$T$1&$R$1&H14&$Q$1&$S$1&$P$1&$T$1&$I$2&$T$1&$R$1&I14&$Q$1&$S$1&$P$1&$T$1&$J$2&$T$1&$R$1&J14&$Q$1&$O$1 -> [{"2":134},{"4":74},{"5":74},{"12":469},{"7":8},{"6":0},{"8":10},{"9":0}] | AG13: 11 | AH13: =INT(AG13/1.5) -> 7 | AI13: =AH13 -> 7 | AJ13: 95 | AK13: 4 | AL13: 8 | AM13: 0 | AN13: 10
A14: 12 | B14: =$AP$2+AG14 -> 112 | C14: =INT(B14*1.2) -> 134 | D14: =AH14+$AQ$2 -> 74 | E14: =D14 -> 74 | F14: =INT(主角属性配置!F14/3+$AS$2) -> 937 | G14: 8 | H14: 0 | I14: 10 | J14: 0 | K14: =ROUND(F14/3,0) -> 312 | L14: =ROUND(F14/2,0) -> 469 | N14: =$N$1&$P$1&$T$1&$B$2&$T$1&$R$1&B15&$Q$1&$S$1&$P$1&$T$1&$D$2&$T$1&$R$1&D15&$Q$1&$S$1&$P$1&$T$1&$E$2&$T$1&$R$1&E15&$Q$1&$S$1&$P$1&$T$1&$F$2&$T$1&$R$1&F15&$Q$1&$S$1&$P$1&$T$1&$G$2&$T$1&$R$1&G15&$Q$1&$S$1&$P$1&$T$1&$H$2&$T$1&$R$1&H15&$Q$1&$S$1&$P$1&$T$1&$I$2&$T$1&$R$1&I15&$Q$1&$S$1&$P$1&$T$1&$J$2&$T$1&$R$1&J15&$Q$1&$O$1 -> [{"1":113},{"4":74},{"5":74},{"12":962},{"7":8},{"6":0},{"8":10},{"9":0}] | W14: =$N$1&$P$1&$T$1&$C$2&$T$1&$R$1&C15&$Q$1&$S$1&$P$1&$T$1&$D$2&$T$1&$R$1&D15&$Q$1&$S$1&$P$1&$T$1&$E$2&$T$1&$R$1&E15&$Q$1&$S$1&$P$1&$T$1&$F$2&$T$1&$R$1&K15&$Q$1&$S$1&$P$1&$T$1&$G$2&$T$1&$R$1&G15&$Q$1&$S$1&$P$1&$T$1&$H$2&$T$1&$R$1&H15&$Q$1&$S$1&$P$1&$T$1&$I$2&$T$1&$R$1&I15&$Q$1&$S$1&$P$1&$T$1&$J$2&$T$1&$R$1&J15&$Q$1&$O$1 -> [{"2":135},{"4":74},{"5":74},{"12":321},{"7":8},{"6":0},{"8":10},{"9":0}] | AE14: =$N$1&$P$1&$T$1&$C$2&$T$1&$R$1&C15&$Q$1&$S$1&$P$1&$T$1&$D$2&$T$1&$R$1&D15&$Q$1&$S$1&$P$1&$T$1&$E$2&$T$1&$R$1&E15&$Q$1&$S$1&$P$1&$T$1&$F$2&$T$1&$R$1&L15&$Q$1&$S$1&$P$1&$T$1&$G$2&$T$1&$R$1&G15&$Q$1&$S$1&$P$1&$T$1&$H$2&$T$1&$R$1&H15&$Q$1&$S$1&$P$1&$T$1&$I$2&$T$1&$R$1&I15&$Q$1&$S$1&$P$1&$T$1&$J$2&$T$1&$R$1&J15&$Q$1&$O$1 -> [{"2":135},{"4":74},{"5":74},{"12":481},{"7":8},{"6":0},{"8":10},{"9":0}] | AG14: 12 | AH14: =INT(AG14/1.5) -> 8 | AI14: =AH14 -> 8 | AJ14: 103 | AK14: 4 | AL14: 8 | AM14: 0 | AN14: 10
... A152: 150 | B152: =$AP$2+AG152 -> 250 | C152: =INT(B152*1.2) -> 300 | D152: =AH152+$AQ$2 -> 166 | E152: =D152 -> 166 | F152: =INT(主角属性配置!F152/3+$AS$2) -> 16572 | G152: 8 | H152: 0 | I152: 10 | J152: 0 | K152: =ROUND(F152/3,0) -> 5524 | L152: =ROUND(F152/2,0) -> 8286 | N152: =$N$1&$P$1&$T$1&$B$2&$T$1&$R$1&B153&$Q$1&$S$1&$P$1&$T$1&$D$2&$T$1&$R$1&D153&$Q$1&$S$1&$P$1&$T$1&$E$2&$T$1&$R$1&E153&$Q$1&$S$1&$P$1&$T$1&$F$2&$T$1&$R$1&F153&$Q$1&$S$1&$P$1&$T$1&$G$2&$T$1&$R$1&G153&$Q$1&$S$1&$P$1&$T$1&$H$2&$T$1&$R$1&H153&$Q$1&$S$1&$P$1&$T$1&$I$2&$T$1&$R$1&I153&$Q$1&$S$1&$P$1&$T$1&$J$2&$T$1&$R$1&J153&$Q$1&$O$1 -> [{"1":},{"4":},{"5":},{"12":},{"7":},{"6":},{"8":},{"9":}] | W152: =$N$1&$P$1&$T$1&$C$2&$T$1&$R$1&C153&$Q$1&$S$1&$P$1&$T$1&$D$2&$T$1&$R$1&D153&$Q$1&$S$1&$P$1&$T$1&$E$2&$T$1&$R$1&E153&$Q$1&$S$1&$P$1&$T$1&$F$2&$T$1&$R$1&K153&$Q$1&$S$1&$P$1&$T$1&$G$2&$T$1&$R$1&G153&$Q$1&$S$1&$P$1&$T$1&$H$2&$T$1&$R$1&H153&$Q$1&$S$1&$P$1&$T$1&$I$2&$T$1&$R$1&I153&$Q$1&$S$1&$P$1&$T$1&$J$2&$T$1&$R$1&J153&$Q$1&$O$1 -> [{"2":},{"4":},{"5":},{"12":},{"7":},{"6":},{"8":},{"9":}] | AE152: =$N$1&$P$1&$T$1&$C$2&$T$1&$R$1&C153&$Q$1&$S$1&$P$1&$T$1&$D$2&$T$1&$R$1&D153&$Q$1&$S$1&$P$1&$T$1&$E$2&$T$1&$R$1&E153&$Q$1&$S$1&$P$1&$T$1&$F$2&$T$1&$R$1&L153&$Q$1&$S$1&$P$1&$T$1&$G$2&$T$1&$R$1&G153&$Q$1&$S$1&$P$1&$T$1&$H$2&$T$1&$R$1&H153&$Q$1&$S$1&$P$1&$T$1&$I$2&$T$1&$R$1&I153&$Q$1&$S$1&$P$1&$T$1&$J$2&$T$1&$R$1&J153&$Q$1&$O$1 -> [{"2":},{"4":},{"5":},{"12":},{"7":},{"6":},{"8":},{"9":}] | AG152: 150 | AH152: =INT(AG152/1.5) -> 100 | AI152: =AH152 -> 100 | AJ152: 1202 | AK152: 4 | AL152: 8 | AM152: 0 | AN152: 10

Sheet 战宠属性配置
A1: 等级 | B1: 物理攻击 | C1: 魔法攻击 | D1: 物理防御 | E1: 魔法防御 | F1: 战士生命值 | G1: 命中 | H1: 闪避 | I1: 暴击值 | J1: 韧性值 | K1: 法师生命值 | L1: 祭祀生命值 | N1: [ | O1: ] | P1: { | Q1: } | R1: : | S1: , | T1: " | U1: " | W1: 法师配置 | AE1: 祭祀配置 | AG1: 攻击 | AH1: 物防 | AI1: 魔防 | AJ1: 生命 | AK1: 魔躲 | AL1: 命中 | AM1: 闪避 | AN1: 暴击 | AO1: 基础攻击 | AP1: 基础物防 | AQ1: 基础魔防 | AR1: 基础生命 | AS1: 基础命中 | AT1: 基础闪避 | AU1: 基础暴击
A2: 0 | B2: 1 | C2: 2 | D2: 4 | E2: 5 | F2: 12 | G2: 7 | H2: 6 | I2: 8 | J2: 9 | K2: =INT(F2/4) -> 3 | N2: =$N$1&$P$1&$T$1&$B$2&$T$1&$R$1&B3&$Q$1&$S$1&$P$1&$T$1&$C$2&$T$1&$R$1&C3&$Q$1&$S$1&$P$1&$T$1&$D$2&$T$1&$R$1&D3&$Q$1&$S$1&$P$1&$T$1&$E$2&$T$1&$R$1&E3&$Q$1&$S$1&$P$1&$T$1&$F$2&$T$1&$R$1&F3&$Q$1&$O$1 -> [{"1":112},{"2":91},{"4":74},{"5":74},{"12":1540}] | W2: =$N$1&$P$1&$T$1&$C$2&$T$1&$R$1&C3&$Q$1&$S$1&$P$1&$T$1&$D$2&$T$1&$R$1&D3&$Q$1&$S$1&$P$1&$T$1&$E$2&$T$1&$R$1&E3&$Q$1&$S$1&$P$1&$T$1&$F$2&$T$1&$R$1&K3&$Q$1&$S$1&$P$1&$T$1&$G$2&$T$1&$R$1&G3&$Q$1&$S$1&$P$1&$T$1&$H$2&$T$1&$R$1&H3&$Q$1&$S$1&$P$1&$T$1&$I$2&$T$1&$R$1&I3&$Q$1&$S$1&$P$1&$T$1&$J$2&$T$1&$R$1&J3&$Q$1&$O$1 -> [{"2":91},{"4":74},{"5":74},{"12":513},{"7":8},{"6":0},{"8":10},{"9":0}] | AE2: =$N$1&$P$1&$T$1&$C$2&$T$1&$R$1&C3&$Q$1&$S$1&$P$1&$T$1&$D$2&$T$1&$R$1&D3&$Q$1&$S$1&$P$1&$T$1&$E$2&$T$1&$R$1&E3&$Q$1&$S$1&$P$1&$T$1&$F$2&$T$1&$R$1&L3&$Q$1&$S$1&$P$1&$T$1&$G$2&$T$1&$R$1&G3&$Q$1&$S$1&$P$1&$T$1&$H$2&$T$1&$R$1&H3&$Q$1&$S$1&$P$1&$T$1&$I$2&$T$1&$R$1&I3&$Q$1&$S$1&$P$1&$T$1&$J$2&$T$1&$R$1&J3&$Q$1&$O$1 -> [{"2":91},{"4":74},{"5":74},{"12":770},{"7":8},{"6":0},{"8":10},{"9":0}] | AG2: 1.5 | AH2: 1 | AI2: 1 | AJ2: 10 | AK2: 0.4 | AL2: 0.4 | AM2: 0.4 | AN2: 0.4 | AO2: 12 | AP2: 8 | AQ2: 8 | AR2: 220 | AS2: 10 | AT2: 0 | AU2: 10
A3: 1 | B3: =$AO$2+AG3 -> 112 | C3: =INT(B3*0.82) -> 91 | D3: =INT(B3/1.5) -> 74 | E3: =D3 -> 74 | F3: =$AR$2+AJ3 -> 1540 | G3: 8 | H3: 0 | I3: 10 | J3: 0 | K3: =INT(F3/3) -> 513 | L3: =INT(F3/2) -> 770 | N3: =$N$1&$P$1&$T$1&$B$2&$T$1&$R$1&B4&$Q$1&$S$1&$P$1&$T$1&$C$2&$T$1&$R$1&C4&$Q$1&$S$1&$P$1&$T$1&$D$2&$T$1&$R$1&D4&$Q$1&$S$1&$P$1&$T$1&$E$2&$T$1&$R$1&E4&$Q$1&$S$1&$P$1&$T$1&$F$2&$T$1&$R$1&F4&$Q$1&$O$1 -> [{"1":114},{"2":93},{"4":76},{"5":76},{"12":1580}] | W3: =$N$1&$P$1&$T$1&$C$2&$T$1&$R$1&C4&$Q$1&$S$1&$P$1&$T$1&$D$2&$T$1&$R$1&D4&$Q$1&$S$1&$P$1&$T$1&$E$2&$T$1&$R$1&E4&$Q$1&$S$1&$P$1&$T$1&$F$2&$T$1&$R$1&K4&$Q$1&$S$1&$P$1&$T$1&$G$2&$T$1&$R$1&G4&$Q$1&$S$1&$P$1&$T$1&$H$2&$T$1&$R$1&H4&$Q$1&$S$1&$P$1&$T$1&$I$2&$T$1&$R$1&I4&$Q$1&$S$1&$P$1&$T$1&$J$2&$T$1&$R$1&J4&$Q$1&$O$1 -> [{"2":93},{"4":76},{"5":76},{"12":526},{"7":8},{"6":0},{"8":10},{"9":0}] | AE3: =$N$1&$P$1&$T$1&$C$2&$T$1&$R$1&C4&$Q$1&$S$1&$P$1&$T$1&$D$2&$T$1&$R$1&D4&$Q$1&$S$1&$P$1&$T$1&$E$2&$T$1&$R$1&E4&$Q$1&$S$1&$P$1&$T$1&$F$2&$T$1&$R$1&L4&$Q$1&$S$1&$P$1&$T$1&$G$2&$T$1&$R$1&G4&$Q$1&$S$1&$P$1&$T$1&$H$2&$T$1&$R$1&H4&$Q$1&$S$1&$P$1&$T$1&$I$2&$T$1&$R$1&I4&$Q$1&$S$1&$P$1&$T$1&$J$2&$T$1&$R$1&J4&$Q$1&$O$1 -> [{"2":93},{"4":76},{"5":76},{"12":790},{"7":8},{"6":0},{"8":10},{"9":0}] | AG3: 100 | AH3: =INT(AG3/1.5) -> 66 | AI3: =AH3 -> 66 | AJ3: =AI3*20 -> 1320 | AK3: 4 | AL3: 8 | AM3: 0 | AN3: 10
A4: 2 | B4: =$AO$2+AG4 -> 114 | C4: =INT(B4*0.82) -> 93 | D4: =INT(B4/1.5) -> 76 | E4: =D4 -> 76 | F4: =$AR$2+AJ4 -> 1580 | G4: 8 | H4: 0 | I4: 10 | J4: 0 | K4: =INT(F4/3) -> 526 | L4: =INT(F4/2) -> 790 | N4: =$N$1&$P$1&$T$1&$B$2&$T$1&$R$1&B5&$Q$1&$S$1&$P$1&$T$1&$C$2&$T$1&$R$1&C5&$Q$1&$S$1&$P$1&$T$1&$D$2&$T$1&$R$1&D5&$Q$1&$S$1&$P$1&$T$1&$E$2&$T$1&$R$1&E5&$Q$1&$S$1&$P$1&$T$1&$F$2&$T$1&$R$1&F5&$Q$1&$O$1 -> [{"1":116},{"2":95},{"4":77},{"5":77},{"12":1600}] | W4: =$N$1&$P$1&$T$1&$C$2&$T$1&$R$1&C5&$Q$1&$S$1&$P$1&$T$1&$D$2&$T$1&$R$1&D5&$Q$1&$S$1&$P$1&$T$1&$E$2&$T$1&$R$1&E5&$Q$1&$S$1&$P$1&$T$1&$F$2&$T$1&$R$1&K5&$Q$1&$S$1&$P$1&$T$1&$G$2&$T$1&$R$1&G5&$Q$1&$S$1&$P$1&$T$1&$H$2&$T$1&$R$1&H5&$Q$1&$S$1&$P$1&$T$1&$I$2&$T$1&$R$1&I5&$Q$1&$S$1&$P$1&$T$1&$J$2&$T$1&$R$1&J5&$Q$1&$O$1 -> [{"2":95},{"4":77},{"5":77},{"12":533},{"7":8},{"6":0},{"8":10},{"9":0}] | AE4: =$N$1&$P$1&$T$1&$C$2&$T$1&$R$1&C5&$Q$1&$S$1&$P$1&$T$1&$D$2&$T$1&$R$1&D5&$Q$1&$S$1&$P$1&$T$1&$E$2&$T$1&$R$1&E5&$Q$1&$S$1&$P$1&$T$1&$F$2&$T$1&$R$1&L5&$Q$1&$S$1&$P$1&$T$1&$G$2&$T$1&$R$1&G5&$Q$1&$S$1&$P$1&$T$1&$H$2&$T$1&$R$1&H5&$Q$1&$S$1&$P$1&$T$1&$I$2&$T$1&$R$1&I5&$Q$1&$S$1&$P$1&$T$1&$J$2&$T$1&$R$1&J5&$Q$1&$O$1 -> [{"2":95},{"4":77},{"5":77},{"12":800},{"7":8},{"6":0},{"8":10},{"9":0}] | AG4: 102 | AH4: =INT(AG4/1.5) -> 68 | AI4: =AH4 -> 68 | AJ4: =AI4*20 -> 1360 | AK4: 4 | AL4: 8 | AM4: 0 | AN4: 10
A5: 3 | B5: =$AO$2+AG5 -> 116 | C5: =INT(B5*0.82) -> 95 | D5: =INT(B5/1.5) -> 77 | E5: =D5 -> 77 | F5: =$AR$2+AJ5 -> 1600 | G5: 8 | H5: 0 | I5: 10 | J5: 0 | K5: =INT(F5/3) -> 533 | L5: =INT(F5/2) -> 800 | N5: =$N$1&$P$1&$T$1&$B$2&$T$1&$R$1&B6&$Q$1&$S$1&$P$1&$T$1&$C$2&$T$1&$R$1&C6&$Q$1&$S$1&$P$1&$T$1&$D$2&$T$1&$R$1&D6&$Q$1&$S$1&$P$1&$T$1&$E$2&$T$1&$R$1&E6&$Q$1&$S$1&$P$1&$T$1&$F$2&$T$1&$R$1&F6&$Q$1&$O$1 -> [{"1":118},{"2":96},{"4":78},{"5":78},{"12":1620}] | W5: =$N$1&$P$1&$T$1&$C$2&$T$1&$R$1&C6&$Q$1&$S$1&$P$1&$T$1&$D$2&$T$1&$R$1&D6&$Q$1&$S$1&$P$1&$T$1&$E$2&$T$1&$R$1&E6&$Q$1&$S$1&$P$1&$T$1&$F$2&$T$1&$R$1&K6&$Q$1&$S$1&$P$1&$T$1&$G$2&$T$1&$R$1&G6&$Q$1&$S$1&$P$1&$T$1&$H$2&$T$1&$R$1&H6&$Q$1&$S$1&$P$1&$T$1&$I$2&$T$1&$R$1&I6&$Q$1&$S$1&$P$1&$T$1&$J$2&$T$1&$R$1&J6&$Q$1&$O$1 -> [{"2":96},{"4":78},{"5":78},{"12":540},{"7":8},{"6":0},{"8":10},{"9":0}] | AE5: =$N$1&$P$1&$T$1&$C$2&$T$1&$R$1&C6&$Q$1&$S$1&$P$1&$T$1&$D$2&$T$1&$R$1&D6&$Q$1&$S$1&$P$1&$T$1&$E$2&$T$1&$R$1&E6&$Q$1&$S$1&$P$1&$T$1&$F$2&$T$1&$R$1&L6&$Q$1&$S$1&$P$1&$T$1&$G$2&$T$1&$R$1&G6&$Q$1&$S$1&$P$1&$T$1&$H$2&$T$1&$R$1&H6&$Q$1&$S$1&$P$1&$T$1&$I$2&$T$1&$R$1&I6&$Q$1&$S$1&$P$1&$T$1&$J$2&$T$1&$R$1&J6&$Q$1&$O$1 -> [{"2":96},{"4":78},{"5":78},{"12":810},{"7":8},{"6":0},{"8":10},{"9":0}] | AG5: 104 | AH5: =INT(AG5/1.5) -> 69 | AI5: =AH5 -> 69 | AJ5: =AI5*20 -> 1380 | AK5: 4 | AL5: 8 | AM5: 0 | AN5: 10
A6: 4 | B6: =$AO$2+AG6 -> 118 | C6: =INT(B6*0.82) -> 96 | D6: =INT(B6/1.5) -> 78 | E6: =D6 -> 78 | F6: =$AR$2+AJ6 -> 1620 | G6: 8 | H6: 0 | I6: 10 | J6: 0 | K6: =INT(F6/3) -> 540 | L6: =INT(F6/2) -> 810 | N6: =$N$1&$P$1&$T$1&$B$2&$T$1&$R$1&B7&$Q$1&$S$1&$P$1&$T$1&$C$2&$T$1&$R$1&C7&$Q$1&$S$1&$P$1&$T$1&$D$2&$T$1&$R$1&D7&$Q$1&$S$1&$P$1&$T$1&$E$2&$T$1&$R$1&E7&$Q$1&$S$1&$P$1&$T$1&$F$2&$T$1&$R$1&F7&$Q$1&$O$1 -> [{"1":120},{"2":98},{"4":80},{"5":80},{"12":1660}] | W6: =$N$1&$P$1&$T$1&$C$2&$T$1&$R$1&C7&$Q$1&$S$1&$P$1&$T$1&$D$2&$T$1&$R$1&D7&$Q$1&$S$1&$P$1&$T$1&$E$2&$T$1&$R$1&E7&$Q$1&$S$1&$P$1&$T$1&$F$2&$T$1&$R$1&K7&$Q$1&$S$1&$P$1&$T$1&$G$2&$T$1&$R$1&G7&$Q$1&$S$1&$P$1&$T$1&$H$2&$T$1&$R$1&H7&$Q$1&$S$1&$P$1&$T$1&$I$2&$T$1&$R$1&I7&$Q$1&$S$1&$P$1&$T$1&$J$2&$T$1&$R$1&J7&$Q$1&$O$1 -> [{"2":98},{"4":80},{"5":80},{"12":553},{"7":8},{"6":0},{"8":10},{"9":0}] | AE6: =$N$1&$P$1&$T$1&$C$2&$T$1&$R$1&C7&$Q$1&$S$1&$P$1&$T$1&$D$2&$T$1&$R$1&D7&$Q$1&$S$1&$P$1&$T$1&$E$2&$T$1&$R$1&E7&$Q$1&$S$1&$P$1&$T$1&$F$2&$T$1&$R$1&L7&$Q$1&$S$1&$P$1&$T$1&$G$2&$T$1&$R$1&G7&$Q$1&$S$1&$P$1&$T$1&$H$2&$T$1&$R$1&H7&$Q$1&$S$1&$P$1&$T$1&$I$2&$T$1&$R$1&I7&$Q$1&$S$1&$P$1&$T$1&$J$2&$T$1&$R$1&J7&$Q$1&$O$1 -> [{"2":98},{"4":80},{"5":80},{"12":830},{"7":8},{"6":0},{"8":10},{"9":0}] | AG6: 106 | AH6: =INT(AG6/1.5) -> 70 | AI6: =AH6 -> 70 | AJ6: =AI6*20 -> 1400 | AK6: 4 | AL6: 8 | AM6: 0 | AN6: 10
A7: 5 | B7: =$AO$2+AG7 -> 120 | C7: =INT(B7*0.82) -> 98 | D7: =INT(B7/1.5) -> 80 | E7: =D7 -> 80 | F7: =$AR$2+AJ7 -> 1660 | G7: 8 | H7: 0 | I7: 10 | J7: 0 | K7: =INT(F7/3) -> 553 | L7: =INT(F7/2) -> 830 | N7: =$N$1&$P$1&$T$1&$B$2&$T$1&$R$1&B8&$Q$1&$S$1&$P$1&$T$1&$C$2&$T$1&$R$1&C8&$Q$1&$S$1&$P$1&$T$1&$D$2&$T$1&$R$1&D8&$Q$1&$S$1&$P$1&$T$1&$E$2&$T$1&$R$1&E8&$Q$1&$S$1&$P$1&$T$1&$F$2&$T$1&$R$1&F8&$Q$1&$O$1 -> [{"1":122},{"2":100},{"4":81},{"5":81},{"12":1680}] | W7: =$N$1&$P$1&$T$1&$C$2&$T$1&$R$1&C8&$Q$1&$S$1&$P$1&$T$1&$D$2&$T$1&$R$1&D8&$Q$1&$S$1&$P$1&$T$1&$E$2&$T$1&$R$1&E8&$Q$1&$S$1&$P$1&$T$1&$F$2&$T$1&$R$1&K8&$Q$1&$S$1&$P$1&$T$1&$G$2&$T$1&$R$1&G8&$Q$1&$S$1&$P$1&$T$1&$H$2&$T$1&$R$1&H8&$Q$1&$S$1&$P$1&$T$1&$I$2&$T$1&$R$1&I8&$Q$1&$S$1&$P$1&$T$1&$J$2&$T$1&$R$1&J8&$Q$1&$O$1 -> [{"2":100},{"4":81},{"5":81},{"12":560},{"7":8},{"6":0},{"8":10},{"9":0}] | AE7: =$N$1&$P$1&$T$1&$C$2&$T$1&$R$1&C8&$Q$1&$S$1&$P$1&$T$1&$D$2&$T$1&$R$1&D8&$Q$1&$S$1&$P$1&$T$1&$E$2&$T$1&$R$1&E8&$Q$1&$S$1&$P$1&$T$1&$F$2&$T$1&$R$1&L8&$Q$1&$S$1&$P$1&$T$1&$G$2&$T$1&$R$1&G8&$Q$1&$S$1&$P$1&$T$1&$H$2&$T$1&$R$1&H8&$Q$1&$S$1&$P$1&$T$1&$I$2&$T$1&$R$1&I8&$Q$1&$S$1&$P$1&$T$1&$J$2&$T$1&$R$1&J8&$Q$1&$O$1 -> [{"2":100},{"4":81},{"5":81},{"12":840},{"7":8},{"6":0},{"8":10},{"9":0}] | AG7: 108 | AH7: =INT(AG7/1.5) -> 72 | AI7: =AH7 -> 72 | AJ7: =AI7*20 -> 1440 | AK7: 4 | AL7: 8 | AM7: 0 | AN7: 10
A8: 6 | B8: =$AO$2+AG8 -> 122 | C8: =INT(B8*0.82) -> 100 | D8: =INT(B8/1.5) -> 81 | E8: =D8 -> 81 | F8: =$AR$2+AJ8 -> 1680 | G8: 8 | H8: 0 | I8: 10 | J8: 0 | K8: =INT(F8/3) -> 560 | L8: =INT(F8/2) -> 840 | N8: =$N$1&$P$1&$T$1&$B$2&$T$1&$R$1&B9&$Q$1&$S$1&$P$1&$T$1&$C$2&$T$1&$R$1&C9&$Q$1&$S$1&$P$1&$T$1&$D$2&$T$1&$R$1&D9&$Q$1&$S$1&$P$1&$T$1&$E$2&$T$1&$R$1&E9&$Q$1&$S$1&$P$1&$T$1&$F$2&$T$1&$R$1&F9&$Q$1&$O$1 -> [{"1":124},{"2":101},{"4":82},{"5":82},{"12":1700}] | W8: =$N$1&$P$1&$T$1&$C$2&$T$1&$R$1&C9&$Q$1&$S$1&$P$1&$T$1&$D$2&$T$1&$R$1&D9&$Q$1&$S$1&$P$1&$T$1&$E$2&$T$1&$R$1&E9&$Q$1&$S$1&$P$1&$T$1&$F$2&$T$1&$R$1&K9&$Q$1&$S$1&$P$1&$T$1&$G$2&$T$1&$R$1&G9&$Q$1&$S$1&$P$1&$T$1&$H$2&$T$1&$R$1&H9&$Q$1&$S$1&$P$1&$T$1&$I$2&$T$1&$R$1&I9&$Q$1&$S$1&$P$1&$T$1&$J$2&$T$1&$R$1&J9&$Q$1&$O$1 -> [{"2":101},{"4":82},{"5":82},{"12":566},{"7":8},{"6":0},{"8":10},{"9":0}] | AE8: =$N$1&$P$1&$T$1&$C$2&$T$1&$R$1&C9&$Q$1&$S$1&$P$1&$T$1&$D$2&$T$1&$R$1&D9&$Q$1&$S$1&$P$1&$T$1&$E$2&$T$1&$R$1&E9&$Q$1&$S$1&$P$1&$T$1&$F$2&$T$1&$R$1&L9&$Q$1&$S$1&$P$1&$T$1&$G$2&$T$1&$R$1&G9&$Q$1&$S$1&$P$1&$T$1&$H$2&$T$1&$R$1&H9&$Q$1&$S$1&$P$1&$T$1&$I$2&$T$1&$R$1&I9&$Q$1&$S$1&$P$1&$T$1&$J$2&$T$1&$R$1&J9&$Q$1&$O$1 -> [{"2":101},{"4":82},{"5":82},{"12":850},{"7":8},{"6":0},{"8":10},{"9":0}] | AG8: 110 | AH8: =INT(AG8/1.5) -> 73 | AI8: =AH8 -> 73 | AJ8: =AI8*20 -> 1460 | AK8: 4 | AL8: 8 | AM8: 0 | AN8: 10
A9: 7 | B9: =$AO$2+AG9 -> 124 | C9: =INT(B9*0.82) -> 101 | D9: =INT(B9/1.5) -> 82 | E9: =D9 -> 82 | F9: =$AR$2+AJ9 -> 1700 | G9: 8 | H9: 0 | I9: 10 | J9: 0 | K9: =INT(F9/3) -> 566 | L9: =INT(F9/2) -> 850 | N9: =$N$1&$P$1&$T$1&$B$2&$T$1&$R$1&B10&$Q$1&$S$1&$P$1&$T$1&$C$2&$T$1&$R$1&C10&$Q$1&$S$1&$P$1&$T$1&$D$2&$T$1&$R$1&D10&$Q$1&$S$1&$P$1&$T$1&$E$2&$T$1&$R$1&E10&$Q$1&$S$1&$P$1&$T$1&$F$2&$T$1&$R$1&F10&$Q$1&$O$1 -> [{"1":126},{"2":103},{"4":84},{"5":84},{"12":1740}] | W9: =$N$1&$P$1&$T$1&$C$2&$T$1&$R$1&C10&$Q$1&$S$1&$P$1&$T$1&$D$2&$T$1&$R$1&D10&$Q$1&$S$1&$P$1&$T$1&$E$2&$T$1&$R$1&E10&$Q$1&$S$1&$P$1&$T$1&$F$2&$T$1&$R$1&K10&$Q$1&$S$1&$P$1&$T$1&$G$2&$T$1&$R$1&G10&$Q$1&$S$1&$P$1&$T$1&$H$2&$T$1&$R$1&H10&$Q$1&$S$1&$P$1&$T$1&$I$2&$T$1&$R$1&I10&$Q$1&$S$1&$P$1&$T$1&$J$2&$T$1&$R$1&J10&$Q$1&$O$1 -> [{"2":103},{"4":84},{"5":84},{"12":580},{"7":8},{"6":0},{"8":10},{"9":0}] | AE9: =$N$1&$P$1&$T$1&$C$2&$T$1&$R$1&C10&$Q$1&$S$1&$P$1&$T$1&$D$2&$T$1&$R$1&D10&$Q$1&$S$1&$P$1&$T$1&$E$2&$T$1&$R$1&E10&$Q$1&$S$1&$P$1&$T$1&$F$2&$T$1&$R$1&L10&$Q$1&$S$1&$P$1&$T$1&$G$2&$T$1&$R$1&G10&$Q$1&$S$1&$P$1&$T$1&$H$2&$T$1&$R$1&H10&$Q$1&$S$1&$P$1&$T$1&$I$2&$T$1&$R$1&I10&$Q$1&$S$1&$P$1&$T$1&$J$2&$T$1&$R$1&J10&$Q$1&$O$1 -> [{"2":103},{"4":84},{"5":84},{"12":870},{"7":8},{"6":0},{"8":10},{"9":0}] | AG9: 112 | AH9: =INT(AG9/1.5) -> 74 | AI9: =AH9 -> 74 | AJ9: =AI9*20 -> 1480 | AK9: 4 | AL9: 8 | AM9: 0 | AN9: 10
